Workbook
Name Anomalia: SELEÇÕES!$Q$14:$Q$15
Name AnomaliaMecânica: SELEÇÕES!$AD$29
Name AnomaliaVia: SELEÇÕES!$AC$29
Name ATIVOS: BS_ATIVO!$A$2:$A$250
Name CCOCirculação: SELEÇÕES!$K$14:$K$17
Name CCOCirculaçãoIntervaloContrato: SELEÇÕES!$Q$29:$Q$39
Name CCOCirculaçãoIntervaloExtra: SELEÇÕES!$AH$29
Name CCOCirculaçãoIntervaloOportunidade: SELEÇÕES!$S$29:$S$39
Name CCOCirculaçãoProgramação: SELEÇÕES!$R$29
Name CCOEscala: SELEÇÕES!$J$14
Name CCOEscalaEquipagem: SELEÇÕES!$P$29:$P$32
Name CondiçõesClimática: SELEÇÕES!$R$14:$R$16
Name CondiçõesClimáticaChuva: SELEÇÕES!$AG$29
Name CondiçõesClimáticaTemperatura: SELEÇÕES!$AE$29:$AE$31
Name CondiçõesClimáticaVentosFortes: SELEÇÕES!$AF$29:$AF$29
Name Confiabilidade: SELEÇÕES!$S$14:$S$15
Name ConfiabilidadeAtivo: SELEÇÕES!$AJ$29:$AJ$30
Name ConfiabilidadeOperação: SELEÇÕES!$AI$29:$AI$33
Name DIN_ATIVIDADE: BS_ATIVO!$C$2:$C$100
Name Engenharia: SELEÇÕES!$T$14:$T$17
Name EngenhariaAtivo: SELEÇÕES!$AL$29:$AL$39
Name EngenhariaOperação: SELEÇÕES!$AK$29:$AK$39
Name Expansão: SELEÇÕES!$M$14:$M$15
Name ExpansãoEquipamento: SELEÇÕES!$V$29:$V$30
Name ExpansãoExecução: SELEÇÕES!$W$29:$W$38
Name FaltadeContrato: SELEÇÕES!$U$14
Name FaltadeContratoFaltadeContrato: SELEÇÕES!$AM$29
Name IMPCAUSADOR: SELEÇÕES!$A$13:$W$13
Name Infraestrutura: SELEÇÕES!$O$14:$O$15
Name InfraestruturaEquipamento: SELEÇÕES!$Z$29:$Z$30
Name InfraestruturaExecução: SELEÇÕES!$AA$29:$AA$38
Name Mecânica: SELEÇÕES!$G$14:$G$15
Name MecânicaLocomotiva: SELEÇÕES!$J$29
Name MecânicaVagão: SELEÇÕES!$K$29
Name Mecanização: SELEÇÕES!$H$14:$H$15
Name MecanizaçãoAtivos: SELEÇÕES!$M$29:$M$31
Name MecanizaçãoOperação: SELEÇÕES!$L$29:$L$35
Name Modernização: SELEÇÕES!$N$14:$N$17
Name ModernizaçãoEquipamento: SELEÇÕES!$X$29:$X$30
Name ModernizaçãoExecução: SELEÇÕES!$Y$29:$Y$38
Name NãoControláveis: SELEÇÕES!$B$14:$B$15
Name NãoControláveisAcidente: SELEÇÕES!$E$29
Name NãoControláveisVandalismo: SELEÇÕES!$D$29:$D$33
Name OK: SELEÇÕES!$P$14
Name OKOK: SELEÇÕES!$AB$29
Name OutrasFerrovias: SELEÇÕES!$W$14:$W$14
Name OutrasFerroviasOutrasFerrovias: SELEÇÕES!$AO$29:$AO$29
Name Pátio: SELEÇÕES!$D$14
Name PátioOperação: SELEÇÕES!$G$29:$G$30
Name PCMMecânica: SELEÇÕES!$F$14
Name PCMMecânicaLocomotiva: SELEÇÕES!$I$29:$I$30
Name PCMVIA: SELEÇÕES!$I$14:$I$15
Name PCMVIAProgramação: SELEÇÕES!$O$29:$O$31
Name PCMVIARecursosInternos: SELEÇÕES!$N$29:$N$31
Name Qualidade: SELEÇÕES!$T$14:$T$15
Name QualidadeAtivo: SELEÇÕES!$AL$29
Name QualidadeOperação: SELEÇÕES!$AK$29:$AK$30
Name SemOportunidade: SELEÇÕES!$V$14
Name SemOportunidadeSemOportunidade: SELEÇÕES!$AN$29
Name SUBs: SELEÇÕES!$A$44:$A$50

Sheet BS_ATIVO
A1: BLOCO | C1: ATIVIDADE | D1: UNIDADE | E1: CONTROLE INDICADOR | F1: GRUPO | G1: Item PDM | H1: PESO | I1: Prioridade | J1: CORRELATO
A2: BLOCO | C2: BLOCO | D2: BINÁRIO | E2: OUTROS | F2: BLOCO | G2: - | H2: 0 | I2: 0 | J2: BLOCO
A3: EXPANSÃO TURMA 1 | C3: CAMINHÃO DE SOLDA | D3: Nº DE SOLDA | E3: CAMINHÂO - SOLDA | F3: CAMINHÃO SOLDA | G3: - | H3: 1 | I3: 1 | J3: CAMINHÃO SOLDA
A4: EXPANSÃO TURMA 2 | C4: CONSERVAÇÃO PN | D4: BINÁRIO | E4: CONSERVAÇÂO PN | F4: VIA - TURMA | G4: - | H4: 1 | I4: 1 | J4: VIA - TURMA
A5: INFRA 1 | C5: DESCARGA DE MATERIAL | D5: BINÁRIO | E5: OUTROS | F5: VIA - LASTRO | J5: VIA - LASTRO
A6: INFRA 2 | C6: DESLOCAMENTO | D6: BINÁRIO | E6: OUTROS | F6: TODOS | G6: - | H6: 0 | I6: 4 | J6: TODOS
A7: MOD ZDG PAT | C7: DETECÇÃO - CARRO CONTROLE | D7: KM | E7: DETECÇÃO | F7: DETECÇÃO | G7: - | H7: 1 | I7: 1 | J7: DETECÇÃO
A8: MOD ZEM | C8: DETECÇÃO - RONDA 7 DIAS | D8: KM | E8: DETECÇÃO | F8: DETECÇÃO | G8: - | H8: 1 | I8: 1 | J8: DETECÇÃO
A9: MOD ZRB | C9: DETECÇÃO - ULTRASSOM - SPERRY | D9: KM | E9: DETECÇÃO | F9: DETECÇÃO | G9: - | H9: 1 | I9: 1 | J9: DETECÇÃO
A10: MOD ZWU ZDC | C10: EXPANSÃO - ALÍVIO DE TENSÃO | D10: M | E10: EXPANSÃO | F10: EXPANSÃO | G10: - | H10: 0 | I10: 0 | J10: EXPANSÃO - TURMA
A11: MOD ZYQ ZWI | C11: EXPANSÃO - AMV - JACARÉ | D11: Nº DE PEÇAS | E11: EXPANSÃO | F11: EXPANSÃO | G11: - | H11: 0 | I11: 0 | J11: EXPANSÃO - TURMA
A12: MODERNIZAÇÃO LASTRO 2 | C12: EXPANSÃO - AMV - MEIA CHAVE | D12: Nº DE PEÇAS | E12: EXPANSÃO | F12: EXPANSÃO | G12: - | H12: 0 | I12: 0 | J12: EXPANSÃO - TURMA
A13: MODERNIZAÇÃO TURMA 2 | C13: EXPANSÃO - DESCARGA - TRILHO | D13: Nº DE BARRAS | E13: EXPANSÃO | F13: EXPANSÃO | G13: - | H13: 0 | I13: 0 | J13: EXPANSÃO - TRILHEIRO
A14: SOLDA T3 | C14: EXPANSÃO - DORMENTE - CARGA | D14: Nº DE DORMENTES | E14: EXPANSÃO | F14: EXPANSÃO | G14: - | H14: 0 | I14: 0 | J14: EXPANSÃO - LASTRO
A15: SUPER | C15: EXPANSÃO - DORMENTE - DESCARGA | D15: Nº DE DORMENTES | E15: EXPANSÃO | F15: EXPANSÃO | G15: - | H15: 0 | I15: 0 | J15: EXPANSÃO - LASTRO
A16: SUPER SERRA | C16: EXPANSÃO - OUTRA ATIVIDADE | D16: BINÁRIO | E16: EXPANSÃO | F16: EXPANSÃO | G16: - | H16: 0 | I16: 0 | J16: EXPANSÃO - TODOS
A17: SUPER ZAR | C17: EXPANSÃO - TRILHEIRO - DESCARGA | D17: M | E17: EXPANSÃO | F17: EXPANSÃO | G17: - | H17: 1 | I17: 1 | J17: EXPANSÃO - TRILHEIRO
... A75: V87 | C75: VANDALISMO - LIMPEZA | D75: M | E75: OUTROS | F75: VIA - TURMA | G75: - | H75: 1 | I75: 1 | J75: VIA - TURMA
A76: V88 | C76: VARRIÇÃO | D76: M | E76: OUTROS | F76: VIA - TURMA | H76: 1 | I76: 1 | J76: VIA - TURMA
A77: V89 | C77: NIVELAMENTO | D77: BINÁRIO | E77: OUTROS | F77: VIA - TURMA | G77: NIVELAMENTO | H77: 1 | I77: 1 | J77: VIA - TURMA
A78: V90 | C78: PREPARAÇÃO DE BARRA | D78: BINÁRIO | E78: OUTROS | F78: VIA - TURMA | G78: TRILHO | H78: 1 | I78: 1 | J78: VIA - TURMA
A79: V92 | C79: INSPEÇÃO | D79: BINÁRIO | E79: OUTROS | F79: VIA - TURMA | G79: VIA | H79: 0 | I79: 0 | J79: VIA - TURMA
A80: V93 | C80: MECANIZAÇÃO - REGULAGEM | D80: M | E80: OUTROS - MECANIZAÇÃO | F80: REGULAGEM | G80: VIA | H80: 1 | I80: 0 | J80: REGULAGEM
A81: V96 | C81: MODERNIZAÇÃO - REGULAGEM | D81: M | E81: MODERNIZAÇÃO | F81: REGULAGEM | G81: VIA | H81: 1 | I81: 0 | J81: REGULAGEM
A82: V97
A83: V98
A84: W19
A85: W48
A86: W50
A87: W53
A88: W54
A89: W55
A90: W58
A91: W59
A92: W60
A93: W61
... A208: FERNANDO (TF-19)

Sheet BASE_MAPA
A1: Gerência | B1: SUB | C1: KM Inicio | D1: KM Fim | E1: Trecho | F1: SB | G1: NOME SUB | H1: Trecho Coordenação
A2: FERRONORTE | B2: 74 | C2: 0 | D2: 5.77 | E2: TMI-TRP | F2: TMITRP | G2: MARCO INICIAL - ALTO ARAGUAIA | H2: TMI-TCS
A3: FERRONORTE | B3: 74 | C3: 5.77 | D3: 7 | E3: TRP | F3: TRP1 | G3: MARCO INICIAL - ALTO ARAGUAIA | H3: TMI-TCS
A4: FERRONORTE | B4: 74 | C4: 5.77 | D4: 7 | E4: TRP | F4: TRP2 | G4: MARCO INICIAL - ALTO ARAGUAIA | H4: TMI-TCS
A5: FERRONORTE | B5: 74 | C5: 7 | D5: 8.448 | E5: TRP-TAP | F5: TRPPAT1 | G5: MARCO INICIAL - ALTO ARAGUAIA | H5: TMI-TCS
A6: FERRONORTE | B6: 74 | C6: 7 | D6: 8.448 | E6: TRP-TAP | F6: TRPPAT2 | G6: MARCO INICIAL - ALTO ARAGUAIA | H6: TMI-TCS
A7: FERRONORTE | B7: 74 | C7: 8.448 | D7: 11.754 | E7: TRP-TAP | F7: TRPK12 | G7: MARCO INICIAL - ALTO ARAGUAIA | H7: TMI-TCS
A8: FERRONORTE | B8: 74 | C8: 11.754 | D8: 13.235 | E8: TRP-TAP | F8: K12TEL1 | G8: MARCO INICIAL - ALTO ARAGUAIA | H8: TMI-TCS
A9: FERRONORTE | B9: 74 | C9: 11.754 | D9: 13.694 | E9: TRP-TAP | F9: K12TEL2 | G9: MARCO INICIAL - ALTO ARAGUAIA | H9: TMI-TCS
A10: FERRONORTE | B10: 74 | C10: 13.235 | D10: 23.232 | E10: TRP-TAP | F10: TELTAP | G10: MARCO INICIAL - ALTO ARAGUAIA | H10: TMI-TCS
A11: FERRONORTE | B11: 74 | C11: 23.232 | D11: 25 | E11: TAP | F11: TAP1 | G11: MARCO INICIAL - ALTO ARAGUAIA | H11: TMI-TCS
A12: FERRONORTE | B12: 74 | C12: 23.232 | D12: 25 | E12: TAP | F12: TAP2 | G12: MARCO INICIAL - ALTO ARAGUAIA | H12: TMI-TCS
A13: FERRONORTE | B13: 74 | C13: 25 | D13: 26.449 | E13: TAP-TLG | F13: TAPPAT1 | G13: MARCO INICIAL - ALTO ARAGUAIA | H13: TMI-TCS
... A39: FERRONORTE | B39: 74 | C39: 111.369 | D39: 112.855 | E39: TIN-TSJ | F39: TIN113 | G39: MARCO INICIAL - ALTO ARAGUAIA | H39: TMI-TCS
A40: FERRONORTE | B40: 74 | C40: 112.855 | D40: 118 | E40: TIN-TSJ | F40: 113118 | G40: MARCO INICIAL - ALTO ARAGUAIA | H40: TMI-TCS
A41: FERRONORTE | B41: 74 | C41: 118 | D41: 124.181 | E41: TIN-TSJ | F41: 118TSJ | G41: MARCO INICIAL - ALTO ARAGUAIA | H41: TMI-TCS
A42: FERRONORTE | B42: 74 | C42: 124.181 | D42: 126 | E42: TSJ | F42: TSJ1 | G42: MARCO INICIAL - ALTO ARAGUAIA | H42: TMI-TCS
A43: FERRONORTE | B43: 74 | C43: 124.181 | D43: 126 | E43: TSJ | F43: TSJ2 | G43: MARCO INICIAL - ALTO ARAGUAIA | H43: TMI-TCS
A44: FERRONORTE | B44: 74 | C44: 126 | D44: 126.899 | E44: TSJ-TMO | F44: TSJPAT1 | G44: MARCO INICIAL - ALTO ARAGUAIA | H44: TMI-TCS
A45: FERRONORTE | B45: 74 | C45: 126 | D45: 126.899 | E45: TSJ-TMO | F45: TSJPAT2 | G45: MARCO INICIAL - ALTO ARAGUAIA | H45: TMI-TCS
A46: FERRONORTE | B46: 74 | C46: 126.899 | D46: 135 | E46: TSJ-TMO | F46: TSJ135 | G46: MARCO INICIAL - ALTO ARAGUAIA | H46: TMI-TCS
A47: FERRONORTE | B47: 74 | C47: 135 | D47: 143.268 | E47: TSJ-TMO | F47: 135TMO | G47: MARCO INICIAL - ALTO ARAGUAIA | H47: TMI-TCS
A48: FERRONORTE | B48: 74 | C48: 143.268 | D48: 145 | E48: TMO | F48: TMO1 | G48: MARCO INICIAL - ALTO ARAGUAIA | H48: TMI-TCS
A49: FERRONORTE | B49: 74 | C49: 143.268 | D49: 145 | E49: TMO | F49: TMO2 | G49: MARCO INICIAL - ALTO ARAGUAIA | H49: TMI-TCS
A50: FERRONORTE | B50: 74 | C50: 145 | D50: 146.219 | E50: TMO-TCE | F50: TMOPAT1 | G50: MARCO INICIAL - ALTO ARAGUAIA | H50: TMI-TCS
A51: FERRONORTE | B51: 74 | C51: 145 | D51: 146.219 | E51: TMO-TCE | F51: TMOPAT2 | G51: MARCO INICIAL - ALTO ARAGUAIA | H51: TMI-TCS
A52: FERRONORTE | B52: 74 | C52: 146.219 | D52: 155 | E52: TMO-TCE | F52: TMO155 | G52: MARCO INICIAL - ALTO ARAGUAIA | H52: TMI-TCS
... A64: FERRONORTE | B64: 74 | C64: 189.966 | D64: 201 | E64: TID-TVI | F64: TID201 | G64: MARCO INICIAL - ALTO ARAGUAIA | H64: TMI-TCS
A65: FERRONORTE | B65: 74 | C65: 201 | D65: 213 | E65: TID-TVI | F65: 201213 | G65: MARCO INICIAL - ALTO ARAGUAIA | H65: TMI-TCS
A66: FERRONORTE | B66: 74 | C66: 213 | D66: 225.247 | E66: TID-TVI | F66: 213TVI | G66: MARCO INICIAL - ALTO ARAGUAIA | H66: TMI-TCS
A67: FERRONORTE | B67: 74 | C67: 225.247 | D67: 227 | E67: TVI | F67: TVI1 | G67: MARCO INICIAL - ALTO ARAGUAIA | H67: TMI-TCS
A68: FERRONORTE | B68: 74 | C68: 225.247 | D68: 227 | E68: TVI | F68: TVI2 | G68: MARCO INICIAL - ALTO ARAGUAIA | H68: TMI-TCS
A69: FERRONORTE | B69: 74 | C69: 227 | D69: 227.952 | E69: TVI-TJA | F69: TVIPAT1 | G69: MARCO INICIAL - ALTO ARAGUAIA | H69: TMI-TCS
A70: FERRONORTE | B70: 74 | C70: 227 | D70: 227.952 | E70: TVI-TJA | F70: TVIPAT2 | G70: MARCO INICIAL - ALTO ARAGUAIA | H70: TMI-TCS
A71: FERRONORTE | B71: 74 | C71: 227.952 | D71: 239 | E71: TVI-TJA | F71: TVI239 | G71: MARCO INICIAL - ALTO ARAGUAIA | H71: TMI-TCS
A72: FERRONORTE | B72: 74 | C72: 239 | D72: 251 | E72: TVI-TJA | F72: 239251 | G72: MARCO INICIAL - ALTO ARAGUAIA | H72: TMI-TCS
A73: FERRONORTE | B73: 74 | C73: 251 | D73: 262.674 | E73: TVI-TJA | F73: 251TJA | G73: MARCO INICIAL - ALTO ARAGUAIA | H73: TMI-TCS
A74: FERRONORTE | B74: 74 | C74: 262.674 | D74: 264 | E74: TJA | F74: TJA1 | G74: MARCO INICIAL - ALTO ARAGUAIA | H74: TMI-TCS
A75: FERRONORTE | B75: 74 | C75: 262.674 | D75: 264 | E75: TJA | F75: TJA2 | G75: MARCO INICIAL - ALTO ARAGUAIA | H75: TMI-TCS
A76: FERRONORTE | B76: 74 | C76: 264 | D76: 265.632 | E76: TJA-TCS | F76: TJAPAT1 | G76: MARCO INICIAL - ALTO ARAGUAIA | H76: TMI-TCS
...

Sheet SELEÇÕES
A1: MAQUINISTAS | C1: ACIONAMENTO | E1: PRÉVIA | G1: DESVIO | I1: PROGRAMADO? | K1: ProgramaPCM | M1: Prioridade
A2: FIXO | C2: SBR | E2: 1 | G2: VIA | I2: SIM | K2: Contrato | M2: P0
A3: ESCALA | C3: AGD ACIONAMENTO PCM | E3: 2 | G3: - | I3: NÃO | K3: Oportunidade | M3: P1
A4: FIXO + ESCALA | C4: ACIONAMENTO | I4: OPORTUNIDADE | K4: Extra | M4: P2
A5: - | C5: - | M5: P3
M6: P4
M7: P5
A13: TO | B13: Não Controláveis | C13: TI | D13: Pátio | E13: Tração | F13: PCM Mecânica | G13: Mecânica | H13: Mecanização | I13: PCM VIA | J13: CCO Escala | K13: CCO Circulação | L13: Super | M13: Expansão | N13: Modernização | O13: Infraestrutura | P13: OK | Q13: Anomalia | R13: Condições Climática | S13: Confiabilidade | T13: Engenharia | U13: Falta de Contrato | V13: Sem Oportunidade | W13: Outras Ferrovias
A14: Embarcado | B14: Vandalismo | C14: Sistema | D14: Operação | E14: Operação | F14: Locomotiva | G14: Locomotiva | H14: Operação | I14: Recursos Internos | J14: Equipagem | K14: Intervalo Contrato | L14: Equipamento | M14: Equipamento | N14: Equipamento | O14: Equipamento | P14: OK | Q14: Via | R14: Temperatura | S14: Operação | T14: Operação | U14: Falta de Contrato | V14: Sem Oportunidade | W14: Outras Ferrovias
A15: Não Embarcado | B15: Acidente | C15: ="" | G15: Vagão | H15: Ativos | I15: Programação | K15: Intervalo Oportunidade | L15: Execução | M15: Execução | N15: Execução | O15: Execução | Q15: Mecânica | R15: Chuva | S15: Ativo | T15: Ativo
A16: Operação | C16: ="" | K16: Intervalo Extra | R16: Ventos Fortes
K17: Programação
A28: TOEmbarcado | B28: TONãoEmbarcado | C28: TOOperação | D28: NãoControláveisVandalismo | E28: NãoControláveisAcidente | F28: TISistema | G28: PátioOperação | H28: TraçãoOperação | I28: PCMMecânicaLocomotiva | J28: MecânicaLocomotiva | K28: MecânicaVagão | L28: MecanizaçãoOperação | M28: MecanizaçãoAtivos | N28: PCMVIARecursosInternos | O28: PCMVIAProgramação | P28: CCOEscalaEquipagem | Q28: CCOCirculaçãoIntervaloContrato | R28: CCOCirculaçãoProgramação | S28: CCOCirculaçãoIntervaloOportunidade | T28: SuperEquipamento | U28: SuperExecução | V28: ExpansãoEquipamento | W28: ExpansãoExecução | X28: ModernizaçãoEquipamento | Y28: ModernizaçãoExecução | Z28: InfraestruturaEquipamento | AA28: InfraestruturaExecução | AB28: OKOK | AC28: AnomaliaVia | AD28: AnomaliaMecânica | AE28: CondiçõesClimáticaTemperatura | AF28: CondiçõesClimáticaVentos Fortes | AG28: CondiçõesClimáticaChuva | AH28: CCOCirculaçãoIntervaloExtra | AI28: ConfiabilidadeOperação | AJ28: ConfiabilidadeAtivo | AK28: EngenhariaOperação | AL28: EngenhariaAtivo | AM28: Falta de ContratoFalta de Contrato | AN28: SemOportunidadeSemOportunidade | AO28: OutrasFerroviasOutrasFerrovias
A29: Avaria de CBL | B29: AMV sem indicação | C29: Alteração de programação da turma | D29: Locomotiva | E29: Acidente | F29: Sistema licenciamento indisponível | G29: Manobra indisponível | H29: Maquinista indisponível | I29: Alteração de programação | J29: Avaria | K29: Avaria | L29: Operador indisponível | M29: Avaria em veículo (Mecanização) | N29: Cancelado devido priorização | O29: Falta de OS | P29: Atraso chegada maquinista | Q29: Realizado entre trens | R29: Desvio alocação de locomotiva | S29: Sem oportunidade | T29: Avaria (Escavadeira / caminhão / munck) | U29: Erro de programação | V29: Avaria (Escavadeira / caminhão / munck) | W29: Erro de programação | X29: Avaria (Escavadeira / caminhão / munck / Socadora) | Y29: Erro de programação | Z29: Avaria (Escavadeira / caminhão / munck) | AA29: Erro de programação | AB29: OK | AC29: Defeito na via | AD29: Avaria em trem | AE29: Temperatura Alta | AF29: Ventos Fortes | AG29: Chuva | AH29: Serviço extra contrato | AI29: Falta de Equipe | AJ29: Avaria | AK29: Falta de Equipe | AL29: Avaria | AM29: Falta de Contrato | AN29: Sem Oportunidade | AO29: Outras Ferrovias
D30: Vagão | F30: Queda / Instabilidade de sistema | G30: Linha ocupada | H30: Atualização malha | I30: Locomotiva indisponível | L30: Operador não habilitado | M30: Avaria em veículo (Detecção) | N30: Alteração de programação | O30: Alteração de programação (Equipamento) | P30: Jornada maquinista excedida | Q30: Concedido intervalo parcial | S30: Realizado entre trens | T30: Avaria (Ferramental) | U30: Alteração de programação | V30: Avaria (Ferramental) | W30: Alteração de programação | X30: Avaria (Ferramental) | Y30: Alteração de programação | Z30: Avaria (Ferramental) | AA30: odni | AE30: Temperatura Baixa | AI30: Alteração de Programação | AJ30: Manutenção | AK30: Alteração de Programação
D31: Via de circulação | L31: Desvio de escala | M31: Desvio programação (Manutenção) | N31: Erro de programação | O31: Falta de equipamento / material | P31: Falta Maquinista (Contrato) | Q31: Intervalo negado em D-1 | S31: Concedido intervalo parcial | U31: Quando reduzido da turma | W31: Quando reduzido da turma | Y31: Quando reduzido da turma | AA31: Quando reduzido da turma | AE31: Oscilação de Temperatura | AI31: Falha de programação
D32: Equipamento via | L32: Baixa produtividade | P32: Falta Maquinista (Extra) | Q32: Intervalo Concedido fora do horário programado | S32: Intervalo negado em D-1 | U32: Falta de turma (Não Justificado) | W32: Falta de turma (Não Justificado) | Y32: Falta de turma (Não Justificado) | AA32: Falta de turma (Não Justificado) | AI32: Desvio de escala
D33: Ativo mecanização | L33: Risco de exceder a jornada | Q33: Fluxo intenso de trens | S33: Intervalo Concedido fora do horário programado | U33: Equipe interditada | W33: Equipe interditada | Y33: Equipe interditada | AA33: Equipe interditada | AI33: Risco de exceder a jornada
L34: Abastecimento | Q34: Propagação de TI | S34: Fluxo intenso de trens | U34: Falta de insumo / material | W34: Falta de insumo / material | Y34: Falta de insumo / material | AA34: Falta de insumo / material
L35: Desvio de programação | Q35: Propagação de avaria de trens | S35: Propagação de TI | U35: Desvio escala da turma | W35: Desvio escala da turma | Y35: Desvio escala da turma | AA35: Desvio escala da turma
Q36: Propagação de vandalismo | S36: Propagação de avaria de trens | U36: Intervalo utilizado parcialmente | W36: Intervalo utilizado parcialmente | Y36: Intervalo utilizado parcialmente | AA36: Intervalo utilizado parcialmente
Q37: Propagação por motivo via | S37: Propagação de vandalismo | U37: Baixa produtividade | W37: Baixa produtividade | Y37: Baixa produtividade | AA37: Baixa produtividade
Q38: Erro CCO | S38: Propagação por motivo via | U38: Falha de execução | W38: Falha de execução | Y38: Falha de execução | AA38: Falha de execução
Q39: Intervalo Fracionado | S39: Erro CCO
A43: SUBs
A44: 72
A45: 74
A46: 78
A47: 98
A48: 101
A49: 102
A50: 103

Sheet FN_MC
F1: PROGRAMA | AI1: ; | BH1: GESTÃO DE ACOMPANHAMENTO | BM1: FECHAMENTO
F2: ITENS GUIA | S2: RESPONSABILIDADE | AA2: RECURSO | AI2: ITENS GUIA | AS2: INTERVALO | BA2: PRODUÇÃO | BC2: RESPONSABILIDADE
F3: O QUE? | H3: ONDE? | O3: INTERVALO | Q3: PODUÇÃO | S3: QUEM VAI RESPONDER PELA EXECUÇÃO? | W3: GESTÃO | AA3: EQUIPAGEM | AE3: ATIVOS | AI3: O QUE? | AK3: ONDE? | AS3: PARCIAL 1 | AU3: PARCIAL 2 | AW3: PARCIAL 3 | AY3: TOTAL | BC3: QUEM VAI RESPONDER PELA EXECUÇÃO? | BM3: ANALISE | BQ3: %
A4: FORMULA | B4: ESCREVE | C4: FORMULA | D4: SELECIONAR | F4: SELECIONAR | G4: FORMULA | H4: ESCREVE | I4: ESCREVE | J4: ESCREVE | K4: ESCREVE | L4: ESCREVE | M4: ESCREVE | N4: ESCREVE | O4: ESCREVE | P4: ESCREVE | Q4: ESCREVE | R4: FORMULA | S4: SELECIONAR | T4: SELECIONAR | U4: FORMULA | V4: ESCREVE | W4: ESCREVE | X4: SELECIONAR | Y4: SELECIONAR | Z4: SELECIONAR | AA4: ESCREVE | AB4: SELECIONAR | AC4: SELECIONAR | AD4: ESCREVE | AE4: ESCREVE | AF4: ESCREVE | AG4: ESCREVE | AI4: SELECIONAR | AJ4: FORMULA | AK4: ESCREVE | AL4: ESCREVE | AM4: ESCREVE | AN4: ESCREVE | AO4: ESCREVE | AP4: ESCREVE | AQ4: ESCREVE | AR4: ESCREVE | AS4: ESCREVE | AT4: ESCREVE | AU4: ESCREVE | AV4: ESCREVE | AW4: ESCREVE | AX4: ESCREVE | AY4: FORMULA | AZ4: SELECIONAR | BA4: ESCREVE | BB4: FORMULA | BC4: SELECIONAR | BD4: SELECIONAR | BE4: FORMULA | BF4: ESCREVE | BG4: * | BH4: ESCREVE | BI4: ESCREVE | BJ4: ESCREVE | BK4: ESCREVE | BL4: * | BM4: SELECIONAR | BN4: SELECIONAR | BO4: SELECIONAR | BP4: ESCREVE | BQ4: FORMULA | BR4: FORMULA | BS4: FORMULA
A5: CHAVE | B5: DATA | C5: Semana | D5: ATIVO | E5: *1 | F5: Atividade | G5: Atividade - Inidicador | H5: Local - Partida | I5: Local - Encerramento | J5: SUB | K5: KM - Inicio | L5: KM - Fim | M5: Entre - Estações | N5: SB | O5: Inicia | P5: Duração | Q5: Quantidade | R5: Unidade | S5: Gerência da Via | T5: Coordenação da Via | U5: Trecho | V5: Responsavel pelo boletim | W5: Detalhe Programação | X5: Programar para D+1 | Y5: Confirmação programação | Z5: Prioridade | AA5: Qtd. Maquinista | AB5: Tipo de Maquinista (Fixo / Escala) | AC5: Tipo de Acionamento | AD5: Apresentação no lastro | AE5: Ativo - 1 | AF5: Ativo - 2 | AG5: Vagões - Qtd. | AH5: *2 | AI5: Atividade_1 | AJ5: Atividade - PDM | AK5: Local - Partida_2 | AL5: Local - Encerramento_3 | AM5: Entre-Locais | AN5: SB_4 | AO5: SUB_5 | AP5: KM - ínicio | AQ5: KM - Fim_6 | AR5: HR Turma Pronta | AS5: Inicio | AT5: Fim | AU5: Inicio_7 | AV5: Fim_8 | AW5: Inicio_9 | AX5: Fim_10 | AY5: TOTAL | AZ5: LIBERADO PELO CCO | BA5: Quantidade_11 | BB5: Unidade_12 | BC5: Gerência da Via_13 | BD5: Coordenação da Via_14 | BE5: Trecho_15 | BF5: Responsavel pelo boletim_16 | BG5: *3 | BH5: Status | BI5: Prévia CCO 22h | BJ5: Prévia - 1 | BK5: Prévia - 2 | BL5: *4 | BM5: Responsabilidade | BN5: Fechamento - Impacto | BO5: Detalhe - Fechamento | BP5: Justificativa | BQ5: Analise Prévia | BR5: Intervalo | BS5: QTD | BT5: =IF(BN5="","",SUBSTITUTE(BM5," ","")&SUBSTITUTE(BN5," ","")) -> ResponsabilidadeFechamento-Impacto
A6: =D6&B6 -> W70 | C6: =IF(BS_CONTROLE[[#This Row],[DATA]]="","",WEEKNUM(BS_CONTROLE[[#This Row],[DATA]])) | D6: W70 | F6: DESLOCAMENTO | G6: =IF(D6="","*",VLOOKUP(F6,BS_ATIVIDADE[#All],3,FALSE)) -> OUTROS | H6: TGR2 | I6: TIQ | J6: 98 | K6: 501 | L6: - | M6: TGR-TIQ | N6: TGRTIQ | O6: 0.375 | P6: 0.041666667 | Q6: 1 | R6: =IFERROR(_xlfn.XLOOKUP(F6, BS_ATIVIDADE[ATIVIDADE],BS_ATIVIDADE[UNIDADE] ), "*") -> BINÁRIO | S6: {=_xlfn.XLOOKUP( 1, ( TabelaMap[SUB] = BS_CONTROLE[[#This Row],[SUB]]) * ( TabelaMap[KM Inicio] <= BS_CONTROLE[[#This Row],[KM - Inicio]]) * ( TabelaMap[KM Fim] >= BS_CONTROLE[[#This Row],[KM - Inicio]]), TabelaMap[Gerência], "-", 0 )} -> - | T6: {=_xlfn.XLOOKUP( 1, ( TabelaMap[SUB] = BS_CONTROLE[[#This Row],[SUB]]) * ( TabelaMap[KM Inicio] <= BS_CONTROLE[[#This Row],[KM - Inicio]]) * ( TabelaMap[KM Fim] >= BS_CONTROLE[[#This Row],[KM - Inicio]]), TabelaMap[Trecho Coordenação], "-", 0 )} -> - | U6: =IFERROR(_xlfn.XLOOKUP(J6, BASE_MAPA!$B$2:$B$420, BASE_MAPA!$G$2:$G$420), "ERRO") -> ALTO ARAGUAIA - RONDONOPOLIS | V6: Camila | W6: Deslocamento | X6: Oportunidade | AA6: 2 (Enio e Daniel) | AB6: FIXO | AI6: =IF(BS_CONTROLE[[#This Row],[Atividade]]=0, "-", BS_CONTROLE[[#This Row],[Atividade]]) -> DESLOCAMENTO | AJ6: =IF(D6="","*",VLOOKUP(AI6,BS_ATIVIDADE[#Data],3,FALSE)) -> OUTROS | AK6: =IF(BS_CONTROLE[[#This Row],[Local - Partida]]=0, "-", BS_CONTROLE[[#This Row],[Local - Partida]]) -> TGR2 | AL6: =IF(BS_CONTROLE[[#This Row],[Local - Encerramento]]=0, "-", BS_CONTROLE[[#This Row],[Local - Encerramento]]) -> TIQ | AM6: =IF(BS_CONTROLE[[#This Row],[Entre - Estações]]=0, "-", BS_CONTROLE[[#This Row],[Entre - Estações]]) -> TGR-TIQ | AN6: =IF(BS_CONTROLE[[#This Row],[SB]]=0, "-", BS_CONTROLE[[#This Row],[SB]]) -> TGRTIQ | AO6: =IF(BS_CONTROLE[[#This Row],[SUB]]=0, "-", BS_CONTROLE[[#This Row],[SUB]]) -> 98 | AP6: =IF(BS_CONTROLE[[#This Row],[KM - Inicio]]=0, "-", BS_CONTROLE[[#This Row],[KM - Inicio]]) -> 501 | AQ6: =IF(BS_CONTROLE[[#This Row],[KM - Fim]]=0, "-", BS_CONTROLE[[#This Row],[KM - Fim]]) -> - | AY6: =IF(D6="","*",IFERROR(IF(ISODD(COUNT(AS6:AX8)),"ERRO",SUM((AT6-AS6),(AV6-AU6),(AX6-AW6))),"ERRO")) -> 0 | BB6: =IFERROR(_xlfn.XLOOKUP(AI6, BS_ATIVIDADE[ATIVIDADE],BS_ATIVIDADE[UNIDADE] ), "*") -> BINÁRIO | BC6: {=_xlfn.XLOOKUP( 1, ( TabelaMap[SUB] = BS_CONTROLE[[#This Row],[SUB]]) * ( TabelaMap[KM Inicio] <= BS_CONTROLE[[#This Row],[KM - Inicio]]) * ( TabelaMap[KM Fim] >= BS_CONTROLE[[#This Row],[KM - Inicio]]), TabelaMap[Gerência], "-", 0 )} -> - | BD6: {=_xlfn.XLOOKUP( 1, ( TabelaMap[SUB] = BS_CONTROLE[[#This Row],[SUB_5]]) * ( TabelaMap[KM Inicio] <= BS_CONTROLE[[#This Row],[KM - Inicio]]) * ( TabelaMap[KM Fim] >= BS_CONTROLE[[#This Row],[KM - Inicio]]), TabelaMap[Trecho Coordenação], "-", 0 )} -> - | BE6: =IFERROR(_xlfn.XLOOKUP(AO6, BASE_MAPA!$B$2:$B$420, BASE_MAPA!$G$2:$G$420), "ERRO") -> ALTO ARAGUAIA - RONDONOPOLIS | BF6: =IF(BS_CONTROLE[[#This Row],[Responsavel pelo boletim]]=0, "-", BS_CONTROLE[[#This Row],[Responsavel pelo boletim]]) -> Camila | BQ6: =IF(AND(BR6<1,BS6<1),"Produção e Intervalo",IF(BR6<1,"Intervalo",IF(BS6<1,"Produção","Aderente"))) -> Aderente | BR6: =IF(OR(B6="",F6=""),"*",AY6/P6) -> * | BS6: =IF(OR(B6="",F6=""),"*",BA6/Q6) -> * | BT6: =IF(BN6="","",SUBSTITUTE(BM6," ","")&SUBSTITUTE(BN6," ",""))
A7: =D7&B7 | C7: =IF(BS_CONTROLE[[#This Row],[DATA]]="","",WEEKNUM(BS_CONTROLE[[#This Row],[DATA]])) | G7: =IF(D7="","*",VLOOKUP(F7,BS_ATIVIDADE[#All],3,FALSE)) -> * | M7: {=_xlfn.XLOOKUP( 1, ( TabelaMap[SUB] = BS_CONTROLE[[#This Row],[SUB]]) * ( TabelaMap[KM Inicio] <= BS_CONTROLE[[#This Row],[KM - Inicio]]) * ( TabelaMap[KM Fim] >= BS_CONTROLE[[#This Row],[KM - Inicio]]), TabelaMap[Trecho], "-", 0 )} -> - | N7: {=_xlfn.XLOOKUP( 1, ( TabelaMap[SUB] = BS_CONTROLE[[#This Row],[SUB]]) * ( TabelaMap[KM Inicio] <= BS_CONTROLE[[#This Row],[KM - Inicio]]) * ( TabelaMap[KM Fim] >= BS_CONTROLE[[#This Row],[KM - Inicio]]), TabelaMap[SB], "-", 0 )} -> - | R7: =IFERROR(_xlfn.XLOOKUP(F7, BS_ATIVIDADE[ATIVIDADE],BS_ATIVIDADE[UNIDADE] ), "*") -> * | S7: {=_xlfn.XLOOKUP( 1, ( TabelaMap[SUB] = BS_CONTROLE[[#This Row],[SUB]]) * ( TabelaMap[KM Inicio] <= BS_CONTROLE[[#This Row],[KM - Inicio]]) * ( TabelaMap[KM Fim] >= BS_CONTROLE[[#This Row],[KM - Inicio]]), TabelaMap[Gerência], "-", 0 )} -> - | T7: {=_xlfn.XLOOKUP( 1, ( TabelaMap[SUB] = BS_CONTROLE[[#This Row],[SUB]]) * ( TabelaMap[KM Inicio] <= BS_CONTROLE[[#This Row],[KM - Inicio]]) * ( TabelaMap[KM Fim] >= BS_CONTROLE[[#This Row],[KM - Inicio]]), TabelaMap[Trecho Coordenação], "-", 0 )} -> - | U7: =IFERROR(_xlfn.XLOOKUP(J7, BASE_MAPA!$B$2:$B$420, BASE_MAPA!$G$2:$G$420), "ERRO") -> ERRO | AI7: =IF(BS_CONTROLE[[#This Row],[Atividade]]=0, "-", BS_CONTROLE[[#This Row],[Atividade]]) -> - | AJ7: =IF(D7="","*",VLOOKUP(AI7,BS_ATIVIDADE[#Data],3,FALSE)) -> * | AK7: =IF(BS_CONTROLE[[#This Row],[Local - Partida]]=0, "-", BS_CONTROLE[[#This Row],[Local - Partida]]) -> - | AL7: =IF(BS_CONTROLE[[#This Row],[Local - Encerramento]]=0, "-", BS_CONTROLE[[#This Row],[Local - Encerramento]]) -> - | AM7: =IF(BS_CONTROLE[[#This Row],[Entre - Estações]]=0, "-", BS_CONTROLE[[#This Row],[Entre - Estações]]) -> - | AN7: =IF(BS_CONTROLE[[#This Row],[SB]]=0, "-", BS_CONTROLE[[#This Row],[SB]]) -> - | AO7: =IF(BS_CONTROLE[[#This Row],[SUB]]=0, "-", BS_CONTROLE[[#This Row],[SUB]]) -> - | AP7: =IF(BS_CONTROLE[[#This Row],[KM - Inicio]]=0, "-", BS_CONTROLE[[#This Row],[KM - Inicio]]) -> - | AQ7: =IF(BS_CONTROLE[[#This Row],[KM - Fim]]=0, "-", BS_CONTROLE[[#This Row],[KM - Fim]]) -> - | AY7: =IF(D7="","*",IFERROR(IF(ISODD(COUNT(AS7:AX9)),"ERRO",SUM((AT7-AS7),(AV7-AU7),(AX7-AW7))),"ERRO")) -> * | BB7: =IFERROR(_xlfn.XLOOKUP(AI7, BS_ATIVIDADE[ATIVIDADE],BS_ATIVIDADE[UNIDADE] ), "*") -> * | BC7: {=_xlfn.XLOOKUP( 1, ( TabelaMap[SUB] = BS_CONTROLE[[#This Row],[SUB]]) * ( TabelaMap[KM Inicio] <= BS_CONTROLE[[#This Row],[KM - Inicio]]) * ( TabelaMap[KM Fim] >= BS_CONTROLE[[#This Row],[KM - Inicio]]), TabelaMap[Gerência], "-", 0 )} -> - | BD7: {=_xlfn.XLOOKUP( 1, ( TabelaMap[SUB] = BS_CONTROLE[[#This Row],[SUB_5]]) * ( TabelaMap[KM Inicio] <= BS_CONTROLE[[#This Row],[KM - Inicio]]) * ( TabelaMap[KM Fim] >= BS_CONTROLE[[#This Row],[KM - Inicio]]), TabelaMap[Trecho Coordenação], "-", 0 )} -> - | BE7: =IFERROR(_xlfn.XLOOKUP(AO7, BASE_MAPA!$B$2:$B$420, BASE_MAPA!$G$2:$G$420), "ERRO") -> ERRO | BF7: =IF(BS_CONTROLE[[#This Row],[Responsavel pelo boletim]]=0, "-", BS_CONTROLE[[#This Row],[Responsavel pelo boletim]]) -> - | BQ7: =IF(AND(BR7<1,BS7<1),"Produção e Intervalo",IF(BR7<1,"Intervalo",IF(BS7<1,"Produção","Aderente"))) -> Aderente | BR7: =IF(OR(B7="",F7=""),"*",AY7/P7) -> * | BS7: =IF(OR(B7="",F7=""),"*",BA7/Q7) -> *
A8: =D8&B8 -> V7746056 | B8: 46056 | C8: =IF(BS_CONTROLE[[#This Row],[DATA]]="","",WEEKNUM(BS_CONTROLE[[#This Row],[DATA]])) -> 6 | D8: V77 | F8: INSPEÇÃO AUTO DE LINHA | G8: =IF(D8="","*",VLOOKUP(F8,BS_ATIVIDADE[#All],3,FALSE)) -> OUTROS | H8: TIQ1 | I8: TGR2 | J8: 98 | K8: 616 | L8: - | M8: TIQ-TGR | N8: TIQTGR | O8: 0.375 | P8: 0.041666667 | Q8: 1 | R8: =IFERROR(_xlfn.XLOOKUP(F8, BS_ATIVIDADE[ATIVIDADE],BS_ATIVIDADE[UNIDADE] ), "*") -> BINÁRIO | S8: {=_xlfn.XLOOKUP( 1, ( TabelaMap[SUB] = BS_CONTROLE[[#This Row],[SUB]]) * ( TabelaMap[KM Inicio] <= BS_CONTROLE[[#This Row],[KM - Inicio]]) * ( TabelaMap[KM Fim] >= BS_CONTROLE[[#This Row],[KM - Inicio]]), TabelaMap[Gerência], "-", 0 )} -> FERRONORTE | T8: {=_xlfn.XLOOKUP( 1, ( TabelaMap[SUB] = BS_CONTROLE[[#This Row],[SUB]]) * ( TabelaMap[KM Inicio] <= BS_CONTROLE[[#This Row],[KM - Inicio]]) * ( TabelaMap[KM Fim] >= BS_CONTROLE[[#This Row],[KM - Inicio]]), TabelaMap[Trecho Coordenação], "-", 0 )} -> TGR-TRO | U8: =IFERROR(_xlfn.XLOOKUP(J8, BASE_MAPA!$B$2:$B$420, BASE_MAPA!$G$2:$G$420), "ERRO") -> ALTO ARAGUAIA - RONDONOPOLIS | V8: Camiila | W8: Inspeção auto de linha | X8: Oportunidade | AA8: 1 | AB8: FIXO | AC8: - | AD8: 0.29166667 | AE8: - | AF8: - | AG8: - | AI8: =IF(BS_CONTROLE[[#This Row],[Atividade]]=0, "-", BS_CONTROLE[[#This Row],[Atividade]]) -> INSPEÇÃO AUTO DE LINHA | AJ8: =IF(D8="","*",VLOOKUP(AI8,BS_ATIVIDADE[#Data],3,FALSE)) -> OUTROS | AK8: =IF(BS_CONTROLE[[#This Row],[Local - Partida]]=0, "-", BS_CONTROLE[[#This Row],[Local - Partida]]) -> TIQ1 | AL8: =IF(BS_CONTROLE[[#This Row],[Local - Encerramento]]=0, "-", BS_CONTROLE[[#This Row],[Local - Encerramento]]) -> TGR2 | AM8: =IF(BS_CONTROLE[[#This Row],[Entre - Estações]]=0, "-", BS_CONTROLE[[#This Row],[Entre - Estações]]) -> TIQ-TGR | AN8: =IF(BS_CONTROLE[[#This Row],[SB]]=0, "-", BS_CONTROLE[[#This Row],[SB]]) -> TIQTGR | AO8: =IF(BS_CONTROLE[[#This Row],[SUB]]=0, "-", BS_CONTROLE[[#This Row],[SUB]]) -> 98 | AP8: =IF(BS_CONTROLE[[#This Row],[KM - Inicio]]=0, "-", BS_CONTROLE[[#This Row],[KM - Inicio]]) -> 616 | AQ8: =IF(BS_CONTROLE[[#This Row],[KM - Fim]]=0, "-", BS_CONTROLE[[#This Row],[KM - Fim]]) -> - | AR8: 0.39583333 | AS8: 0.45347222 | AT8: 0.49513889 | AY8: =IF(D8="","*",IFERROR(IF(ISODD(COUNT(AS8:AX10)),"ERRO",SUM((AT8-AS8),(AV8-AU8),(AX8-AW8))),"ERRO")) -> 0.041666667 | BA8: 1 | BB8: =IFERROR(_xlfn.XLOOKUP(AI8, BS_ATIVIDADE[ATIVIDADE],BS_ATIVIDADE[UNIDADE] ), "*") -> BINÁRIO | BC8: {=_xlfn.XLOOKUP( 1, ( TabelaMap[SUB] = BS_CONTROLE[[#This Row],[SUB]]) * ( TabelaMap[KM Inicio] <= BS_CONTROLE[[#This Row],[KM - Inicio]]) * ( TabelaMap[KM Fim] >= BS_CONTROLE[[#This Row],[KM - Inicio]]), TabelaMap[Gerência], "-", 0 )} -> FERRONORTE | BD8: {=_xlfn.XLOOKUP( 1, ( TabelaMap[SUB] = BS_CONTROLE[[#This Row],[SUB_5]]) * ( TabelaMap[KM Inicio] <= BS_CONTROLE[[#This Row],[KM - Inicio]]) * ( TabelaMap[KM Fim] >= BS_CONTROLE[[#This Row],[KM - Inicio]]), TabelaMap[Trecho Coordenação], "-", 0 )} -> TGR-TRO | BE8: =IFERROR(_xlfn.XLOOKUP(AO8, BASE_MAPA!$B$2:$B$420, BASE_MAPA!$G$2:$G$420), "ERRO") -> ALTO ARAGUAIA - RONDONOPOLIS | BF8: =IF(BS_CONTROLE[[#This Row],[Responsavel pelo boletim]]=0, "-", BS_CONTROLE[[#This Row],[Responsavel pelo boletim]]) -> Camiila | BH8: 2 | BJ8: MC1 08:08, faixa após I29, previsão 11h | BK8: MC1 as 09:30 - Licença as 10:53h | BM8: OK | BN8: OK | BO8: OK | BQ8: =IF(AND(BR8<1,BS8<1),"Produção e Intervalo",IF(BR8<1,"Intervalo",IF(BS8<1,"Produção","Aderente"))) -> Aderente | BR8: =IF(OR(B8="",F8=""),"*",AY8/P8) -> 1 | BS8: =IF(OR(B8="",F8=""),"*",BA8/Q8) -> 1 | BT8: =IF(BN8="","",SUBSTITUTE(BM8," ","")&SUBSTITUTE(BN8," ","")) -> OKOK
A9: =D9&B9 -> V8646055 | B9: 46055 | C9: =IF(BS_CONTROLE[[#This Row],[DATA]]="","",WEEKNUM(BS_CONTROLE[[#This Row],[DATA]])) -> 6 | D9: V86 | E9: 2 | F9: MECANIZAÇÃO - SOCADORA | G9: =IF(D9="","*",VLOOKUP(F9,BS_ATIVIDADE[#All],3,FALSE)) -> MECANIZAÇÃO - SOCADORA | H9: TSF | I9: TSF | J9: 98 | K9: 746.5 | L9: 749 | M9: {=_xlfn.XLOOKUP( 1, ( TabelaMap[SUB] = BS_CONTROLE[[#This Row],[SUB]]) * ( TabelaMap[KM Inicio] <= BS_CONTROLE[[#This Row],[KM - Inicio]]) * ( TabelaMap[KM Fim] >= BS_CONTROLE[[#This Row],[KM - Inicio]]), TabelaMap[Trecho], "-", 0 )} -> TSF-TEX | N9: {=_xlfn.XLOOKUP( 1, ( TabelaMap[SUB] = BS_CONTROLE[[#This Row],[SUB]]) * ( TabelaMap[KM Inicio] <= BS_CONTROLE[[#This Row],[KM - Inicio]]) * ( TabelaMap[KM Fim] >= BS_CONTROLE[[#This Row],[KM - Inicio]]), TabelaMap[SB], "-", 0 )} -> 744TEX | O9: 0.41666667 | P9: 0.083333333 | Q9: 1120 | R9: =IFERROR(_xlfn.XLOOKUP(F9, BS_ATIVIDADE[ATIVIDADE],BS_ATIVIDADE[UNIDADE] ), "*") -> M | S9: {=_xlfn.XLOOKUP( 1, ( TabelaMap[SUB] = BS_CONTROLE[[#This Row],[SUB]]) * ( TabelaMap[KM Inicio] <= BS_CONTROLE[[#This Row],[KM - Inicio]]) * ( TabelaMap[KM Fim] >= BS_CONTROLE[[#This Row],[KM - Inicio]]), TabelaMap[Gerência], "-", 0 )} -> FERRONORTE | T9: {=_xlfn.XLOOKUP( 1, ( TabelaMap[SUB] = BS_CONTROLE[[#This Row],[SUB]]) * ( TabelaMap[KM Inicio] <= BS_CONTROLE[[#This Row],[KM - Inicio]]) * ( TabelaMap[KM Fim] >= BS_CONTROLE[[#This Row],[KM - Inicio]]), TabelaMap[Trecho Coordenação], "-", 0 )} -> TGR-TRO | U9: =IFERROR(_xlfn.XLOOKUP(J9, BASE_MAPA!$B$2:$B$420, BASE_MAPA!$G$2:$G$420), "ERRO") -> ALTO ARAGUAIA - RONDONOPOLIS | V9: Antonioni | W9: Socaria mecanizada | X9: Oportunidade | AA9: 1 | AB9: FIXO | AC9: - | AD9: 0.29166667 | AE9: 6636 | AF9: 6236 | AG9: - | AI9: =IF(BS_CONTROLE[[#This Row],[Atividade]]=0, "-", BS_CONTROLE[[#This Row],[Atividade]]) -> MECANIZAÇÃO - SOCADORA | AJ9: =IF(D9="","*",VLOOKUP(AI9,BS_ATIVIDADE[#Data],3,FALSE)) -> MECANIZAÇÃO - SOCADORA | AK9: =IF(BS_CONTROLE[[#This Row],[Local - Partida]]=0, "-", BS_CONTROLE[[#This Row],[Local - Partida]]) -> TSF | AL9: =IF(BS_CONTROLE[[#This Row],[Local - Encerramento]]=0, "-", BS_CONTROLE[[#This Row],[Local - Encerramento]]) -> TSF | AM9: =IF(BS_CONTROLE[[#This Row],[Entre - Estações]]=0, "-", BS_CONTROLE[[#This Row],[Entre - Estações]]) -> TSF-TEX | AN9: =IF(BS_CONTROLE[[#This Row],[SB]]=0, "-", BS_CONTROLE[[#This Row],[SB]]) -> 744TEX | AO9: =IF(BS_CONTROLE[[#This Row],[SUB]]=0, "-", BS_CONTROLE[[#This Row],[SUB]]) -> 98 | AP9: =IF(BS_CONTROLE[[#This Row],[KM - Inicio]]=0, "-", BS_CONTROLE[[#This Row],[KM - Inicio]]) -> 746.5 | AQ9: =IF(BS_CONTROLE[[#This Row],[KM - Fim]]=0, "-", BS_CONTROLE[[#This Row],[KM - Fim]]) -> 749 | AR9: 0.39513889 | AS9: 0.50138889 | AT9: 0.52708333 | AY9: =IF(D9="","*",IFERROR(IF(ISODD(COUNT(AS9:AX11)),"ERRO",SUM((AT9-AS9),(AV9-AU9),(AX9-AW9))),"ERRO")) -> 0.025694444 | BA9: 0 | BB9: =IFERROR(_xlfn.XLOOKUP(AI9, BS_ATIVIDADE[ATIVIDADE],BS_ATIVIDADE[UNIDADE] ), "*") -> M | BC9: {=_xlfn.XLOOKUP( 1, ( TabelaMap[SUB] = BS_CONTROLE[[#This Row],[SUB]]) * ( TabelaMap[KM Inicio] <= BS_CONTROLE[[#This Row],[KM - Inicio]]) * ( TabelaMap[KM Fim] >= BS_CONTROLE[[#This Row],[KM - Inicio]]), TabelaMap[Gerência], "-", 0 )} -> FERRONORTE | BD9: {=_xlfn.XLOOKUP( 1, ( TabelaMap[SUB] = BS_CONTROLE[[#This Row],[SUB_5]]) * ( TabelaMap[KM Inicio] <= BS_CONTROLE[[#This Row],[KM - Inicio]]) * ( TabelaMap[KM Fim] >= BS_CONTROLE[[#This Row],[KM - Inicio]]), TabelaMap[Trecho Coordenação], "-", 0 )} -> TGR-TRO | BE9: =IFERROR(_xlfn.XLOOKUP(AO9, BASE_MAPA!$B$2:$B$420, BASE_MAPA!$G$2:$G$420), "ERRO") -> ALTO ARAGUAIA - RONDONOPOLIS | BF9: =IF(BS_CONTROLE[[#This Row],[Responsavel pelo boletim]]=0, "-", BS_CONTROLE[[#This Row],[Responsavel pelo boletim]]) -> Antonioni | BH9: 0 | BJ9: MC1 09:29, aguarda oportunidade | BK9: MC1 09:29, autorizado 11:37, realizado somente viagem de medição/Sem oportunidade para socaria | BM9: CCO Circulação | BN9: Intervalo Oportunidade | BO9: Sem oportunidade | BQ9: =IF(AND(BR9<1,BS9<1),"Produção e Intervalo",IF(BR9<1,"Intervalo",IF(BS9<1,"Produção","Aderente"))) -> Produção e Intervalo | BR9: =IF(OR(B9="",F9=""),"*",AY9/P9) -> 0.30833333 | BS9: =IF(OR(B9="",F9=""),"*",BA9/Q9) -> 0 | BT9: =IF(BN9="","",SUBSTITUTE(BM9," ","")&SUBSTITUTE(BN9," ","")) -> CCOCirculaçãoIntervaloOportunidade
A10: =D10&B10 -> W7046055 | B10: 46055 | C10: =IF(BS_CONTROLE[[#This Row],[DATA]]="","",WEEKNUM(BS_CONTROLE[[#This Row],[DATA]])) -> 6 | D10: W70 | E10: 3 | F10: PDM - PEDRA - DESCARGA | G10: =IF(D10="","*",VLOOKUP(F10,BS_ATIVIDADE[#All],3,FALSE)) -> PEDRA | H10: 752RVD | I10: TGR2 | J10: 98 | K10: 700 | L10: 703 | M10: {=_xlfn.XLOOKUP( 1, ( TabelaMap[SUB] = BS_CONTROLE[[#This Row],[SUB]]) * ( TabelaMap[KM Inicio] <= BS_CONTROLE[[#This Row],[KM - Inicio]]) * ( TabelaMap[KM Fim] >= BS_CONTROLE[[#This Row],[KM - Inicio]]), TabelaMap[Trecho], "-", 0 )} -> TAL-TSF | N10: {=_xlfn.XLOOKUP( 1, ( TabelaMap[SUB] = BS_CONTROLE[[#This Row],[SUB]]) * ( TabelaMap[KM Inicio] <= BS_CONTROLE[[#This Row],[KM - Inicio]]) * ( TabelaMap[KM Fim] >= BS_CONTROLE[[#This Row],[KM - Inicio]]), TabelaMap[SB], "-", 0 )} -> 699710 | O10: 0.33333333 | P10: 0.125 | Q10: 28 | R10: =IFERROR(_xlfn.XLOOKUP(F10, BS_ATIVIDADE[ATIVIDADE],BS_ATIVIDADE[UNIDADE] ), "*") -> VAGÕES | S10: {=_xlfn.XLOOKUP( 1, ( TabelaMap[SUB] = BS_CONTROLE[[#This Row],[SUB]]) * ( TabelaMap[KM Inicio] <= BS_CONTROLE[[#This Row],[KM - Inicio]]) * ( TabelaMap[KM Fim] >= BS_CONTROLE[[#This Row],[KM - Inicio]]), TabelaMap[Gerência], "-", 0 )} -> FERRONORTE | T10: {=_xlfn.XLOOKUP( 1, ( TabelaMap[SUB] = BS_CONTROLE[[#This Row],[SUB]]) * ( TabelaMap[KM Inicio] <= BS_CONTROLE[[#This Row],[KM - Inicio]]) * ( TabelaMap[KM Fim] >= BS_CONTROLE[[#This Row],[KM - Inicio]]), TabelaMap[Trecho Coordenação], "-", 0 )} -> TGR-TRO | U10: =IFERROR(_xlfn.XLOOKUP(J10, BASE_MAPA!$B$2:$B$420, BASE_MAPA!$G$2:$G$420), "ERRO") -> ALTO ARAGUAIA - RONDONOPOLIS | V10: Camila | W10: Descarga de brita | X10: Oportunidade | AA10: 2 (Enio e Daniel) | AB10: FIXO | AD10: 0.29166667 | AE10: 7632 | AF10: 9292 | AI10: =IF(BS_CONTROLE[[#This Row],[Atividade]]=0, "-", BS_CONTROLE[[#This Row],[Atividade]]) -> PDM - PEDRA - DESCARGA | AJ10: =IF(D10="","*",VLOOKUP(AI10,BS_ATIVIDADE[#Data],3,FALSE)) -> PEDRA | AK10: =IF(BS_CONTROLE[[#This Row],[Local - Partida]]=0, "-", BS_CONTROLE[[#This Row],[Local - Partida]]) -> 752RVD | AL10: =IF(BS_CONTROLE[[#This Row],[Local - Encerramento]]=0, "-", BS_CONTROLE[[#This Row],[Local - Encerramento]]) -> TGR2 | AM10: =IF(BS_CONTROLE[[#This Row],[Entre - Estações]]=0, "-", BS_CONTROLE[[#This Row],[Entre - Estações]]) -> TAL-TSF | AN10: =IF(BS_CONTROLE[[#This Row],[SB]]=0, "-", BS_CONTROLE[[#This Row],[SB]]) -> 699710 | AO10: =IF(BS_CONTROLE[[#This Row],[SUB]]=0, "-", BS_CONTROLE[[#This Row],[SUB]]) -> 98 | AP10: =IF(BS_CONTROLE[[#This Row],[KM - Inicio]]=0, "-", BS_CONTROLE[[#This Row],[KM - Inicio]]) -> 700 | AQ10: =IF(BS_CONTROLE[[#This Row],[KM - Fim]]=0, "-", BS_CONTROLE[[#This Row],[KM - Fim]]) -> 703 | AR10: 0 | AS10: 0 | AT10: 0 | AY10: =IF(D10="","*",IFERROR(IF(ISODD(COUNT(AS10:AX12)),"ERRO",SUM((AT10-AS10),(AV10-AU10),(AX10-AW10))),"ERRO")) -> 0 | BA10: 0 | BB10: =IFERROR(_xlfn.XLOOKUP(AI10, BS_ATIVIDADE[ATIVIDADE],BS_ATIVIDADE[UNIDADE] ), "*") -> VAGÕES | BC10: {=_xlfn.XLOOKUP( 1, ( TabelaMap[SUB] = BS_CONTROLE[[#This Row],[SUB]]) * ( TabelaMap[KM Inicio] <= BS_CONTROLE[[#This Row],[KM - Inicio]]) * ( TabelaMap[KM Fim] >= BS_CONTROLE[[#This Row],[KM - Inicio]]), TabelaMap[Gerência], "-", 0 )} -> FERRONORTE | BD10: {=_xlfn.XLOOKUP( 1, ( TabelaMap[SUB] = BS_CONTROLE[[#This Row],[SUB_5]]) * ( TabelaMap[KM Inicio] <= BS_CONTROLE[[#This Row],[KM - Inicio]]) * ( TabelaMap[KM Fim] >= BS_CONTROLE[[#This Row],[KM - Inicio]]), TabelaMap[Trecho Coordenação], "-", 0 )} -> TGR-TRO | BE10: =IFERROR(_xlfn.XLOOKUP(AO10, BASE_MAPA!$B$2:$B$420, BASE_MAPA!$G$2:$G$420), "ERRO") -> ALTO ARAGUAIA - RONDONOPOLIS | BF10: =IF(BS_CONTROLE[[#This Row],[Responsavel pelo boletim]]=0, "-", BS_CONTROLE[[#This Row],[Responsavel pelo boletim]]) -> Camila | BH10: 0 | BJ10: Aguarda confirmação do pátio para encerramento | BK10: Locomotiva 7632 não envia mensagem, MC1 14:42 aguarda autorização | BM10: Mecânica | BN10: Locomotiva | BO10: Avaria | BP10: Locomotiva 7632 não envia mensagem | BQ10: =IF(AND(BR10<1,BS10<1),"Produção e Intervalo",IF(BR10<1,"Intervalo",IF(BS10<1,"Produção","Aderente"))) -> Produção e Intervalo | BR10: =IF(OR(B10="",F10=""),"*",AY10/P10) -> 0 | BS10: =IF(OR(B10="",F10=""),"*",BA10/Q10) -> 0 | BT10: =IF(BN10="","",SUBSTITUTE(BM10," ","")&SUBSTITUTE(BN10," ","")) -> MecânicaLocomotiva
A11: =D11&B11 -> FRANCISCO (TF-19)46055 | B11: 46055 | C11: =IF(BS_CONTROLE[[#This Row],[DATA]]="","",WEEKNUM(BS_CONTROLE[[#This Row],[DATA]])) -> 6 | D11: FRANCISCO (TF-19) | E11: 4 | F11: PDM - AMV - MEIA CHAVE | G11: =IF(D11="","*",VLOOKUP(F11,BS_ATIVIDADE[#All],3,FALSE)) -> AMV | H11: TBSNORTE | I11: - | J11: 98 | K11: 662.313 | L11: - | M11: {=_xlfn.XLOOKUP( 1, ( TabelaMap[SUB] = BS_CONTROLE[[#This Row],[SUB]]) * ( TabelaMap[KM Inicio] <= BS_CONTROLE[[#This Row],[KM - Inicio]]) * ( TabelaMap[KM Fim] >= BS_CONTROLE[[#This Row],[KM - Inicio]]), TabelaMap[Trecho], "-", 0 )} -> TBS-TAL | N11: {=_xlfn.XLOOKUP( 1, ( TabelaMap[SUB] = BS_CONTROLE[[#This Row],[SUB]]) * ( TabelaMap[KM Inicio] <= BS_CONTROLE[[#This Row],[KM - Inicio]]) * ( TabelaMap[KM Fim] >= BS_CONTROLE[[#This Row],[KM - Inicio]]), TabelaMap[SB], "-", 0 )} -> TBSPAT1 | O11: 0.375 | P11: 0.125 | Q11: 1 | R11: =IFERROR(_xlfn.XLOOKUP(F11, BS_ATIVIDADE[ATIVIDADE],BS_ATIVIDADE[UNIDADE] ), "*") -> Nº DE PEÇAS | S11: {=_xlfn.XLOOKUP( 1, ( TabelaMap[SUB] = BS_CONTROLE[[#This Row],[SUB]]) * ( TabelaMap[KM Inicio] <= BS_CONTROLE[[#This Row],[KM - Inicio]]) * ( TabelaMap[KM Fim] >= BS_CONTROLE[[#This Row],[KM - Inicio]]), TabelaMap[Gerência], "-", 0 )} -> FERRONORTE | T11: {=_xlfn.XLOOKUP( 1, ( TabelaMap[SUB] = BS_CONTROLE[[#This Row],[SUB]]) * ( TabelaMap[KM Inicio] <= BS_CONTROLE[[#This Row],[KM - Inicio]]) * ( TabelaMap[KM Fim] >= BS_CONTROLE[[#This Row],[KM - Inicio]]), TabelaMap[Trecho Coordenação], "-", 0 )} -> TGR-TRO | U11: =IFERROR(_xlfn.XLOOKUP(J11, BASE_MAPA!$B$2:$B$420, BASE_MAPA!$G$2:$G$420), "ERRO") -> ALTO ARAGUAIA - RONDONOPOLIS | V11: Camila | W11: Troca de meia chave TBS norte | X11: Oportunidade | AA11: - | AI11: =IF(BS_CONTROLE[[#This Row],[Atividade]]=0, "-", BS_CONTROLE[[#This Row],[Atividade]]) -> PDM - AMV - MEIA CHAVE | AJ11: =IF(D11="","*",VLOOKUP(AI11,BS_ATIVIDADE[#Data],3,FALSE)) -> AMV | AK11: =IF(BS_CONTROLE[[#This Row],[Local - Partida]]=0, "-", BS_CONTROLE[[#This Row],[Local - Partida]]) -> TBSNORTE | AL11: =IF(BS_CONTROLE[[#This Row],[Local - Encerramento]]=0, "-", BS_CONTROLE[[#This Row],[Local - Encerramento]]) -> - | AM11: =IF(BS_CONTROLE[[#This Row],[Entre - Estações]]=0, "-", BS_CONTROLE[[#This Row],[Entre - Estações]]) -> TBS-TAL | AN11: =IF(BS_CONTROLE[[#This Row],[SB]]=0, "-", BS_CONTROLE[[#This Row],[SB]]) -> TBSPAT1 | AO11: =IF(BS_CONTROLE[[#This Row],[SUB]]=0, "-", BS_CONTROLE[[#This Row],[SUB]]) -> 98 | AP11: =IF(BS_CONTROLE[[#This Row],[KM - Inicio]]=0, "-", BS_CONTROLE[[#This Row],[KM - Inicio]]) -> 662.313 | AQ11: =IF(BS_CONTROLE[[#This Row],[KM - Fim]]=0, "-", BS_CONTROLE[[#This Row],[KM - Fim]]) -> - | AR11: 0.45277778 | AS11: 0 | AT11: 0 | AY11: =IF(D11="","*",IFERROR(IF(ISODD(COUNT(AS11:AX13)),"ERRO",SUM((AT11-AS11),(AV11-AU11),(AX11-AW11))),"ERRO")) -> 0 | BA11: 0 | BB11: =IFERROR(_xlfn.XLOOKUP(AI11, BS_ATIVIDADE[ATIVIDADE],BS_ATIVIDADE[UNIDADE] ), "*") -> Nº DE PEÇAS | BC11: {=_xlfn.XLOOKUP( 1, ( TabelaMap[SUB] = BS_CONTROLE[[#This Row],[SUB]]) * ( TabelaMap[KM Inicio] <= BS_CONTROLE[[#This Row],[KM - Inicio]]) * ( TabelaMap[KM Fim] >= BS_CONTROLE[[#This Row],[KM - Inicio]]), TabelaMap[Gerência], "-", 0 )} -> FERRONORTE | BD11: {=_xlfn.XLOOKUP( 1, ( TabelaMap[SUB] = BS_CONTROLE[[#This Row],[SUB_5]]) * ( TabelaMap[KM Inicio] <= BS_CONTROLE[[#This Row],[KM - Inicio]]) * ( TabelaMap[KM Fim] >= BS_CONTROLE[[#This Row],[KM - Inicio]]), TabelaMap[Trecho Coordenação], "-", 0 )} -> TGR-TRO | BE11: =IFERROR(_xlfn.XLOOKUP(AO11, BASE_MAPA!$B$2:$B$420, BASE_MAPA!$G$2:$G$420), "ERRO") -> ALTO ARAGUAIA - RONDONOPOLIS | BF11: =IF(BS_CONTROLE[[#This Row],[Responsavel pelo boletim]]=0, "-", BS_CONTROLE[[#This Row],[Responsavel pelo boletim]]) -> Camila | BH11: 0 | BJ11: Equipe pronta as 10h | BK11: Equipe pronta 10:52, sem oportunidade | BM11: CCO Circulação | BN11: Intervalo Oportunidade | BO11: Sem oportunidade | BP11: - | BQ11: =IF(AND(BR11<1,BS11<1),"Produção e Intervalo",IF(BR11<1,"Intervalo",IF(BS11<1,"Produção","Aderente"))) -> Produção e Intervalo | BR11: =IF(OR(B11="",F11=""),"*",AY11/P11) -> 0 | BS11: =IF(OR(B11="",F11=""),"*",BA11/Q11) -> 0 | BT11: =IF(BN11="","",SUBSTITUTE(BM11," ","")&SUBSTITUTE(BN11," ","")) -> CCOCirculaçãoIntervaloOportunidade
A12: =D12&B12 -> BRUNO (TF-525)46055 | B12: 46055 | C12: =IF(BS_CONTROLE[[#This Row],[DATA]]="","",WEEKNUM(BS_CONTROLE[[#This Row],[DATA]])) -> 6 | D12: BRUNO (TF-525) | E12: 5 | F12: PDM - SOLDA | G12: =IF(D12="","*",VLOOKUP(F12,BS_ATIVIDADE[#All],3,FALSE)) -> SOLDA | H12: {=_xlfn.XLOOKUP( 1, ( TabelaMap[SUB] = BS_CONTROLE[[#This Row],[SUB]]) * ( TabelaMap[KM Inicio] <= BS_CONTROLE[[#This Row],[KM - Inicio]]) * ( TabelaMap[KM Fim] >= BS_CONTROLE[[#This Row],[KM - Inicio]]), TabelaMap[SB], "-", 0 )} -> 539TRM | I12: - | J12: 98 | K12: 548.145 | L12: - | M12: {=_xlfn.XLOOKUP( 1, ( TabelaMap[SUB] = BS_CONTROLE[[#This Row],[SUB]]) * ( TabelaMap[KM Inicio] <= BS_CONTROLE[[#This Row],[KM - Inicio]]) * ( TabelaMap[KM Fim] >= BS_CONTROLE[[#This Row],[KM - Inicio]]), TabelaMap[Trecho], "-", 0 )} -> TBE-TRM | N12: {=_xlfn.XLOOKUP( 1, ( TabelaMap[SUB] = BS_CONTROLE[[#This Row],[SUB]]) * ( TabelaMap[KM Inicio] <= BS_CONTROLE[[#This Row],[KM - Inicio]]) * ( TabelaMap[KM Fim] >= BS_CONTROLE[[#This Row],[KM - Inicio]]), TabelaMap[SB], "-", 0 )} -> 539TRM | O12: 0.375 | P12: 0.083333333 | Q12: 2 | R12: =IFERROR(_xlfn.XLOOKUP(F12, BS_ATIVIDADE[ATIVIDADE],BS_ATIVIDADE[UNIDADE] ), "*") -> Nº DE SOLDA | S12: {=_xlfn.XLOOKUP( 1, ( TabelaMap[SUB] = BS_CONTROLE[[#This Row],[SUB]]) * ( TabelaMap[KM Inicio] <= BS_CONTROLE[[#This Row],[KM - Inicio]]) * ( TabelaMap[KM Fim] >= BS_CONTROLE[[#This Row],[KM - Inicio]]), TabelaMap[Gerência], "-", 0 )} -> FERRONORTE | T12: {=_xlfn.XLOOKUP( 1, ( TabelaMap[SUB] = BS_CONTROLE[[#This Row],[SUB]]) * ( TabelaMap[KM Inicio] <= BS_CONTROLE[[#This Row],[KM - Inicio]]) * ( TabelaMap[KM Fim] >= BS_CONTROLE[[#This Row],[KM - Inicio]]), TabelaMap[Trecho Coordenação], "-", 0 )} -> TGR-TRO | U12: =IFERROR(_xlfn.XLOOKUP(J12, BASE_MAPA!$B$2:$B$420, BASE_MAPA!$G$2:$G$420), "ERRO") -> ALTO ARAGUAIA - RONDONOPOLIS | V12: Camila | W12: Execução de solda | X12: Oportunidade | AA12: - | AI12: =IF(BS_CONTROLE[[#This Row],[Atividade]]=0, "-", BS_CONTROLE[[#This Row],[Atividade]]) -> PDM - SOLDA | AJ12: =IF(D12="","*",VLOOKUP(AI12,BS_ATIVIDADE[#Data],3,FALSE)) -> SOLDA | AK12: =IF(BS_CONTROLE[[#This Row],[Local - Partida]]=0, "-", BS_CONTROLE[[#This Row],[Local - Partida]]) -> 539TRM | AL12: =IF(BS_CONTROLE[[#This Row],[Local - Encerramento]]=0, "-", BS_CONTROLE[[#This Row],[Local - Encerramento]]) -> - | AM12: =IF(BS_CONTROLE[[#This Row],[Entre - Estações]]=0, "-", BS_CONTROLE[[#This Row],[Entre - Estações]]) -> TBE-TRM | AN12: =IF(BS_CONTROLE[[#This Row],[SB]]=0, "-", BS_CONTROLE[[#This Row],[SB]]) -> 539TRM | AO12: =IF(BS_CONTROLE[[#This Row],[SUB]]=0, "-", BS_CONTROLE[[#This Row],[SUB]]) -> 98 | AP12: =IF(BS_CONTROLE[[#This Row],[KM - Inicio]]=0, "-", BS_CONTROLE[[#This Row],[KM - Inicio]]) -> 548.145 | AQ12: =IF(BS_CONTROLE[[#This Row],[KM - Fim]]=0, "-", BS_CONTROLE[[#This Row],[KM - Fim]]) -> - | AR12: 0.34027778 | AS12: 0.35902778 | AT12: 0.42152778 | AY12: =IF(D12="","*",IFERROR(IF(ISODD(COUNT(AS12:AX14)),"ERRO",SUM((AT12-AS12),(AV12-AU12),(AX12-AW12))),"ERRO")) -> 0.0625 | BA12: 0 | BB12: =IFERROR(_xlfn.XLOOKUP(AI12, BS_ATIVIDADE[ATIVIDADE],BS_ATIVIDADE[UNIDADE] ), "*") -> Nº DE SOLDA | BC12: {=_xlfn.XLOOKUP( 1, ( TabelaMap[SUB] = BS_CONTROLE[[#This Row],[SUB]]) * ( TabelaMap[KM Inicio] <= BS_CONTROLE[[#This Row],[KM - Inicio]]) * ( TabelaMap[KM Fim] >= BS_CONTROLE[[#This Row],[KM - Inicio]]), TabelaMap[Gerência], "-", 0 )} -> FERRONORTE | BD12: {=_xlfn.XLOOKUP( 1, ( TabelaMap[SUB] = BS_CONTROLE[[#This Row],[SUB_5]]) * ( TabelaMap[KM Inicio] <= BS_CONTROLE[[#This Row],[KM - Inicio]]) * ( TabelaMap[KM Fim] >= BS_CONTROLE[[#This Row],[KM - Inicio]]), TabelaMap[Trecho Coordenação], "-", 0 )} -> TGR-TRO | BE12: =IFERROR(_xlfn.XLOOKUP(AO12, BASE_MAPA!$B$2:$B$420, BASE_MAPA!$G$2:$G$420), "ERRO") -> ALTO ARAGUAIA - RONDONOPOLIS | BF12: =IF(BS_CONTROLE[[#This Row],[Responsavel pelo boletim]]=0, "-", BS_CONTROLE[[#This Row],[Responsavel pelo boletim]]) -> Camila | BH12: 0 | BJ12: Equipe no local, sem condições climáticas para atividade | BK12: Equipe no local, sem condições climáticas para atividade | BM12: Condições Climática | BN12: Chuva | BO12: Chuva | BP12: - | BQ12: =IF(AND(BR12<1,BS12<1),"Produção e Intervalo",IF(BR12<1,"Intervalo",IF(BS12<1,"Produção","Aderente"))) -> Produção e Intervalo | BR12: =IF(OR(B12="",F12=""),"*",AY12/P12) -> 0.75 | BS12: =IF(OR(B12="",F12=""),"*",BA12/Q12) -> 0 | BT12: =IF(BN12="","",SUBSTITUTE(BM12," ","")&SUBSTITUTE(BN12," ","")) -> CondiçõesClimáticaChuva
A13: =D13&B13 -> ELSON (TF-526)46055 | B13: 46055 | C13: =IF(BS_CONTROLE[[#This Row],[DATA]]="","",WEEKNUM(BS_CONTROLE[[#This Row],[DATA]])) -> 6 | D13: ELSON (TF-526) | E13: 6 | F13: PDM - SOLDA | G13: =IF(D13="","*",VLOOKUP(F13,BS_ATIVIDADE[#All],3,FALSE)) -> SOLDA | H13: 499TGR1 | I13: - | J13: 74 | K13: 498.9 | L13: - | M13: {=_xlfn.XLOOKUP( 1, ( TabelaMap[SUB] = BS_CONTROLE[[#This Row],[SUB]]) * ( TabelaMap[KM Inicio] <= BS_CONTROLE[[#This Row],[KM - Inicio]]) * ( TabelaMap[KM Fim] >= BS_CONTROLE[[#This Row],[KM - Inicio]]), TabelaMap[Trecho], "-", 0 )} -> TBR-TGR | N13: {=_xlfn.XLOOKUP( 1, ( TabelaMap[SUB] = BS_CONTROLE[[#This Row],[SUB]]) * ( TabelaMap[KM Inicio] <= BS_CONTROLE[[#This Row],[KM - Inicio]]) * ( TabelaMap[KM Fim] >= BS_CONTROLE[[#This Row],[KM - Inicio]]), TabelaMap[SB], "-", 0 )} -> 499TGR1 | O13: 0.41666667 | P13: 0.125 | Q13: 2 | R13: =IFERROR(_xlfn.XLOOKUP(F13, BS_ATIVIDADE[ATIVIDADE],BS_ATIVIDADE[UNIDADE] ), "*") -> Nº DE SOLDA | S13: {=_xlfn.XLOOKUP( 1, ( TabelaMap[SUB] = BS_CONTROLE[[#This Row],[SUB]]) * ( TabelaMap[KM Inicio] <= BS_CONTROLE[[#This Row],[KM - Inicio]]) * ( TabelaMap[KM Fim] >= BS_CONTROLE[[#This Row],[KM - Inicio]]), TabelaMap[Gerência], "-", 0 )} -> FERRONORTE | T13: {=_xlfn.XLOOKUP( 1, ( TabelaMap[SUB] = BS_CONTROLE[[#This Row],[SUB]]) * ( TabelaMap[KM Inicio] <= BS_CONTROLE[[#This Row],[KM - Inicio]]) * ( TabelaMap[KM Fim] >= BS_CONTROLE[[#This Row],[KM - Inicio]]), TabelaMap[Trecho Coordenação], "-", 0 )} -> TCS-TGR | U13: =IFERROR(_xlfn.XLOOKUP(J13, BASE_MAPA!$B$2:$B$420, BASE_MAPA!$G$2:$G$420), "ERRO") -> MARCO INICIAL - ALTO ARAGUAIA | V13: Elson | W13: Execução de solda | X13: Contrato | AA13: - | AI13: =IF(BS_CONTROLE[[#This Row],[Atividade]]=0, "-", BS_CONTROLE[[#This Row],[Atividade]]) -> PDM - SOLDA | AJ13: =IF(D13="","*",VLOOKUP(AI13,BS_ATIVIDADE[#Data],3,FALSE)) -> SOLDA | AK13: =IF(BS_CONTROLE[[#This Row],[Local - Partida]]=0, "-", BS_CONTROLE[[#This Row],[Local - Partida]]) -> 499TGR1 | AL13: =IF(BS_CONTROLE[[#This Row],[Local - Encerramento]]=0, "-", BS_CONTROLE[[#This Row],[Local - Encerramento]]) -> - | AM13: =IF(BS_CONTROLE[[#This Row],[Entre - Estações]]=0, "-", BS_CONTROLE[[#This Row],[Entre - Estações]]) -> TBR-TGR | AN13: =IF(BS_CONTROLE[[#This Row],[SB]]=0, "-", BS_CONTROLE[[#This Row],[SB]]) -> 499TGR1 | AO13: =IF(BS_CONTROLE[[#This Row],[SUB]]=0, "-", BS_CONTROLE[[#This Row],[SUB]]) -> 74 | AP13: =IF(BS_CONTROLE[[#This Row],[KM - Inicio]]=0, "-", BS_CONTROLE[[#This Row],[KM - Inicio]]) -> 498.9 | AQ13: =IF(BS_CONTROLE[[#This Row],[KM - Fim]]=0, "-", BS_CONTROLE[[#This Row],[KM - Fim]]) -> - | AR13: 0.375 | AS13: 0.48472222 | AT13: 0.60972222 | AY13: =IF(D13="","*",IFERROR(IF(ISODD(COUNT(AS13:AX15)),"ERRO",SUM((AT13-AS13),(AV13-AU13),(AX13-AW13))),"ERRO")) -> 0.125 | BA13: 0 | BB13: =IFERROR(_xlfn.XLOOKUP(AI13, BS_ATIVIDADE[ATIVIDADE],BS_ATIVIDADE[UNIDADE] ), "*") -> Nº DE SOLDA | BC13: {=_xlfn.XLOOKUP( 1, ( TabelaMap[SUB] = BS_CONTROLE[[#This Row],[SUB]]) * ( TabelaMap[KM Inicio] <= BS_CONTROLE[[#This Row],[KM - Inicio]]) * ( TabelaMap[KM Fim] >= BS_CONTROLE[[#This Row],[KM - Inicio]]), TabelaMap[Gerência], "-", 0 )} -> FERRONORTE | BD13: {=_xlfn.XLOOKUP( 1, ( TabelaMap[SUB] = BS_CONTROLE[[#This Row],[SUB_5]]) * ( TabelaMap[KM Inicio] <= BS_CONTROLE[[#This Row],[KM - Inicio]]) * ( TabelaMap[KM Fim] >= BS_CONTROLE[[#This Row],[KM - Inicio]]), TabelaMap[Trecho Coordenação], "-", 0 )} -> TCS-TGR | BE13: =IFERROR(_xlfn.XLOOKUP(AO13, BASE_MAPA!$B$2:$B$420, BASE_MAPA!$G$2:$G$420), "ERRO") -> MARCO INICIAL - ALTO ARAGUAIA | BF13: =IF(BS_CONTROLE[[#This Row],[Responsavel pelo boletim]]=0, "-", BS_CONTROLE[[#This Row],[Responsavel pelo boletim]]) -> Elson | BH13: 0 | BJ13: Equipe pronta as 9h, em intervalo 11:38 | BK13: Em intervalo 11:38, cancelado as 11:59 devido chuva no local | BM13: Condições Climática | BN13: Chuva | BO13: Chuva | BP13: - | BQ13: =IF(AND(BR13<1,BS13<1),"Produção e Intervalo",IF(BR13<1,"Intervalo",IF(BS13<1,"Produção","Aderente"))) -> Produção | BR13: =IF(OR(B13="",F13=""),"*",AY13/P13) -> 1 | BS13: =IF(OR(B13="",F13=""),"*",BA13/Q13) -> 0 | BT13: =IF(BN13="","",SUBSTITUTE(BM13," ","")&SUBSTITUTE(BN13," ","")) -> CondiçõesClimáticaChuva
A14: =D14&B14 -> E4646055 | B14: 46055 | C14: =IF(BS_CONTROLE[[#This Row],[DATA]]="","",WEEKNUM(BS_CONTROLE[[#This Row],[DATA]])) -> 6 | D14: E46 | E14: 7 | F14: DESLOCAMENTO | G14: =IF(D14="","*",VLOOKUP(F14,BS_ATIVIDADE[#All],3,FALSE)) -> OUTROS | H14: TAG | I14: TIN | J14: 74 | K14: 291 | L14: 109.54 | M14: {=_xlfn.XLOOKUP( 1, ( TabelaMap[SUB] = BS_CONTROLE[[#This Row],[SUB]]) * ( TabelaMap[KM Inicio] <= BS_CONTROLE[[#This Row],[KM - Inicio]]) * ( TabelaMap[KM Fim] >= BS_CONTROLE[[#This Row],[KM - Inicio]]), TabelaMap[Trecho], "-", 0 )} -> TCS-TRC | N14: {=_xlfn.XLOOKUP( 1, ( TabelaMap[SUB] = BS_CONTROLE[[#This Row],[SUB]]) * ( TabelaMap[KM Inicio] <= BS_CONTROLE[[#This Row],[KM - Inicio]]) * ( TabelaMap[KM Fim] >= BS_CONTROLE[[#This Row],[KM - Inicio]]), TabelaMap[SB], "-", 0 )} -> 291TRC1 | O14: 0.375 | P14: 0.041666667 | Q14: 1 | R14: =IFERROR(_xlfn.XLOOKUP(F14, BS_ATIVIDADE[ATIVIDADE],BS_ATIVIDADE[UNIDADE] ), "*") -> BINÁRIO | S14: {=_xlfn.XLOOKUP( 1, ( TabelaMap[SUB] = BS_CONTROLE[[#This Row],[SUB]]) * ( TabelaMap[KM Inicio] <= BS_CONTROLE[[#This Row],[KM - Inicio]]) * ( TabelaMap[KM Fim] >= BS_CONTROLE[[#This Row],[KM - Inicio]]), TabelaMap[Gerência], "-", 0 )} -> FERRONORTE | T14: {=_xlfn.XLOOKUP( 1, ( TabelaMap[SUB] = BS_CONTROLE[[#This Row],[SUB]]) * ( TabelaMap[KM Inicio] <= BS_CONTROLE[[#This Row],[KM - Inicio]]) * ( TabelaMap[KM Fim] >= BS_CONTROLE[[#This Row],[KM - Inicio]]), TabelaMap[Trecho Coordenação], "-", 0 )} -> TCS-TGR | U14: =IFERROR(_xlfn.XLOOKUP(J14, BASE_MAPA!$B$2:$B$420, BASE_MAPA!$G$2:$G$420), "ERRO") -> MARCO INICIAL - ALTO ARAGUAIA | V14: PCM | W14: Deslocamento de TAG para abastecer no TOM e seguir para TIN | X14: Oportunidade | AI14: =IF(BS_CONTROLE[[#This Row],[Atividade]]=0, "-", BS_CONTROLE[[#This Row],[Atividade]]) -> DESLOCAMENTO | AJ14: =IF(D14="","*",VLOOKUP(AI14,BS_ATIVIDADE[#Data],3,FALSE)) -> OUTROS | AK14: =IF(BS_CONTROLE[[#This Row],[Local - Partida]]=0, "-", BS_CONTROLE[[#This Row],[Local - Partida]]) -> TAG | AL14: =IF(BS_CONTROLE[[#This Row],[Local - Encerramento]]=0, "-", BS_CONTROLE[[#This Row],[Local - Encerramento]]) -> TIN | AM14: =IF(BS_CONTROLE[[#This Row],[Entre - Estações]]=0, "-", BS_CONTROLE[[#This Row],[Entre - Estações]]) -> TCS-TRC | AN14: =IF(BS_CONTROLE[[#This Row],[SB]]=0, "-", BS_CONTROLE[[#This Row],[SB]]) -> 291TRC1 | AO14: =IF(BS_CONTROLE[[#This Row],[SUB]]=0, "-", BS_CONTROLE[[#This Row],[SUB]]) -> 74 | AP14: =IF(BS_CONTROLE[[#This Row],[KM - Inicio]]=0, "-", BS_CONTROLE[[#This Row],[KM - Inicio]]) -> 291 | AQ14: =IF(BS_CONTROLE[[#This Row],[KM - Fim]]=0, "-", BS_CONTROLE[[#This Row],[KM - Fim]]) -> 109.54 | AR14: 0 | AS14: 0 | AT14: 0 | AY14: =IF(D14="","*",IFERROR(IF(ISODD(COUNT(AS14:AX16)),"ERRO",SUM((AT14-AS14),(AV14-AU14),(AX14-AW14))),"ERRO")) -> 0 | BA14: 0 | BB14: =IFERROR(_xlfn.XLOOKUP(AI14, BS_ATIVIDADE[ATIVIDADE],BS_ATIVIDADE[UNIDADE] ), "*") -> BINÁRIO | BC14: {=_xlfn.XLOOKUP( 1, ( TabelaMap[SUB] = BS_CONTROLE[[#This Row],[SUB]]) * ( TabelaMap[KM Inicio] <= BS_CONTROLE[[#This Row],[KM - Inicio]]) * ( TabelaMap[KM Fim] >= BS_CONTROLE[[#This Row],[KM - Inicio]]), TabelaMap[Gerência], "-", 0 )} -> FERRONORTE | BD14: {=_xlfn.XLOOKUP( 1, ( TabelaMap[SUB] = BS_CONTROLE[[#This Row],[SUB_5]]) * ( TabelaMap[KM Inicio] <= BS_CONTROLE[[#This Row],[KM - Inicio]]) * ( TabelaMap[KM Fim] >= BS_CONTROLE[[#This Row],[KM - Inicio]]), TabelaMap[Trecho Coordenação], "-", 0 )} -> TCS-TGR | BE14: =IFERROR(_xlfn.XLOOKUP(AO14, BASE_MAPA!$B$2:$B$420, BASE_MAPA!$G$2:$G$420), "ERRO") -> MARCO INICIAL - ALTO ARAGUAIA | BF14: =IF(BS_CONTROLE[[#This Row],[Responsavel pelo boletim]]=0, "-", BS_CONTROLE[[#This Row],[Responsavel pelo boletim]]) -> PCM | BH14: 0 | BJ14: Aguarda informação do pátio para acionar equipe, cancelado devido anomália do I71 | BK14: Aguarda informação do pátio para acionar equipe, cancelado devido anomália do I71 | BM14: Anomalia | BN14: Mecânica | BO14: Avaria em trem | BP14: I71 DDV quebrado | BQ14: =IF(AND(BR14<1,BS14<1),"Produção e Intervalo",IF(BR14<1,"Intervalo",IF(BS14<1,"Produção","Aderente"))) -> Produção e Intervalo | BR14: =IF(OR(B14="",F14=""),"*",AY14/P14) -> 0 | BS14: =IF(OR(B14="",F14=""),"*",BA14/Q14) -> 0 | BT14: =IF(BN14="","",SUBSTITUTE(BM14," ","")&SUBSTITUTE(BN14," ","")) -> AnomaliaMecânica
