Workbook
Name Anomalia: SELEÇÕES!$Q$14:$Q$15
Name AnomaliaMecânica: SELEÇÕES!$AD$29
Name AnomaliaVia: SELEÇÕES!$AC$29
Name ATIVOS: BS_ATIVO!$A$2:$A$254
Name CCOCirculação: SELEÇÕES!$K$14:$K$17
Name CCOCirculaçãoIntervaloContrato: SELEÇÕES!$Q$29:$Q$39
Name CCOCirculaçãoIntervaloExtra: SELEÇÕES!$AH$29
Name CCOCirculaçãoIntervaloOportunidade: SELEÇÕES!$S$29:$S$39
Name CCOCirculaçãoProgramação: SELEÇÕES!$R$29
Name CCOEscala: SELEÇÕES!$J$14
Name CCOEscalaEquipagem: SELEÇÕES!$P$29:$P$32
Name CondiçõesClimática: SELEÇÕES!$R$14:$R$16
Name CondiçõesClimáticaChuva: SELEÇÕES!$AF$29
Name CondiçõesClimáticaTemperatura: SELEÇÕES!$AE$29:$AE$31
Name CondiçõesClimáticaVentosFortes: SELEÇÕES!$AG$29:$AG$29
Name Confiabilidade: SELEÇÕES!$S$14:$S$15
Name ConfiabilidadeAtivo: SELEÇÕES!$AJ$29:$AJ$30
Name ConfiabilidadeOperação: SELEÇÕES!$AI$29:$AI$33
Name Expansão: SELEÇÕES!$M$14:$M$15
Name ExpansãoEquipamento: SELEÇÕES!$V$29:$V$30
Name ExpansãoExecução: SELEÇÕES!$W$29:$W$38
Name FaltadeContrato: SELEÇÕES!$U$14
Name FaltadeContratoFaltadeContrato: SELEÇÕES!$AM$29
Name IMPCAUSADOR: SELEÇÕES!$A$13:$V$13
Name Infraestrutura: SELEÇÕES!$O$14:$O$15
Name InfraestruturaEquipamento: SELEÇÕES!$Z$29:$Z$30
Name InfraestruturaExecução: SELEÇÕES!$AA$29:$AA$38
Name Mecânica: SELEÇÕES!$G$14:$G$15
Name MecânicaLocomotiva: SELEÇÕES!$J$29
Name MecânicaVagão: SELEÇÕES!$K$29
Name Mecanização: SELEÇÕES!$H$14:$H$15
Name MecanizaçãoAtivos: SELEÇÕES!$M$29:$M$31
Name MecanizaçãoOperação: SELEÇÕES!$L$29:$L$35
Name Modernização: SELEÇÕES!$N$14:$N$17
Name ModernizaçãoEquipamento: SELEÇÕES!$X$29:$X$30
Name ModernizaçãoExecução: SELEÇÕES!$Y$29:$Y$38
Name NãoControláveis: SELEÇÕES!$B$14:$B$15
Name NãoControláveisAcidente: SELEÇÕES!$E$29
Name NãoControláveisVandalismo: SELEÇÕES!$D$29:$D$33
Name OK: SELEÇÕES!$P$14
Name OKOK: SELEÇÕES!$AB$29
Name Pátio: SELEÇÕES!$D$14
Name PátioOperação: SELEÇÕES!$G$29:$G$30
Name PCMMecânica: SELEÇÕES!$F$14
Name PCMMecânicaLocomotiva: SELEÇÕES!$I$29:$I$30
Name PCMVIA: SELEÇÕES!$I$14:$I$15
Name PCMVIAProgramação: SELEÇÕES!$O$29:$O$31
Name PCMVIARecursosInternos: SELEÇÕES!$N$29:$N$31
Name Qualidade: SELEÇÕES!$T$14:$T$15
Name QualidadeAtivo: SELEÇÕES!$AL$29
Name QualidadeOperação: SELEÇÕES!$AK$29:$AK$30
Name SemOportunidade: SELEÇÕES!$V$14
Name SemOportunidadeSemOportunidade: SELEÇÕES!$AN$29
Name SUBs: SELEÇÕES!$A$44:$A$50
Name Super: SELEÇÕES!$L$14:$L$15
Name SuperEquipamento: SELEÇÕES!$T$29:$T$30
Name SuperExecução: SELEÇÕES!$U$29:$U$38
Name TI: SELEÇÕES!$C$14
Name TISistema: SELEÇÕES!$F$29:$F$30
Name TO: SELEÇÕES!$A$14:$A$16

Sheet BASE_MAPA
A1: Gerência | B1: SUB | C1: KM Inicio | D1: KM Fim | E1: Trecho | F1: SB | G1: NOME SUB | H1: Trecho Coordenação
A2: SP NORTE | B2: 42 | C2: 244.776 | D2: 247.077 | E2: 244-ZTO | F2: 244246 | G2: OURO - TUTOIA (CONTORNO) | H2: ZCZ-ZTI
A3: SP NORTE | B3: 42 | C3: 247.077 | D3: 249.649 | E3: 244-ZTO | F3: 246249 | G3: OURO - TUTOIA (CONTORNO) | H3: ZCZ-ZTI
A4: SP NORTE | B4: 42 | C4: 249.649 | D4: 250.078 | E4: 244-ZTO | F4: 249250 | G4: OURO - TUTOIA (CONTORNO) | H4: ZCZ-ZTI
A5: SP NORTE | B5: 42 | C5: 250.078 | D5: 252.635 | E5: 244-ZTO | F5: 250ZTO1 | G5: OURO - TUTOIA (CONTORNO) | H5: ZCZ-ZTI
A6: SP NORTE | B6: 42 | C6: 250.078 | D6: 252.638 | E6: 244-ZTO | F6: 250ZTO2 | G6: OURO - TUTOIA (CONTORNO) | H6: ZCZ-ZTI
A7: SP NORTE | B7: 42 | C7: 252.635 | D7: 252.833 | E7: ZTO | F7: ZTO1 | G7: OURO - TUTOIA (CONTORNO) | H7: ZCZ-ZTI
A8: SP NORTE | B8: 42 | C8: 252.638 | D8: 252.834 | E8: ZTO | F8: ZTO2 | G8: OURO - TUTOIA (CONTORNO) | H8: ZCZ-ZTI
A9: SP NORTE | B9: 42 | C9: 252.833 | D9: 253 | E9: ZTO-ZFT | F9: ZTOZZR1 | G9: OURO - TUTOIA (CONTORNO) | H9: ZCZ-ZTI
A10: SP NORTE | B10: 42 | C10: 252.834 | D10: 253.106 | E10: ZTO-ZFT | F10: ZTOZZR2 | G10: OURO - TUTOIA (CONTORNO) | H10: ZCZ-ZTI
A11: SP NORTE | B11: 43 | C11: 6.337 | D11: 6.983 | E11: ZTO-ZFT | F11: ZTOZFT1 | G11: TUTOIA - BUENO DE ANDRADE (CONTORNO) | H11: ZCZ-ZTI
A12: SP NORTE | B12: 43 | C12: 6.337 | D12: 6.983 | E12: ZTO-ZFT | F12: ZTOZFT2 | G12: TUTOIA - BUENO DE ANDRADE (CONTORNO) | H12: ZCZ-ZTI
A13: SP NORTE | B13: 43 | C13: 6.983 | D13: 7.189 | E13: ZFT | F13: ZFT1 | G13: TUTOIA - BUENO DE ANDRADE (CONTORNO) | H13: ZCZ-ZTI
A14: SP NORTE | B14: 43 | C14: 6.983 | D14: 7.188 | E14: ZFT | F14: ZFT2 | G14: TUTOIA - BUENO DE ANDRADE (CONTORNO) | H14: ZCZ-ZTI
A15: SP NORTE | B15: 43 | C15: 7.188 | D15: 9.742 | E15: ZFT-KM9 | F15: ZFTKM92 | G15: TUTOIA - BUENO DE ANDRADE (CONTORNO) | H15: ZCZ-ZTI
A16: SP NORTE | B16: 43 | C16: 7.189 | D16: 9.742 | E16: ZFT-KM9 | F16: ZFTKM91 | G16: TUTOIA - BUENO DE ANDRADE (CONTORNO) | H16: ZCZ-ZTI
... A22: SP NORTE | B22: 70 | C22: 137 | D22: 138 | E22: ZRQ-ZQX | F22: ZRQ1381 | G22: RECANTO - ITIRAPINA (L1 PRINCIPAL) | H22: ZRX-ZTI
A23: SP NORTE | B23: 70 | C23: 138 | D23: 139 | E23: ZRQ-ZQX | F23: 1381391 | G23: RECANTO - ITIRAPINA (L1 PRINCIPAL) | H23: ZRX-ZTI
A24: SP NORTE | B24: 70 | C24: 139 | D24: 142.245 | E24: ZRQ-ZQX | F24: 139ZQX1 | G24: RECANTO - ITIRAPINA (L1 PRINCIPAL) | H24: ZRX-ZTI
A25: SP NORTE | B25: 70 | C25: 142.245 | D25: 145.76 | E25: ZQX | F25: ZQX1 | G25: RECANTO - ITIRAPINA (L1 PRINCIPAL) | H25: ZRX-ZTI
A26: SP NORTE | B26: 70 | C26: 145.76 | D26: 148 | E26: ZQX-ZOX | F26: ZQX148 | G26: RECANTO - ITIRAPINA (L1 PRINCIPAL) | H26: ZRX-ZTI
A27: SP NORTE | B27: 70 | C27: 148 | D27: 151 | E27: ZQX-ZOX | F27: 148151 | G27: RECANTO - ITIRAPINA (L1 PRINCIPAL) | H27: ZRX-ZTI
A28: SP NORTE | B28: 70 | C28: 151 | D28: 154 | E28: ZQX-ZOX | F28: 151154 | G28: RECANTO - ITIRAPINA (L1 PRINCIPAL) | H28: ZRX-ZTI
A29: SP NORTE | B29: 70 | C29: 154 | D29: 156.125 | E29: ZQX-ZOX | F29: 154ZOX | G29: RECANTO - ITIRAPINA (L1 PRINCIPAL) | H29: ZRX-ZTI
A30: SP NORTE | B30: 70 | C30: 156.125 | D30: 158 | E30: ZOX | F30: ZOX1 | G30: RECANTO - ITIRAPINA (L1 PRINCIPAL) | H30: ZRX-ZTI
A31: SP NORTE | B31: 70 | C31: 156.125 | D31: 158 | E31: ZOX | F31: ZOX2 | G31: RECANTO - ITIRAPINA (L1 PRINCIPAL) | H31: ZRX-ZTI
A32: SP NORTE | B32: 70 | C32: 158 | D32: 159.303 | E32: ZOX-ZIQ | F32: ZOX1591 | G32: RECANTO - ITIRAPINA (L1 PRINCIPAL) | H32: ZRX-ZTI
A33: SP NORTE | B33: 70 | C33: 158 | D33: 159.303 | E33: ZOX-ZIQ | F33: ZOX1592 | G33: RECANTO - ITIRAPINA (L1 PRINCIPAL) | H33: ZRX-ZTI
A34: SP NORTE | B34: 70 | C34: 159.303 | D34: 162 | E34: ZOX-ZIQ | F34: 159162 | G34: RECANTO - ITIRAPINA (L1 PRINCIPAL) | H34: ZRX-ZTI
A35: SP NORTE | B35: 70 | C35: 162 | D35: 164 | E35: ZOX-ZIQ | F35: 162164 | G35: RECANTO - ITIRAPINA (L1 PRINCIPAL) | H35: ZRX-ZTI
A36: SP NORTE | B36: 70 | C36: 164 | D36: 166.727 | E36: ZOX-ZIQ | F36: 164ZIQ | G36: RECANTO - ITIRAPINA (L1 PRINCIPAL) | H36: ZRX-ZTI
A37: SP NORTE | B37: 70 | C37: 166.727 | D37: 168.44 | E37: ZIQ | F37: ZIQ1 | G37: RECANTO - ITIRAPINA (L1 PRINCIPAL) | H37: ZRX-ZTI
A38: SP NORTE | B38: 70 | C38: 166.727 | D38: 168.44 | E38: ZIQ | F38: ZIQ2 | G38: RECANTO - ITIRAPINA (L1 PRINCIPAL) | H38: ZRX-ZTI
A39: SP NORTE | B39: 71 | C39: 173.1 | D39: 174.887 | E39: ZIQ-ZVI | F39: ZIQ1751 | G39: ITIRAPINA - ARARAQUARA | H39: ZRX-ZTI
A40: SP NORTE | B40: 71 | C40: 173.1 | D40: 174.887 | E40: ZIQ-ZVI | F40: ZIQ1752 | G40: ITIRAPINA - ARARAQUARA | H40: ZRX-ZTI
A41: SP NORTE | B41: 71 | C41: 174.887 | D41: 178 | E41: ZIQ-ZVI | F41: 175178 | G41: ITIRAPINA - ARARAQUARA | H41: ZRX-ZTI
A42: SP NORTE | B42: 71 | C42: 178 | D42: 180.946 | E42: ZIQ-ZVI | F42: 178181 | G42: ITIRAPINA - ARARAQUARA | H42: ZRX-ZTI
A43: SP NORTE | B43: 71 | C43: 180.946 | D43: 182.626 | E43: ZIQ-ZVI | F43: 181ZVI | G43: ITIRAPINA - ARARAQUARA | H43: ZRX-ZTI
A44: SP NORTE | B44: 71 | C44: 182.626 | D44: 184 | E44: ZVI | F44: ZVI1 | G44: ITIRAPINA - ARARAQUARA | H44: ZRX-ZTI
A45: SP NORTE | B45: 71 | C45: 182.626 | D45: 184 | E45: ZVI | F45: ZVI2 | G45: ITIRAPINA - ARARAQUARA | H45: ZRX-ZTI
...

Sheet SELEÇÕES
A1: MAQUINISTAS | C1: ACIONAMENTO | E1: PRÉVIA | G1: DESVIO | I1: PROGRAMADO? | K1: ProgramaPCM | M1: Prioridade
A2: FIXO | C2: SBR | E2: 1 | G2: VIA | I2: SIM | K2: Contrato | M2: P0
A3: ESCALA | C3: AGD ACIONAMENTO PCM | E3: 2 | I3: NÃO | K3: Oportunidade | M3: P1
A4: FIXO + ESCALA | C4: ACIONAMENTO | I4: OPORTUNIDADE | K4: Extra | M4: P2
M5: P3
M6: P4
M7: P5
A13: TO | B13: Não Controláveis | C13: TI | D13: Pátio | E13: Tração | F13: PCM Mecânica | G13: Mecânica | H13: Mecanização | I13: PCM VIA | J13: CCO Escala | K13: CCO Circulação | L13: Super | M13: Expansão | N13: Modernização | O13: Infraestrutura | P13: OK | Q13: Anomalia | R13: Condições Climática | S13: Confiabilidade | T13: Engenharia | U13: Falta de Contrato | V13: Sem Oportunidade
A14: Embarcado | B14: Vandalismo | C14: Sistema | D14: Operação | E14: Operação | F14: Locomotiva | G14: Locomotiva | H14: Operação | I14: Recursos Internos | J14: Equipagem | K14: Intervalo Contrato | L14: Equipamento | M14: Equipamento | N14: Equipamento | O14: Equipamento | P14: OK | Q14: Via | R14: Temperatura | S14: Operação | T14: Operação | U14: Falta de Contrato | V14: Sem Oportunidade
A15: Não Embarcado | B15: Acidente | C15: ="" | G15: Vagão | H15: Ativos | I15: Programação | K15: Intervalo Oportunidade | L15: Execução | M15: Execução | N15: Execução | O15: Execução | Q15: Mecânica | R15: Chuva | S15: Ativo | T15: Ativo
A16: Operação | C16: ="" | K16: Intervalo Extra | R16: Ventos Fortes
K17: Programação
A28: TOEmbarcado | B28: TONãoEmbarcado | C28: TOOperação | D28: NãoControláveisVandalismo | E28: NãoControláveisAcidente | F28: TISistema | G28: PátioOperação | H28: TraçãoOperação | I28: PCMMecânicaLocomotiva | J28: MecânicaLocomotiva | K28: MecânicaVagão | L28: MecanizaçãoOperação | M28: MecanizaçãoAtivos | N28: PCMVIARecursosInternos | O28: PCMVIAProgramação | P28: CCOEscalaEquipagem | Q28: CCOCirculaçãoIntervaloContrato | R28: CCOCirculaçãoProgramação | S28: CCOCirculaçãoIntervaloOportunidade | T28: SuperEquipamento | U28: SuperExecução | V28: ExpansãoEquipamento | W28: ExpansãoExecução | X28: ModernizaçãoEquipamento | Y28: ModernizaçãoExecução | Z28: InfraestruturaEquipamento | AA28: InfraestruturaExecução | AB28: OKOK | AC28: AnomaliaVia | AD28: AnomaliaMecânica | AE28: CondiçõesClimáticaTemperatura | AF28: CondiçõesClimáticaChuva | AG28: CondiçõesClimáticaVentos Fortes | AH28: CCOCirculaçãoIntervaloExtra | AI28: ConfiabilidadeOperação | AJ28: ConfiabilidadeAtivo | AK28: EngenhariaOperação | AL28: EngenhariaAtivo | AM28: Falta de ContratoFalta de Contrato | AN28: SemOportunidadeSemOportunidade
A29: Avaria de CBL | B29: AMV sem indicação | C29: Alteração de programação da turma | D29: Locomotiva | E29: Acidente | F29: Sistema licenciamento indisponível | G29: Manobra indisponível | H29: Maquinista indisponível | I29: Alteração de programação | J29: Avaria | K29: Avaria | L29: Operador indisponível | M29: Avaria em veículo (Mecanização) | N29: Cancelado devido priorização | O29: Falta de OS | P29: Atraso chegada maquinista | Q29: Realizado entre trens | R29: Desvio alocação de locomotiva | S29: Sem oportunidade | T29: Avaria (Escavadeira / caminhão / munck) | U29: Erro de programação | V29: Avaria (Escavadeira / caminhão / munck) | W29: Erro de programação | X29: Avaria (Escavadeira / caminhão / munck / Socadora) | Y29: Erro de programação | Z29: Avaria (Escavadeira / caminhão / munck) | AA29: Erro de programação | AB29: OK | AC29: Defeito na via | AD29: Avaria em trem | AE29: Temperatura Alta | AF29: Chuva | AG29: Ventos Fortes | AH29: Serviço extra contrato | AI29: Falta de Equipe | AJ29: Avaria | AK29: Falta de Equipe | AL29: Avaria | AM29: Falta de Contrato | AN29: Sem Oportunidade
A30: Avaria de CBL | D30: Vagão | F30: Queda / Instabilidade de sistema | G30: Linha ocupada | H30: Atualização malha | I30: Locomotiva indisponível | L30: Operador não habilitado | M30: Avaria em veículo (Detecção) | N30: Alteração de programação | O30: Alteração de programação (Equipamento) | P30: Jornada maquinista excedida | Q30: Concedido intervalo parcial | S30: Realizado entre trens | T30: Avaria (Ferramental) | U30: Alteração de programação | V30: Avaria (Ferramental) | W30: Alteração de programação | X30: Avaria (Ferramental) | Y30: Alteração de programação | Z30: Avaria (Ferramental) | AA30: Alteração de programação | AE30: Temperatura Baixa | AI30: Alteração de Programação | AJ30: Manutenção | AK30: Alteração de Programação
D31: Via de circulação | L31: Desvio de escala | M31: Desvio programação (Manutenção) | N31: Erro de programação | O31: Falta de equipamento / material | P31: Falta Maquinista (Contrato) | Q31: Intervalo negado em D-1 | S31: Concedido intervalo parcial | U31: Quando reduzido da turma | W31: Quando reduzido da turma | Y31: Quando reduzido da turma | AA31: Quando reduzido da turma | AE31: Oscilação de Temperatura | AI31: Falha de programação
D32: Equipamento via | L32: Baixa produtividade | P32: Falta Maquinista (Extra) | Q32: Intervalo Concedido fora do horário programado | S32: Intervalo negado em D-1 | U32: Falta de turma (Não Justificado) | W32: Falta de turma (Não Justificado) | Y32: Falta de turma (Não Justificado) | AA32: Falta de turma (Não Justificado) | AI32: Desvio de escala
D33: Ativo mecanização | L33: Risco de exceder a jornada | Q33: Fluxo intenso de trens | S33: Intervalo Concedido fora do horário programado | U33: Equipe interditada | W33: Equipe interditada | Y33: Equipe interditada | AA33: Equipe interditada | AI33: Risco de exceder a jornada
L34: Abastecimento | Q34: Propagação de TI | S34: Fluxo intenso de trens | U34: Falta de insumo / material | W34: Falta de insumo / material | Y34: Falta de insumo / material | AA34: Falta de insumo / material
L35: Desvio de programação | Q35: Propagação de avaria de trens | S35: Propagação de TI | U35: Desvio escala da turma | W35: Desvio escala da turma | Y35: Desvio escala da turma | AA35: Desvio escala da turma
Q36: Propagação de vandalismo | S36: Propagação de avaria de trens | U36: Intervalo utilizado parcialmente | W36: Intervalo utilizado parcialmente | Y36: Intervalo utilizado parcialmente | AA36: Intervalo utilizado parcialmente
Q37: Propagação por motivo via | S37: Propagação de vandalismo | U37: Baixa produtividade | W37: Baixa produtividade | Y37: Baixa produtividade | AA37: Baixa produtividade
Q38: Erro CCO | S38: Propagação por motivo via | U38: Falha de execução | W38: Falha de execução | Y38: Falha de execução | AA38: Falha de execução
Q39: Intervalo Fracionado | S39: Erro CCO
A44: 42
A45: 43
A46: 70
A47: 71
A48: 73 | C48: /
A49: 170

Sheet BS_ATIVO
A1: BLOCO | D1: ATIVIDADE | E1: UNIDADE | F1: CONTROLE INDICADOR | G1: GRUPO | H1: Item PDM | I1: PESO | J1: Prioridade | K1: CORRELATO
A2: BLOCO | D2: BLOCO | E2: BINÁRIO | F2: OUTROS | G2: BLOCO | H2: - | I2: 0 | J2: 0 | K2: BLOCO
A3: EXPANSÃO TURMA 1 | D3: CAMINHÃO DE SOLDA | E3: Nº DE SOLDA | F3: CAMINHÂO - SOLDA | G3: CAMINHÃO SOLDA | H3: - | I3: 1 | J3: 1 | K3: CAMINHÃO SOLDA
A4: EXPANSÃO TURMA 2 | D4: CONSERVAÇÃO PN | E4: BINÁRIO | F4: CONSERVAÇÂO PN | G4: VIA - TURMA | H4: - | I4: 1 | J4: 1 | K4: VIA - TURMA
A5: INFRA 1 | D5: DESCARGA DE MATERIAL | E5: BINÁRIO | F5: OUTROS | G5: VIA - LASTRO | K5: VIA - LASTRO
A6: INFRA 2 | D6: DESLOCAMENTO | E6: BINÁRIO | F6: OUTROS | G6: TODOS | H6: - | I6: 0 | J6: 4 | K6: TODOS
A7: MOD SPN | D7: DETECÇÃO - CARRO CONTROLE | E7: KM | F7: DETECÇÃO | G7: DETECÇÃO | H7: - | I7: 1 | J7: 1 | K7: DETECÇÃO
A8: MOD ZDG PAT | D8: DETECÇÃO - RONDA 7 DIAS | E8: KM | F8: DETECÇÃO | G8: DETECÇÃO | H8: - | I8: 1 | J8: 1 | K8: DETECÇÃO
A9: MOD ZEM | D9: DETECÇÃO - ULTRASSOM - SPERRY | E9: KM | F9: DETECÇÃO | G9: DETECÇÃO | H9: - | I9: 1 | J9: 1 | K9: DETECÇÃO
A10: MOD ZRB | D10: EXPANSÃO - ALÍVIO DE TENSÃO | E10: M | F10: EXPANSÃO | G10: EXPANSÃO | H10: - | I10: 0 | J10: 0 | K10: EXPANSÃO - TURMA
A11: MOD ZWU ZDC | D11: EXPANSÃO - AMV - JACARÉ | E11: Nº DE PEÇAS | F11: EXPANSÃO | G11: EXPANSÃO | H11: - | I11: 0 | J11: 0 | K11: EXPANSÃO - TURMA
A12: MOD ZYQ ZWI | D12: EXPANSÃO - AMV - MEIA CHAVE | E12: Nº DE PEÇAS | F12: EXPANSÃO | G12: EXPANSÃO | H12: - | I12: 0 | J12: 0 | K12: EXPANSÃO - TURMA
A13: MODERNIZAÇÃO LASTRO 2 | D13: EXPANSÃO - DESCARGA - TRILHO | E13: Nº DE BARRAS | F13: EXPANSÃO | G13: EXPANSÃO | H13: - | I13: 0 | J13: 0 | K13: EXPANSÃO - TRILHEIRO
A14: MODERNIZAÇÃO TURMA 2 | D14: EXPANSÃO - DORMENTE - CARGA | E14: Nº DE DORMENTES | F14: EXPANSÃO | G14: EXPANSÃO | H14: - | I14: 0 | J14: 0 | K14: EXPANSÃO - LASTRO
A15: SOLDA T3 | D15: EXPANSÃO - DORMENTE - DESCARGA | E15: Nº DE DORMENTES | F15: EXPANSÃO | G15: EXPANSÃO | H15: - | I15: 0 | J15: 0 | K15: EXPANSÃO - LASTRO
A16: SUPER | D16: EXPANSÃO - OUTRA ATIVIDADE | E16: BINÁRIO | F16: EXPANSÃO | G16: EXPANSÃO | H16: - | I16: 0 | J16: 0 | K16: EXPANSÃO - TODOS
A17: SUPER SERRA | D17: EXPANSÃO - TRILHEIRO - DESCARGA | E17: M | F17: EXPANSÃO | G17: EXPANSÃO | H17: - | I17: 1 | J17: 1 | K17: EXPANSÃO - TRILHEIRO
... A75: V88 | D75: VANDALISMO - LIMPEZA | E75: M | F75: OUTROS | G75: VIA - TURMA | H75: - | I75: 1 | J75: 1 | K75: VIA - TURMA
A76: V89
A77: V90
A78: V92 | D78: VARRIÇÃO | E78: M | F78: OUTROS | G78: VIA - TURMA | I78: 1 | J78: 1 | K78: VIA - TURMA
A79: V93 | D79: NIVELAMENTO | E79: BINÁRIO | F79: OUTROS | G79: VIA - TURMA | H79: NIVELAMENTO | I79: 1 | J79: 1 | K79: VIA - TURMA
A80: V94 | D80: PREPARAÇÃO DE BARRA | E80: BINÁRIO | F80: OUTROS | G80: VIA - TURMA | H80: TRILHO | I80: 1 | J80: 1 | K80: VIA - TURMA
A81: V95 | D81: INSPEÇÃO | E81: BINÁRIO | F81: OUTROS | G81: VIA - TURMA | H81: VIA | I81: 0 | J81: 0 | K81: VIA - TURMA
A82: V96
A83: V97
A84: W48
A85: W50
A86: W53
A87: W54
A88: W55
A89: W58
A90: W59
A91: W60
A92: W61
A93: W62
... A206: JOSUEL (TP-697)

Sheet SP_NORTE
B1: INICIO | E1: Nenhum dado encontrado para a data de hoje. | AH1: ] | BG1: GESTÃO DE ACOMPANHAMENTO | BK1: 📋 *RELATÓRIO DIÁRIO - 16/2/2026* Aba: SP_NORTE ---------------------------- 🔹 *Ativo:* V87 └ Status 1: MC1 08:21, sem oportunidade └ Status 2: MC1 08:21, sem oportunidade 🔹 *Ativo:* JOSUEL (TP-697) └ Status 1: Equipe pronta 10:23, aguarda passagem L84 10:30, em intervalo 10:47 └ Status 2: - 🔹 *Ativo:* V48 └ Status 1: MC1 08:15, aguarda oportunidade, previsão de faixa 12h └ Status 2: - 🔹 *Ativo:* W54 └ Status 1: Aguarda mecanica loco 9401 não liga └ Status 2: Locomotiva 9401 avariada, previsão D+1 🔹 *Ativo:* PEDRO (TP-696) └ Status 1: Aguarda equipe informar pronto └ Status 2: - 🔹 *Ativo:* CARLOS (TP-722) └ Status 1: Equipe pronta as 10h, em intervalo 11h, em intervalo 10:54 └ Status 2: - 🔹 *Ativo:* V88 └ Status 1: Aguarda MC1, equipe em descanso └ Status 2: Equipe em interjornada 🔹 *Ativo:* MARCEL (TF-03) └ Status 1: Equipe pronta 9:44, aguarda oportunidade └ Status 2: - 🔹 *Ativo:* V40 └ Status 1: MC1 08:09, sem oportunidade └ Status 2: MC1 08:09, sem oportunidade 🔹 *Ativo:* MAURO TP-868) └ Status 1: Equipe no local, aguarda temperatura └ Status 2: - 🔹 *Ativo:* WAGNER (TP-58) └ Status 1: Equipe no local, aguarda temperatura └ Status 2: - 🔹 *Ativo:* ANTONIO (TF-681) └ Status 1: Aguarda equipe informar pronto └ Status 2: - 🔹 *Ativo:* V83 └ Status 1: MC1 08:27, autorizado 09:53, em deslocamento para intervalo └ Status 2: - ✅ *Total de itens encontrados:* 13 | BL1: FECHAMENTO
E2: ITENS GUIA | R2: RESPONSABILIDADE | Z2: RECURSO | AH2: ITENS GUIA | AR2: INTERVALO | AZ2: PRODUÇÃO | BB2: RESPONSABILIDADE
E3: O QUE? | G3: ONDE? | N3: INTERVALO | P3: PODUÇÃO | R3: QUEM VAI RESPONDER PELA EXECUÇÃO? | V3: GESTÃO | Z3: EQUIPAGEM | AD3: ATIVOS | AH3: O QUE? | AJ3: ONDE? | AR3: PARCIAL 1 | AT3: PARCIAL 2 | AV3: PARCIAL 3 | AX3: TOTAL | BB3: QUEM VAI RESPONDER PELA EXECUÇÃO? | BL3: ANALISE | BP3: %
A4: obr | B4: ESCREVE | C4: FORMULA | D4: SELECIONAR | E4: SELECIONAR | F4: FORMULA | G4: ESCREVE | H4: ESCREVE | I4: ESCREVE | J4: ESCREVE | K4: ESCREVE | L4: ESCREVE | M4: ESCREVE | N4: ESCREVE | O4: ESCREVE | P4: ESCREVE | Q4: FORMULA | R4: SELECIONAR | S4: SELECIONAR | T4: FORMULA | U4: ESCREVE | V4: ESCREVE | W4: SELECIONAR | X4: SELECIONAR | Y4: SELECIONAR | Z4: ESCREVE | AA4: SELECIONAR | AB4: SELECIONAR | AC4: ESCREVE | AD4: ESCREVE | AE4: ESCREVE | AF4: ESCREVE | AH4: SELECIONAR | AI4: FORMULA | AJ4: ESCREVE | AK4: ESCREVE | AL4: ESCREVE | AM4: ESCREVE | AN4: ESCREVE | AO4: ESCREVE | AP4: ESCREVE | AQ4: ESCREVE | AR4: ESCREVE | AS4: ESCREVE | AT4: ESCREVE | AU4: ESCREVE | AV4: ESCREVE | AW4: ESCREVE | AX4: FORMULA | AY4: SELECIONAR | AZ4: ESCREVE | BA4: FORMULA | BB4: SELECIONAR | BC4: SELECIONAR | BD4: FORMULA | BE4: ESCREVE | BF4: * | BG4: ESCREVE | BH4: ESCREVE | BI4: ESCREVE | BJ4: ESCREVE | BK4: * | BL4: SELECIONAR | BM4: SELECIONAR | BN4: SELECIONAR | BO4: ESCREVE | BP4: FORMULA | BQ4: FORMULA | BR4: FORMULA
A5: CHAVE | B5: DATA | C5: Semana | D5: ATIVO | E5: Atividade | F5: Atividade - Inidicador | G5: Local - Partida | H5: Local - Encerramento | I5: SUB | J5: KM - Inicio | K5: KM - Fim | L5: Entre - Estações | M5: SB | N5: Inicia | O5: Duração | P5: Quantidade | Q5: Unidade | R5: Gerência da Via | S5: Coordenação da Via | T5: Trecho | U5: Responsavel pelo boletim | V5: Detalhe Programação | W5: Programar para D+1 | X5: Confirmação programação | Y5: Prioridade | Z5: Qtd. Maquinista | AA5: Tipo de Maquinista (Fixo / Escala) | AB5: Tipo de Acionamento | AC5: Apresentação no lastro | AD5: Ativo - 1 | AE5: Ativo - 2 | AF5: Vagões - Qtd. | AG5: *2 | AH5: Atividade_1 | AI5: Atividade - PDM | AJ5: Local - Partida_2 | AK5: Local - Encerramento_3 | AL5: Entre-Locais | AM5: SB_4 | AN5: SUB_5 | AO5: KM - ínicio | AP5: KM - Fim_6 | AQ5: HR Turma Pronta | AR5: Inicio | AS5: Fim | AT5: Inicio_7 | AU5: Fim_8 | AV5: Inicio_9 | AW5: Fim_10 | AX5: TOTAL | AY5: LIBERADO PELO CCO | AZ5: Quantidade_11 | BA5: Unidade_12 | BB5: Gerência da Via_13 | BC5: Coordenação da Via_14 | BD5: Trecho_15 | BE5: Responsavel pelo boletim_16 | BF5: *3 | BG5: Status | BH5: Prévia CCO 22h | BI5: Prévia - 1 | BJ5: Prévia - 2 | BK5: *4 | BL5: Responsabilidade | BM5: Fechamento - Impacto | BN5: Detalhe - Fechamento | BO5: Justificativa | BP5: Analise Prévia | BQ5: Intervalo | BR5: QTD | BS5: Concat
A6: =D6&B6 | C6: =IF(BS_CONTROLE[[#This Row],[DATA]]="","",WEEKNUM(BS_CONTROLE[[#This Row],[DATA]])) | F6: =IF(D6="","*",VLOOKUP(E6,BS_ATIVIDADE[],3,FALSE)) -> * | L6: {=_xlfn.XLOOKUP( 1, ( TabelaMap[SUB] = BS_CONTROLE[[#This Row],[SUB]]) * ( TabelaMap[KM Inicio] <= BS_CONTROLE[[#This Row],[KM - Inicio]]) * ( TabelaMap[KM Fim] >= BS_CONTROLE[[#This Row],[KM - Inicio]]), TabelaMap[Trecho], "-", 0 )} -> - | M6: {=_xlfn.XLOOKUP( 1, ( TabelaMap[SUB] = BS_CONTROLE[[#This Row],[SUB]]) * ( TabelaMap[KM Inicio] <= BS_CONTROLE[[#This Row],[KM - Inicio]]) * ( TabelaMap[KM Fim] >= BS_CONTROLE[[#This Row],[KM - Inicio]]), TabelaMap[SB], "-", 0 )} -> - | Q6: =IF(E6=0, "*", IFERROR(_xlfn.XLOOKUP(E6, BS_ATIVIDADE[ATIVIDADE], BS_ATIVIDADE[UNIDADE]), "*")) -> * | R6: {=_xlfn.XLOOKUP( 1, ( TabelaMap[SUB] = BS_CONTROLE[[#This Row],[SUB]]) * ( TabelaMap[KM Inicio] <= BS_CONTROLE[[#This Row],[KM - Inicio]]) * ( TabelaMap[KM Fim] >= BS_CONTROLE[[#This Row],[KM - Inicio]]), TabelaMap[Gerência], "-", 0 )} -> - | S6: {=_xlfn.XLOOKUP( 1, ( TabelaMap[SUB] = BS_CONTROLE[[#This Row],[SUB]]) * ( TabelaMap[KM Inicio] <= BS_CONTROLE[[#This Row],[KM - Inicio]]) * ( TabelaMap[KM Fim] >= BS_CONTROLE[[#This Row],[KM - Inicio]]), TabelaMap[Trecho Coordenação], "-", 0 )} -> - | T6: {=_xlfn.XLOOKUP( 1, ( TabelaMap[SUB] = BS_CONTROLE[[#This Row],[SUB]]) * ( TabelaMap[KM Inicio] <= BS_CONTROLE[[#This Row],[KM - Inicio]]) * ( TabelaMap[KM Fim] >= BS_CONTROLE[[#This Row],[KM - Inicio]]), TabelaMap[NOME SUB], "-", 0 )} -> - | AH6: =IF(BS_CONTROLE[[#This Row],[Atividade]]=0, "-", BS_CONTROLE[[#This Row],[Atividade]]) -> - | AI6: =IF(BS_CONTROLE[[#This Row],[Atividade]]=0, "-", BS_CONTROLE[[#This Row],[Atividade]]) -> - | AJ6: =BS_CONTROLE[[#This Row],[Local - Partida]] -> 0 | AK6: =BS_CONTROLE[[#This Row],[Local - Encerramento]] -> 0 | AL6: =IF(BS_CONTROLE[[#This Row],[Entre - Estações]]=0, "-", BS_CONTROLE[[#This Row],[Entre - Estações]]) -> - | AM6: =IF(BS_CONTROLE[[#This Row],[SB]]=0, "-", BS_CONTROLE[[#This Row],[SB]]) -> - | AN6: =IF(BS_CONTROLE[[#This Row],[SUB]]=0, "-", BS_CONTROLE[[#This Row],[SUB]]) -> - | AO6: =BS_CONTROLE[[#This Row],[KM - Inicio]] -> 0 | AP6: =BS_CONTROLE[[#This Row],[KM - Inicio]] -> 0 | AX6: =IF(D6="","*",IFERROR(IF(ISODD(COUNT(AR6:AW6)),"ERRO",SUM((AS6-AR6),(AU6-AT6),(AW6-AV6))),"ERRO")) -> * | BA6: =IFERROR(_xlfn.XLOOKUP(AH6, BS_ATIVIDADE[ATIVIDADE],BS_ATIVIDADE[UNIDADE] ), "*") -> * | BB6: {=_xlfn.XLOOKUP( 1, ( TabelaMap[SUB] = BS_CONTROLE[[#This Row],[SUB_5]]) * ( TabelaMap[KM Inicio] <= BS_CONTROLE[[#This Row],[KM - ínicio]]) * ( TabelaMap[KM Fim] >= BS_CONTROLE[[#This Row],[KM - ínicio]]), TabelaMap[Gerência], "-", 0 )} -> - | BC6: {=_xlfn.XLOOKUP( 1, ( TabelaMap[SUB] = BS_CONTROLE[[#This Row],[SUB_5]]) * ( TabelaMap[KM Inicio] <= BS_CONTROLE[[#This Row],[KM - ínicio]]) * ( TabelaMap[KM Fim] >= BS_CONTROLE[[#This Row],[KM - ínicio]]), TabelaMap[Trecho Coordenação], "-", 0 )} -> - | BD6: {=_xlfn.XLOOKUP( 1, ( TabelaMap[SUB] = BS_CONTROLE[[#This Row],[SUB_5]]) * ( TabelaMap[KM Inicio] <= BS_CONTROLE[[#This Row],[KM - Inicio]]) * ( TabelaMap[KM Fim] >= BS_CONTROLE[[#This Row],[KM - Inicio]]), TabelaMap[NOME SUB], "-", 0 )} -> - | BP6: =IF(AND(BQ6<1,BR6<1),"Produção e Intervalo",IF(BQ6<1,"Intervalo",IF(BR6<1,"Produção","Aderente"))) -> Aderente | BQ6: =IF(OR(B6="",E6=""),"*",AX6/O6) -> * | BR6: =IF(OR(B6="",E6=""),"*",AZ6/P6) -> * | BS6: =IF(BM6="","",SUBSTITUTE(BL6," ","")&SUBSTITUTE(BM6," ",""))
A7: =D7&B7 | C7: =IF(BS_CONTROLE[[#This Row],[DATA]]="","",WEEKNUM(BS_CONTROLE[[#This Row],[DATA]])) | F7: =IF(D7="","*",VLOOKUP(E7,BS_ATIVIDADE[],3,FALSE)) -> * | L7: {=_xlfn.XLOOKUP( 1, ( TabelaMap[SUB] = BS_CONTROLE[[#This Row],[SUB]]) * ( TabelaMap[KM Inicio] <= BS_CONTROLE[[#This Row],[KM - Inicio]]) * ( TabelaMap[KM Fim] >= BS_CONTROLE[[#This Row],[KM - Inicio]]), TabelaMap[Trecho], "-", 0 )} -> - | M7: {=_xlfn.XLOOKUP( 1, ( TabelaMap[SUB] = BS_CONTROLE[[#This Row],[SUB]]) * ( TabelaMap[KM Inicio] <= BS_CONTROLE[[#This Row],[KM - Inicio]]) * ( TabelaMap[KM Fim] >= BS_CONTROLE[[#This Row],[KM - Inicio]]), TabelaMap[SB], "-", 0 )} -> - | Q7: =IF(E7=0, "*", IFERROR(_xlfn.XLOOKUP(E7, BS_ATIVIDADE[ATIVIDADE], BS_ATIVIDADE[UNIDADE]), "*")) -> * | R7: {=_xlfn.XLOOKUP( 1, ( TabelaMap[SUB] = BS_CONTROLE[[#This Row],[SUB]]) * ( TabelaMap[KM Inicio] <= BS_CONTROLE[[#This Row],[KM - Inicio]]) * ( TabelaMap[KM Fim] >= BS_CONTROLE[[#This Row],[KM - Inicio]]), TabelaMap[Gerência], "-", 0 )} -> - | S7: {=_xlfn.XLOOKUP( 1, ( TabelaMap[SUB] = BS_CONTROLE[[#This Row],[SUB]]) * ( TabelaMap[KM Inicio] <= BS_CONTROLE[[#This Row],[KM - Inicio]]) * ( TabelaMap[KM Fim] >= BS_CONTROLE[[#This Row],[KM - Inicio]]), TabelaMap[Trecho Coordenação], "-", 0 )} -> - | T7: {=_xlfn.XLOOKUP( 1, ( TabelaMap[SUB] = BS_CONTROLE[[#This Row],[SUB]]) * ( TabelaMap[KM Inicio] <= BS_CONTROLE[[#This Row],[KM - Inicio]]) * ( TabelaMap[KM Fim] >= BS_CONTROLE[[#This Row],[KM - Inicio]]), TabelaMap[NOME SUB], "-", 0 )} -> - | AH7: =IF(BS_CONTROLE[[#This Row],[Atividade]]=0, "-", BS_CONTROLE[[#This Row],[Atividade]]) -> - | AI7: =IF(BS_CONTROLE[[#This Row],[Atividade]]=0, "-", BS_CONTROLE[[#This Row],[Atividade]]) -> - | AJ7: =BS_CONTROLE[[#This Row],[Local - Partida]] -> 0 | AK7: =BS_CONTROLE[[#This Row],[Local - Encerramento]] -> 0 | AL7: =IF(BS_CONTROLE[[#This Row],[Entre - Estações]]=0, "-", BS_CONTROLE[[#This Row],[Entre - Estações]]) -> - | AM7: =IF(BS_CONTROLE[[#This Row],[SB]]=0, "-", BS_CONTROLE[[#This Row],[SB]]) -> - | AN7: =IF(BS_CONTROLE[[#This Row],[SUB]]=0, "-", BS_CONTROLE[[#This Row],[SUB]]) -> - | AO7: =BS_CONTROLE[[#This Row],[KM - Inicio]] -> 0 | AP7: =BS_CONTROLE[[#This Row],[KM - Inicio]] -> 0 | AX7: =IF(D7="","*",IFERROR(IF(ISODD(COUNT(AR7:AW7)),"ERRO",SUM((AS7-AR7),(AU7-AT7),(AW7-AV7))),"ERRO")) -> * | BA7: =IFERROR(_xlfn.XLOOKUP(AH7, BS_ATIVIDADE[ATIVIDADE],BS_ATIVIDADE[UNIDADE] ), "*") -> * | BB7: {=_xlfn.XLOOKUP( 1, ( TabelaMap[SUB] = BS_CONTROLE[[#This Row],[SUB_5]]) * ( TabelaMap[KM Inicio] <= BS_CONTROLE[[#This Row],[KM - ínicio]]) * ( TabelaMap[KM Fim] >= BS_CONTROLE[[#This Row],[KM - ínicio]]), TabelaMap[Gerência], "-", 0 )} -> - | BC7: {=_xlfn.XLOOKUP( 1, ( TabelaMap[SUB] = BS_CONTROLE[[#This Row],[SUB_5]]) * ( TabelaMap[KM Inicio] <= BS_CONTROLE[[#This Row],[KM - ínicio]]) * ( TabelaMap[KM Fim] >= BS_CONTROLE[[#This Row],[KM - ínicio]]), TabelaMap[Trecho Coordenação], "-", 0 )} -> - | BD7: {=_xlfn.XLOOKUP( 1, ( TabelaMap[SUB] = BS_CONTROLE[[#This Row],[SUB_5]]) * ( TabelaMap[KM Inicio] <= BS_CONTROLE[[#This Row],[KM - Inicio]]) * ( TabelaMap[KM Fim] >= BS_CONTROLE[[#This Row],[KM - Inicio]]), TabelaMap[NOME SUB], "-", 0 )} -> - | BP7: =IF(AND(BQ7<1,BR7<1),"Produção e Intervalo",IF(BQ7<1,"Intervalo",IF(BR7<1,"Produção","Aderente"))) -> Aderente | BQ7: =IF(OR(B7="",E7=""),"*",AX7/O7) -> * | BR7: =IF(OR(B7="",E7=""),"*",AZ7/P7) -> * | BS7: =IF(BM7="","",SUBSTITUTE(BL7," ","")&SUBSTITUTE(BM7," ",""))
A8: =D8&B8 -> V8746054 | B8: 46054 | C8: =IF(BS_CONTROLE[[#This Row],[DATA]]="","",WEEKNUM(BS_CONTROLE[[#This Row],[DATA]])) -> 6 | D8: V87 | E8: MECANIZAÇÃO - SOCADORA | F8: =IF(D8="","*",VLOOKUP(E8,BS_ATIVIDADE[],3,FALSE)) -> MECANIZAÇÃO - SOCADORA | G8: ZDP2 | H8: ZDP2 | I8: 73 | J8: 293.3 | K8: 291 | L8: {=_xlfn.XLOOKUP( 1, ( TabelaMap[SUB] = BS_CONTROLE[[#This Row],[SUB]]) * ( TabelaMap[KM Inicio] <= BS_CONTROLE[[#This Row],[KM - Inicio]]) * ( TabelaMap[KM Fim] >= BS_CONTROLE[[#This Row],[KM - Inicio]]), TabelaMap[Trecho], "-", 0 )} -> ZZM-ZCF | M8: {=_xlfn.XLOOKUP( 1, ( TabelaMap[SUB] = BS_CONTROLE[[#This Row],[SUB]]) * ( TabelaMap[KM Inicio] <= BS_CONTROLE[[#This Row],[KM - Inicio]]) * ( TabelaMap[KM Fim] >= BS_CONTROLE[[#This Row],[KM - Inicio]]), TabelaMap[Trecho], "-", 0 )} -> ZZM-ZCF | N8: 0.35416667 | O8: 0.083333333 | P8: 400 | Q8: =IF(E8=0, "*", IFERROR(_xlfn.XLOOKUP(E8, BS_ATIVIDADE[ATIVIDADE], BS_ATIVIDADE[UNIDADE]), "*")) -> M | R8: {=_xlfn.XLOOKUP( 1, ( TabelaMap[SUB] = BS_CONTROLE[[#This Row],[SUB]]) * ( TabelaMap[KM Inicio] <= BS_CONTROLE[[#This Row],[KM - Inicio]]) * ( TabelaMap[KM Fim] >= BS_CONTROLE[[#This Row],[KM - Inicio]]), TabelaMap[Gerência], "-", 0 )} -> SP NORTE | S8: {=_xlfn.XLOOKUP( 1, ( TabelaMap[SUB] = BS_CONTROLE[[#This Row],[SUB]]) * ( TabelaMap[KM Inicio] <= BS_CONTROLE[[#This Row],[KM - Inicio]]) * ( TabelaMap[KM Fim] >= BS_CONTROLE[[#This Row],[KM - Inicio]]), TabelaMap[Trecho Coordenação], "-", 0 )} -> TMI-ZEB | T8: {=_xlfn.XLOOKUP( 1, ( TabelaMap[SUB] = BS_CONTROLE[[#This Row],[SUB]]) * ( TabelaMap[KM Inicio] <= BS_CONTROLE[[#This Row],[KM - Inicio]]) * ( TabelaMap[KM Fim] >= BS_CONTROLE[[#This Row],[KM - Inicio]]), TabelaMap[NOME SUB], "-", 0 )} -> ARARAQUARA - MARCO INICIAL | U8: Antonioni | V8: Socadora Mecanizada | W8: Oportunidade | AH8: =IF(BS_CONTROLE[[#This Row],[Atividade]]=0, "-", BS_CONTROLE[[#This Row],[Atividade]]) -> MECANIZAÇÃO - SOCADORA | AI8: =IF(BS_CONTROLE[[#This Row],[Atividade]]=0, "-", BS_CONTROLE[[#This Row],[Atividade]]) -> MECANIZAÇÃO - SOCADORA | AJ8: =BS_CONTROLE[[#This Row],[Local - Partida]] -> ZDP2 | AK8: =BS_CONTROLE[[#This Row],[Local - Encerramento]] -> ZDP2 | AL8: =IF(BS_CONTROLE[[#This Row],[Entre - Estações]]=0, "-", BS_CONTROLE[[#This Row],[Entre - Estações]]) -> ZZM-ZCF | AM8: =IF(BS_CONTROLE[[#This Row],[SB]]=0, "-", BS_CONTROLE[[#This Row],[SB]]) -> ZZM-ZCF | AN8: =IF(BS_CONTROLE[[#This Row],[SUB]]=0, "-", BS_CONTROLE[[#This Row],[SUB]]) -> 73 | AO8: =BS_CONTROLE[[#This Row],[KM - Inicio]] -> 293.3 | AP8: =BS_CONTROLE[[#This Row],[KM - Inicio]] -> 293.3 | AQ8: 0.34236111 | AR8: 0.55138889 | AS8: 0.63472222 | AX8: =IF(D8="","*",IFERROR(IF(ISODD(COUNT(AR8:AW8)),"ERRO",SUM((AS8-AR8),(AU8-AT8),(AW8-AV8))),"ERRO")) -> 0.083333333 | AZ8: 400 | BA8: =IFERROR(_xlfn.XLOOKUP(AH8, BS_ATIVIDADE[ATIVIDADE],BS_ATIVIDADE[UNIDADE] ), "*") -> M | BB8: {=_xlfn.XLOOKUP( 1, ( TabelaMap[SUB] = BS_CONTROLE[[#This Row],[SUB_5]]) * ( TabelaMap[KM Inicio] <= BS_CONTROLE[[#This Row],[KM - ínicio]]) * ( TabelaMap[KM Fim] >= BS_CONTROLE[[#This Row],[KM - ínicio]]), TabelaMap[Gerência], "-", 0 )} -> SP NORTE | BC8: {=_xlfn.XLOOKUP( 1, ( TabelaMap[SUB] = BS_CONTROLE[[#This Row],[SUB_5]]) * ( TabelaMap[KM Inicio] <= BS_CONTROLE[[#This Row],[KM - ínicio]]) * ( TabelaMap[KM Fim] >= BS_CONTROLE[[#This Row],[KM - ínicio]]), TabelaMap[Trecho Coordenação], "-", 0 )} -> TMI-ZEB | BD8: {=_xlfn.XLOOKUP( 1, ( TabelaMap[SUB] = BS_CONTROLE[[#This Row],[SUB_5]]) * ( TabelaMap[KM Inicio] <= BS_CONTROLE[[#This Row],[KM - Inicio]]) * ( TabelaMap[KM Fim] >= BS_CONTROLE[[#This Row],[KM - Inicio]]), TabelaMap[NOME SUB], "-", 0 )} -> ARARAQUARA - MARCO INICIAL | BG8: 2 | BI8: MC1 07:57, licenciado 11:42, intervalo 13;14 até 15:02 | BJ8: MC1 07:57, licenciado 11:42, intervalo 13;14 até 15:02 | BL8: OK | BM8: OK | BN8: OK | BO8: - | BP8: =IF(AND(BQ8<1,BR8<1),"Produção e Intervalo",IF(BQ8<1,"Intervalo",IF(BR8<1,"Produção","Aderente"))) -> Intervalo | BQ8: =IF(OR(B8="",E8=""),"*",AX8/O8) -> 1 | BR8: =IF(OR(B8="",E8=""),"*",AZ8/P8) -> 1 | BS8: =IF(BM8="","",SUBSTITUTE(BL8," ","")&SUBSTITUTE(BM8," ","")) -> OKOK | BU8: TEXTO ABAIXO
A9: =D9&B9 -> V8846054 | B9: 46054 | C9: =IF(BS_CONTROLE[[#This Row],[DATA]]="","",WEEKNUM(BS_CONTROLE[[#This Row],[DATA]])) -> 6 | D9: V88 | E9: MECANIZAÇÃO - SOCADORA | F9: =IF(D9="","*",VLOOKUP(E9,BS_ATIVIDADE[],3,FALSE)) -> MECANIZAÇÃO - SOCADORA | G9: ZPN2 | H9: ZPN2 | I9: 73 | J9: 156.9 | K9: 152 | L9: {=_xlfn.XLOOKUP( 1, ( TabelaMap[SUB] = BS_CONTROLE[[#This Row],[SUB]]) * ( TabelaMap[KM Inicio] <= BS_CONTROLE[[#This Row],[KM - Inicio]]) * ( TabelaMap[KM Fim] >= BS_CONTROLE[[#This Row],[KM - Inicio]]), TabelaMap[Trecho], "-", 0 )} -> ZCV-ZCT | M9: {=_xlfn.XLOOKUP( 1, ( TabelaMap[SUB] = BS_CONTROLE[[#This Row],[SUB]]) * ( TabelaMap[KM Inicio] <= BS_CONTROLE[[#This Row],[KM - Inicio]]) * ( TabelaMap[KM Fim] >= BS_CONTROLE[[#This Row],[KM - Inicio]]), TabelaMap[Trecho], "-", 0 )} -> ZCV-ZCT | N9: 0.35416667 | O9: 0.083333333 | P9: 1000 | Q9: =IF(E9=0, "*", IFERROR(_xlfn.XLOOKUP(E9, BS_ATIVIDADE[ATIVIDADE], BS_ATIVIDADE[UNIDADE]), "*")) -> M | R9: {=_xlfn.XLOOKUP( 1, ( TabelaMap[SUB] = BS_CONTROLE[[#This Row],[SUB]]) * ( TabelaMap[KM Inicio] <= BS_CONTROLE[[#This Row],[KM - Inicio]]) * ( TabelaMap[KM Fim] >= BS_CONTROLE[[#This Row],[KM - Inicio]]), TabelaMap[Gerência], "-", 0 )} -> SP NORTE | S9: {=_xlfn.XLOOKUP( 1, ( TabelaMap[SUB] = BS_CONTROLE[[#This Row],[SUB]]) * ( TabelaMap[KM Inicio] <= BS_CONTROLE[[#This Row],[KM - Inicio]]) * ( TabelaMap[KM Fim] >= BS_CONTROLE[[#This Row],[KM - Inicio]]), TabelaMap[Trecho Coordenação], "-", 0 )} -> ZEB-ZCZ | T9: {=_xlfn.XLOOKUP( 1, ( TabelaMap[SUB] = BS_CONTROLE[[#This Row],[SUB]]) * ( TabelaMap[KM Inicio] <= BS_CONTROLE[[#This Row],[KM - Inicio]]) * ( TabelaMap[KM Fim] >= BS_CONTROLE[[#This Row],[KM - Inicio]]), TabelaMap[NOME SUB], "-", 0 )} -> ARARAQUARA - MARCO INICIAL | U9: Antonioni | V9: Socadora Mecanizada | W9: Oportunidade | Z9: 1 | AA9: FIXO | AB9: ACIONAMENTO | AC9: 0.3125 | AD9: 6234 | AE9: 6238 | AF9: - | AH9: =IF(BS_CONTROLE[[#This Row],[Atividade]]=0, "-", BS_CONTROLE[[#This Row],[Atividade]]) -> MECANIZAÇÃO - SOCADORA | AI9: =IF(BS_CONTROLE[[#This Row],[Atividade]]=0, "-", BS_CONTROLE[[#This Row],[Atividade]]) -> MECANIZAÇÃO - SOCADORA | AJ9: =BS_CONTROLE[[#This Row],[Local - Partida]] -> ZPN2 | AK9: =BS_CONTROLE[[#This Row],[Local - Encerramento]] -> ZPN2 | AL9: =IF(BS_CONTROLE[[#This Row],[Entre - Estações]]=0, "-", BS_CONTROLE[[#This Row],[Entre - Estações]]) -> ZCV-ZCT | AM9: =IF(BS_CONTROLE[[#This Row],[SB]]=0, "-", BS_CONTROLE[[#This Row],[SB]]) -> ZCV-ZCT | AN9: =IF(BS_CONTROLE[[#This Row],[SUB]]=0, "-", BS_CONTROLE[[#This Row],[SUB]]) -> 73 | AO9: =BS_CONTROLE[[#This Row],[KM - Inicio]] -> 156.9 | AP9: =BS_CONTROLE[[#This Row],[KM - Inicio]] -> 156.9 | AQ9: 0.33125 | AR9: 0 | AS9: 0 | AX9: =IF(D9="","*",IFERROR(IF(ISODD(COUNT(AR9:AW9)),"ERRO",SUM((AS9-AR9),(AU9-AT9),(AW9-AV9))),"ERRO")) -> 0 | AZ9: 0 | BA9: =IFERROR(_xlfn.XLOOKUP(AH9, BS_ATIVIDADE[ATIVIDADE],BS_ATIVIDADE[UNIDADE] ), "*") -> M | BB9: {=_xlfn.XLOOKUP( 1, ( TabelaMap[SUB] = BS_CONTROLE[[#This Row],[SUB_5]]) * ( TabelaMap[KM Inicio] <= BS_CONTROLE[[#This Row],[KM - ínicio]]) * ( TabelaMap[KM Fim] >= BS_CONTROLE[[#This Row],[KM - ínicio]]), TabelaMap[Gerência], "-", 0 )} -> SP NORTE | BC9: {=_xlfn.XLOOKUP( 1, ( TabelaMap[SUB] = BS_CONTROLE[[#This Row],[SUB_5]]) * ( TabelaMap[KM Inicio] <= BS_CONTROLE[[#This Row],[KM - ínicio]]) * ( TabelaMap[KM Fim] >= BS_CONTROLE[[#This Row],[KM - ínicio]]), TabelaMap[Trecho Coordenação], "-", 0 )} -> ZEB-ZCZ | BD9: {=_xlfn.XLOOKUP( 1, ( TabelaMap[SUB] = BS_CONTROLE[[#This Row],[SUB_5]]) * ( TabelaMap[KM Inicio] <= BS_CONTROLE[[#This Row],[KM - Inicio]]) * ( TabelaMap[KM Fim] >= BS_CONTROLE[[#This Row],[KM - Inicio]]), TabelaMap[NOME SUB], "-", 0 )} -> ARARAQUARA - MARCO INICIAL | BG9: 0 | BI9: MC1 07:57, sem oportunidade de faixa | BJ9: MC1 07:57, sem oportunidade de faixa | BL9: CCO Circulação | BM9: Intervalo Oportunidade | BN9: Sem oportunidade | BO9: MC1 07:57, sem oportunidade faixa | BP9: =IF(AND(BQ9<1,BR9<1),"Produção e Intervalo",IF(BQ9<1,"Intervalo",IF(BR9<1,"Produção","Aderente"))) -> Produção e Intervalo | BQ9: =IF(OR(B9="",E9=""),"*",AX9/O9) -> 0 | BR9: =IF(OR(B9="",E9=""),"*",AZ9/P9) -> 0 | BS9: =IF(BM9="","",SUBSTITUTE(BL9," ","")&SUBSTITUTE(BM9," ","")) -> CCOCirculaçãoIntervaloOportunidade | BU9: *RELATÓRIO DIÁRIO - SP_NORTE - 16/2/2026* ---------------------------- 🔴 *Ativo:* V87 ├ KM: 326.1 └ Status: MC1 08:21, autorizado 11:37 em deslocamento para intervalo, em intervalo 13:21, realizou somente viagem de medição 🟢 *Ativo:* JOSUEL (TP-697) ├ KM: 312.8 └ Status: Equipe pronta 10:23, aguarda passagem L84 10:30, em intervalo 10:47, sem produção devido temperatura 🟢 *Ativo:* V48 ├ KM: 300 └ Status: MC1 08:15, aguarda oportunidade, previsão de faixa 12h, autorizado 11:12 em deslocamento 🔴 *Ativo:* W54 ├ KM: 204 └ Status: Locomotiva 9401 avariada, previsão D+1 🔴 *Ativo:* PEDRO (TP-696) ├ KM: 187 └ Status: Não solicitou intervalo 🟢 *Ativo:* CARLOS (TP-722) ├ KM: 157.6 └ Status: Equipe pronta as 10h, em intervalo 11h, em intervalo 10:54, realizou 1 solda 🔴 *Ativo:* V88 ├ KM: 153.8 └ Status: Equipe em interjornada 🔴 *Ativo:* MARCEL (TF-03) ├ KM: 102.4 └ Status: Equipe pronta 9:44, sem oportunidade 🔴 *Ativo:* V40 ├ KM: 54.8 └ Status: MC1 08:09, sem oportunidade 🔴 *Ativo:* MAURO TP-868) ├ KM: 46.7 └ Status: Equipe no local, aguarda temperatura 🔴 *Ativo:* WAGNER (TP-58) ├ KM: 41.9 └ Status: Equipe no local, aguarda temperatura 🔴 *Ativo:* ANTONIO (TF-681) ├ KM: 11.2 └ Status: Equipe pronta 10:30, aguarda sem oportunidade 🟢 *Ativo:* V83 ├ KM: 139.2 └ Status: MC1 08:27, autorizado 09:53, em deslocamento para intervalo, em intervalo 11:56, 500m de socaria ✅ *Total de itens encontrados:* 13
A10: =D10&B10 -> V8346054 | B10: 46054 | C10: =IF(BS_CONTROLE[[#This Row],[DATA]]="","",WEEKNUM(BS_CONTROLE[[#This Row],[DATA]])) -> 6 | D10: V83 | E10: MECANIZAÇÃO - SOCADORA | F10: =IF(D10="","*",VLOOKUP(E10,BS_ATIVIDADE[],3,FALSE)) -> MECANIZAÇÃO - SOCADORA | G10: ZIQ2 | H10: ZIQ2 | I10: 70 | J10: 131.9 | K10: 131.2 | L10: {=_xlfn.XLOOKUP( 1, ( TabelaMap[SUB] = BS_CONTROLE[[#This Row],[SUB]]) * ( TabelaMap[KM Inicio] <= BS_CONTROLE[[#This Row],[KM - Inicio]]) * ( TabelaMap[KM Fim] >= BS_CONTROLE[[#This Row],[KM - Inicio]]), TabelaMap[Trecho], "-", 0 )} -> ZRX-ZRQ | M10: {=_xlfn.XLOOKUP( 1, ( TabelaMap[SUB] = BS_CONTROLE[[#This Row],[SUB]]) * ( TabelaMap[KM Inicio] <= BS_CONTROLE[[#This Row],[KM - Inicio]]) * ( TabelaMap[KM Fim] >= BS_CONTROLE[[#This Row],[KM - Inicio]]), TabelaMap[Trecho], "-", 0 )} -> ZRX-ZRQ | N10: 0.35416667 | O10: 0.041666667 | P10: 1 | Q10: =IF(E10=0, "*", IFERROR(_xlfn.XLOOKUP(E10, BS_ATIVIDADE[ATIVIDADE], BS_ATIVIDADE[UNIDADE]), "*")) -> M | R10: SP NORTE | S10: ZEB-ZCZ | T10: {=_xlfn.XLOOKUP( 1, ( TabelaMap[SUB] = BS_CONTROLE[[#This Row],[SUB]]) * ( TabelaMap[KM Inicio] <= BS_CONTROLE[[#This Row],[KM - Inicio]]) * ( TabelaMap[KM Fim] >= BS_CONTROLE[[#This Row],[KM - Inicio]]), TabelaMap[NOME SUB], "-", 0 )} -> RECANTO - ITIRAPINA (L1 PRINCIPAL) | U10: Antonioni | V10: Deslocamento | W10: Oportunidade | AH10: =IF(BS_CONTROLE[[#This Row],[Atividade]]=0, "-", BS_CONTROLE[[#This Row],[Atividade]]) -> MECANIZAÇÃO - SOCADORA | AI10: =IF(BS_CONTROLE[[#This Row],[Atividade]]=0, "-", BS_CONTROLE[[#This Row],[Atividade]]) -> MECANIZAÇÃO - SOCADORA | AJ10: =BS_CONTROLE[[#This Row],[Local - Partida]] -> ZIQ2 | AK10: =BS_CONTROLE[[#This Row],[Local - Encerramento]] -> ZIQ2 | AL10: =IF(BS_CONTROLE[[#This Row],[Entre - Estações]]=0, "-", BS_CONTROLE[[#This Row],[Entre - Estações]]) -> ZRX-ZRQ | AM10: =IF(BS_CONTROLE[[#This Row],[SB]]=0, "-", BS_CONTROLE[[#This Row],[SB]]) -> ZRX-ZRQ | AN10: =IF(BS_CONTROLE[[#This Row],[SUB]]=0, "-", BS_CONTROLE[[#This Row],[SUB]]) -> 70 | AO10: =BS_CONTROLE[[#This Row],[KM - Inicio]] -> 131.9 | AP10: =BS_CONTROLE[[#This Row],[KM - Inicio]] -> 131.9 | AQ10: 0.39375 | AR10: 0 | AS10: 0 | AX10: =IF(D10="","*",IFERROR(IF(ISODD(COUNT(AR10:AW10)),"ERRO",SUM((AS10-AR10),(AU10-AT10),(AW10-AV10))),"ERRO")) -> 0 | AZ10: 0 | BA10: =IFERROR(_xlfn.XLOOKUP(AH10, BS_ATIVIDADE[ATIVIDADE],BS_ATIVIDADE[UNIDADE] ), "*") -> M | BB10: {=_xlfn.XLOOKUP( 1, ( TabelaMap[SUB] = BS_CONTROLE[[#This Row],[SUB_5]]) * ( TabelaMap[KM Inicio] <= BS_CONTROLE[[#This Row],[KM - ínicio]]) * ( TabelaMap[KM Fim] >= BS_CONTROLE[[#This Row],[KM - ínicio]]), TabelaMap[Gerência], "-", 0 )} -> SP NORTE | BC10: {=_xlfn.XLOOKUP( 1, ( TabelaMap[SUB] = BS_CONTROLE[[#This Row],[SUB_5]]) * ( TabelaMap[KM Inicio] <= BS_CONTROLE[[#This Row],[KM - ínicio]]) * ( TabelaMap[KM Fim] >= BS_CONTROLE[[#This Row],[KM - ínicio]]), TabelaMap[Trecho Coordenação], "-", 0 )} -> ZRX-ZTI | BD10: {=_xlfn.XLOOKUP( 1, ( TabelaMap[SUB] = BS_CONTROLE[[#This Row],[SUB_5]]) * ( TabelaMap[KM Inicio] <= BS_CONTROLE[[#This Row],[KM - Inicio]]) * ( TabelaMap[KM Fim] >= BS_CONTROLE[[#This Row],[KM - Inicio]]), TabelaMap[NOME SUB], "-", 0 )} -> RECANTO - ITIRAPINA (L1 PRINCIPAL) | BG10: 0 | BI10: MC1 09:27, sem oportunidade de faixa | BJ10: MC1 07:57, sem oportunidade de faixa | BL10: CCO Circulação | BM10: Intervalo Oportunidade | BN10: Sem oportunidade | BO10: MC1 07:57, sem oportunidade de faixa | BP10: =IF(AND(BQ10<1,BR10<1),"Produção e Intervalo",IF(BQ10<1,"Intervalo",IF(BR10<1,"Produção","Aderente"))) -> Produção e Intervalo | BQ10: =IF(OR(B10="",E10=""),"*",AX10/O10) -> 0 | BR10: =IF(OR(B10="",E10=""),"*",AZ10/P10) -> 0 | BS10: =IF(BM10="","",SUBSTITUTE(BL10," ","")&SUBSTITUTE(BM10," ","")) -> CCOCirculaçãoIntervaloOportunidade
A11: =D11&B11 | C11: =IF(BS_CONTROLE[[#This Row],[DATA]]="","",WEEKNUM(BS_CONTROLE[[#This Row],[DATA]])) | F11: =IF(D11="","*",VLOOKUP(E11,BS_ATIVIDADE[],3,FALSE)) -> * | K11: {=_xlfn.XLOOKUP( 1, ( TabelaMap[SUB] = BS_CONTROLE[[#This Row],[SUB]]) * ( TabelaMap[KM Inicio] <= BS_CONTROLE[[#This Row],[KM - Inicio]]) * ( TabelaMap[KM Fim] >= BS_CONTROLE[[#This Row],[KM - Inicio]]), TabelaMap[Trecho], "-", 0 )} -> - | L11: {=_xlfn.XLOOKUP( 1, ( TabelaMap[SUB] = BS_CONTROLE[[#This Row],[SUB]]) * ( TabelaMap[KM Inicio] <= BS_CONTROLE[[#This Row],[KM - Inicio]]) * ( TabelaMap[KM Fim] >= BS_CONTROLE[[#This Row],[KM - Inicio]]), TabelaMap[Trecho], "-", 0 )} -> - | M11: {=_xlfn.XLOOKUP( 1, ( TabelaMap[SUB] = BS_CONTROLE[[#This Row],[SUB]]) * ( TabelaMap[KM Inicio] <= BS_CONTROLE[[#This Row],[KM - Inicio]]) * ( TabelaMap[KM Fim] >= BS_CONTROLE[[#This Row],[KM - Inicio]]), TabelaMap[SB], "-", 0 )} -> - | Q11: =IF(E11=0, "*", IFERROR(_xlfn.XLOOKUP(E11, BS_ATIVIDADE[ATIVIDADE], BS_ATIVIDADE[UNIDADE]), "*")) -> * | R11: {=_xlfn.XLOOKUP( 1, ( TabelaMap[SUB] = BS_CONTROLE[[#This Row],[SUB]]) * ( TabelaMap[KM Inicio] <= BS_CONTROLE[[#This Row],[KM - Inicio]]) * ( TabelaMap[KM Fim] >= BS_CONTROLE[[#This Row],[KM - Inicio]]), TabelaMap[Gerência], "-", 0 )} -> - | S11: {=_xlfn.XLOOKUP( 1, ( TabelaMap[SUB] = BS_CONTROLE[[#This Row],[SUB]]) * ( TabelaMap[KM Inicio] <= BS_CONTROLE[[#This Row],[KM - Inicio]]) * ( TabelaMap[KM Fim] >= BS_CONTROLE[[#This Row],[KM - Inicio]]), TabelaMap[Trecho Coordenação], "-", 0 )} -> - | T11: {=_xlfn.XLOOKUP( 1, ( TabelaMap[SUB] = BS_CONTROLE[[#This Row],[SUB]]) * ( TabelaMap[KM Inicio] <= BS_CONTROLE[[#This Row],[KM - Inicio]]) * ( TabelaMap[KM Fim] >= BS_CONTROLE[[#This Row],[KM - Inicio]]), TabelaMap[NOME SUB], "-", 0 )} -> - | AH11: =IF(BS_CONTROLE[[#This Row],[Atividade]]=0, "-", BS_CONTROLE[[#This Row],[Atividade]]) -> - | AI11: =IF(BS_CONTROLE[[#This Row],[Atividade]]=0, "-", BS_CONTROLE[[#This Row],[Atividade]]) -> - | AJ11: =BS_CONTROLE[[#This Row],[Local - Partida]] -> 0 | AK11: =BS_CONTROLE[[#This Row],[Local - Encerramento]] -> 0 | AL11: =IF(BS_CONTROLE[[#This Row],[Entre - Estações]]=0, "-", BS_CONTROLE[[#This Row],[Entre - Estações]]) -> - | AM11: =IF(BS_CONTROLE[[#This Row],[SB]]=0, "-", BS_CONTROLE[[#This Row],[SB]]) -> - | AN11: =IF(BS_CONTROLE[[#This Row],[SUB]]=0, "-", BS_CONTROLE[[#This Row],[SUB]]) -> - | AO11: =BS_CONTROLE[[#This Row],[KM - Inicio]] -> 0 | AP11: =BS_CONTROLE[[#This Row],[KM - Inicio]] -> 0 | AX11: =IF(D11="","*",IFERROR(IF(ISODD(COUNT(AR11:AW11)),"ERRO",SUM((AS11-AR11),(AU11-AT11),(AW11-AV11))),"ERRO")) -> * | BA11: =IFERROR(_xlfn.XLOOKUP(AH11, BS_ATIVIDADE[ATIVIDADE],BS_ATIVIDADE[UNIDADE] ), "*") -> * | BB11: {=_xlfn.XLOOKUP( 1, ( TabelaMap[SUB] = BS_CONTROLE[[#This Row],[SUB_5]]) * ( TabelaMap[KM Inicio] <= BS_CONTROLE[[#This Row],[KM - ínicio]]) * ( TabelaMap[KM Fim] >= BS_CONTROLE[[#This Row],[KM - ínicio]]), TabelaMap[Gerência], "-", 0 )} -> - | BC11: {=_xlfn.XLOOKUP( 1, ( TabelaMap[SUB] = BS_CONTROLE[[#This Row],[SUB_5]]) * ( TabelaMap[KM Inicio] <= BS_CONTROLE[[#This Row],[KM - ínicio]]) * ( TabelaMap[KM Fim] >= BS_CONTROLE[[#This Row],[KM - ínicio]]), TabelaMap[Trecho Coordenação], "-", 0 )} -> - | BD11: {=_xlfn.XLOOKUP( 1, ( TabelaMap[SUB] = BS_CONTROLE[[#This Row],[SUB_5]]) * ( TabelaMap[KM Inicio] <= BS_CONTROLE[[#This Row],[KM - Inicio]]) * ( TabelaMap[KM Fim] >= BS_CONTROLE[[#This Row],[KM - Inicio]]), TabelaMap[NOME SUB], "-", 0 )} -> - | BE11: =BS_CONTROLE[[#This Row],[Responsavel pelo boletim]] -> 0 | BP11: =IF(AND(BQ11<1,BR11<1),"Produção e Intervalo",IF(BQ11<1,"Intervalo",IF(BR11<1,"Produção","Aderente"))) -> Aderente | BQ11: =IF(OR(B11="",E11=""),"*",AX11/O11) -> * | BR11: =IF(OR(B11="",E11=""),"*",AZ11/P11) -> *
A12: =D12&B12 | C12: =IF(BS_CONTROLE[[#This Row],[DATA]]="","",WEEKNUM(BS_CONTROLE[[#This Row],[DATA]])) | F12: =IF(D12="","*",VLOOKUP(E12,BS_ATIVIDADE[],3,FALSE)) -> * | K12: {=_xlfn.XLOOKUP( 1, ( TabelaMap[SUB] = BS_CONTROLE[[#This Row],[SUB]]) * ( TabelaMap[KM Inicio] <= BS_CONTROLE[[#This Row],[KM - Inicio]]) * ( TabelaMap[KM Fim] >= BS_CONTROLE[[#This Row],[KM - Inicio]]), TabelaMap[Trecho], "-", 0 )} -> - | L12: {=_xlfn.XLOOKUP( 1, ( TabelaMap[SUB] = BS_CONTROLE[[#This Row],[SUB]]) * ( TabelaMap[KM Inicio] <= BS_CONTROLE[[#This Row],[KM - Inicio]]) * ( TabelaMap[KM Fim] >= BS_CONTROLE[[#This Row],[KM - Inicio]]), TabelaMap[Trecho], "-", 0 )} -> - | M12: {=_xlfn.XLOOKUP( 1, ( TabelaMap[SUB] = BS_CONTROLE[[#This Row],[SUB]]) * ( TabelaMap[KM Inicio] <= BS_CONTROLE[[#This Row],[KM - Inicio]]) * ( TabelaMap[KM Fim] >= BS_CONTROLE[[#This Row],[KM - Inicio]]), TabelaMap[SB], "-", 0 )} -> - | Q12: =IF(E12=0, "*", IFERROR(_xlfn.XLOOKUP(E12, BS_ATIVIDADE[ATIVIDADE], BS_ATIVIDADE[UNIDADE]), "*")) -> * | R12: {=_xlfn.XLOOKUP( 1, ( TabelaMap[SUB] = BS_CONTROLE[[#This Row],[SUB]]) * ( TabelaMap[KM Inicio] <= BS_CONTROLE[[#This Row],[KM - Inicio]]) * ( TabelaMap[KM Fim] >= BS_CONTROLE[[#This Row],[KM - Inicio]]), TabelaMap[Gerência], "-", 0 )} -> - | S12: {=_xlfn.XLOOKUP( 1, ( TabelaMap[SUB] = BS_CONTROLE[[#This Row],[SUB]]) * ( TabelaMap[KM Inicio] <= BS_CONTROLE[[#This Row],[KM - Inicio]]) * ( TabelaMap[KM Fim] >= BS_CONTROLE[[#This Row],[KM - Inicio]]), TabelaMap[Trecho Coordenação], "-", 0 )} -> - | T12: {=_xlfn.XLOOKUP( 1, ( TabelaMap[SUB] = BS_CONTROLE[[#This Row],[SUB]]) * ( TabelaMap[KM Inicio] <= BS_CONTROLE[[#This Row],[KM - Inicio]]) * ( TabelaMap[KM Fim] >= BS_CONTROLE[[#This Row],[KM - Inicio]]), TabelaMap[NOME SUB], "-", 0 )} -> - | AH12: =IF(BS_CONTROLE[[#This Row],[Atividade]]=0, "-", BS_CONTROLE[[#This Row],[Atividade]]) -> - | AI12: =IF(BS_CONTROLE[[#This Row],[Atividade]]=0, "-", BS_CONTROLE[[#This Row],[Atividade]]) -> - | AJ12: =BS_CONTROLE[[#This Row],[Local - Partida]] -> 0 | AK12: =BS_CONTROLE[[#This Row],[Local - Encerramento]] -> 0 | AL12: =IF(BS_CONTROLE[[#This Row],[Entre - Estações]]=0, "-", BS_CONTROLE[[#This Row],[Entre - Estações]]) -> - | AM12: =IF(BS_CONTROLE[[#This Row],[SB]]=0, "-", BS_CONTROLE[[#This Row],[SB]]) -> - | AN12: =IF(BS_CONTROLE[[#This Row],[SUB]]=0, "-", BS_CONTROLE[[#This Row],[SUB]]) -> - | AO12: =BS_CONTROLE[[#This Row],[KM - Inicio]] -> 0 | AP12: =BS_CONTROLE[[#This Row],[KM - Inicio]] -> 0 | AX12: =IF(D12="","*",IFERROR(IF(ISODD(COUNT(AR12:AW12)),"ERRO",SUM((AS12-AR12),(AU12-AT12),(AW12-AV12))),"ERRO")) -> * | BA12: =IFERROR(_xlfn.XLOOKUP(AH12, BS_ATIVIDADE[ATIVIDADE],BS_ATIVIDADE[UNIDADE] ), "*") -> * | BB12: {=_xlfn.XLOOKUP( 1, ( TabelaMap[SUB] = BS_CONTROLE[[#This Row],[SUB_5]]) * ( TabelaMap[KM Inicio] <= BS_CONTROLE[[#This Row],[KM - ínicio]]) * ( TabelaMap[KM Fim] >= BS_CONTROLE[[#This Row],[KM - ínicio]]), TabelaMap[Gerência], "-", 0 )} -> - | BC12: {=_xlfn.XLOOKUP( 1, ( TabelaMap[SUB] = BS_CONTROLE[[#This Row],[SUB_5]]) * ( TabelaMap[KM Inicio] <= BS_CONTROLE[[#This Row],[KM - ínicio]]) * ( TabelaMap[KM Fim] >= BS_CONTROLE[[#This Row],[KM - ínicio]]), TabelaMap[Trecho Coordenação], "-", 0 )} -> - | BD12: {=_xlfn.XLOOKUP( 1, ( TabelaMap[SUB] = BS_CONTROLE[[#This Row],[SUB_5]]) * ( TabelaMap[KM Inicio] <= BS_CONTROLE[[#This Row],[KM - Inicio]]) * ( TabelaMap[KM Fim] >= BS_CONTROLE[[#This Row],[KM - Inicio]]), TabelaMap[NOME SUB], "-", 0 )} -> - | BE12: =BS_CONTROLE[[#This Row],[Responsavel pelo boletim]] -> 0 | BP12: =IF(AND(BQ12<1,BR12<1),"Produção e Intervalo",IF(BQ12<1,"Intervalo",IF(BR12<1,"Produção","Aderente"))) -> Aderente | BQ12: =IF(OR(B12="",E12=""),"*",AX12/O12) -> * | BR12: =IF(OR(B12="",E12=""),"*",AZ12/P12) -> *
A13: =D13&B13 -> W5746055 | B13: 46055 | C13: =IF(BS_CONTROLE[[#This Row],[DATA]]="","",WEEKNUM(BS_CONTROLE[[#This Row],[DATA]])) -> 6 | D13: W57 | E13: RECOLHIMENTO DE DORMENTE | F13: =IF(D13="","*",VLOOKUP(E13,BS_ATIVIDADE[],3,FALSE)) -> OUTROS | G13: ZJA2 | H13: ZJA2 | I13: 73 | J13: 379 | K13: 375 | L13: {=_xlfn.XLOOKUP( 1, ( TabelaMap[SUB] = BS_CONTROLE[[#This Row],[SUB]]) * ( TabelaMap[KM Inicio] <= BS_CONTROLE[[#This Row],[KM - Inicio]]) * ( TabelaMap[KM Fim] >= BS_CONTROLE[[#This Row],[KM - Inicio]]), TabelaMap[Trecho], "-", 0 )} -> ZJA-ZUR | M13: {=_xlfn.XLOOKUP( 1, ( TabelaMap[SUB] = BS_CONTROLE[[#This Row],[SUB]]) * ( TabelaMap[KM Inicio] <= BS_CONTROLE[[#This Row],[KM - Inicio]]) * ( TabelaMap[KM Fim] >= BS_CONTROLE[[#This Row],[KM - Inicio]]), TabelaMap[Trecho], "-", 0 )} -> ZJA-ZUR | N13: 0.375 | O13: 0.083333333 | P13: 700 | Q13: =IF(E13=0, "*", IFERROR(_xlfn.XLOOKUP(E13, BS_ATIVIDADE[ATIVIDADE], BS_ATIVIDADE[UNIDADE]), "*")) -> Nº DE PEÇAS | R13: {=_xlfn.XLOOKUP( 1, ( TabelaMap[SUB] = BS_CONTROLE[[#This Row],[SUB]]) * ( TabelaMap[KM Inicio] <= BS_CONTROLE[[#This Row],[KM - Inicio]]) * ( TabelaMap[KM Fim] >= BS_CONTROLE[[#This Row],[KM - Inicio]]), TabelaMap[Gerência], "-", 0 )} -> SP NORTE | S13: {=_xlfn.XLOOKUP( 1, ( TabelaMap[SUB] = BS_CONTROLE[[#This Row],[SUB]]) * ( TabelaMap[KM Inicio] <= BS_CONTROLE[[#This Row],[KM - Inicio]]) * ( TabelaMap[KM Fim] >= BS_CONTROLE[[#This Row],[KM - Inicio]]), TabelaMap[Trecho Coordenação], "-", 0 )} -> TMI-ZEB | T13: {=_xlfn.XLOOKUP( 1, ( TabelaMap[SUB] = BS_CONTROLE[[#This Row],[SUB]]) * ( TabelaMap[KM Inicio] <= BS_CONTROLE[[#This Row],[KM - Inicio]]) * ( TabelaMap[KM Fim] >= BS_CONTROLE[[#This Row],[KM - Inicio]]), TabelaMap[NOME SUB], "-", 0 )} -> ARARAQUARA - MARCO INICIAL | U13: Ronaldo | V13: Recolhimento de dormentes inservÍveis | W13: Oportunidade | Z13: Clayton + Larocca | AA13: FIXO | AB13: ACIONAMENTO | AC13: 0.33333333 | AD13: 9374 | AE13: - | AF13: - | AH13: =IF(BS_CONTROLE[[#This Row],[Atividade]]=0, "-", BS_CONTROLE[[#This Row],[Atividade]]) -> RECOLHIMENTO DE DORMENTE | AI13: =IF(BS_CONTROLE[[#This Row],[Atividade]]=0, "-", BS_CONTROLE[[#This Row],[Atividade]]) -> RECOLHIMENTO DE DORMENTE | AJ13: =BS_CONTROLE[[#This Row],[Local - Partida]] -> ZJA2 | AK13: =BS_CONTROLE[[#This Row],[Local - Encerramento]] -> ZJA2 | AL13: =IF(BS_CONTROLE[[#This Row],[Entre - Estações]]=0, "-", BS_CONTROLE[[#This Row],[Entre - Estações]]) -> ZJA-ZUR | AM13: =IF(BS_CONTROLE[[#This Row],[SB]]=0, "-", BS_CONTROLE[[#This Row],[SB]]) -> ZJA-ZUR | AN13: =IF(BS_CONTROLE[[#This Row],[SUB]]=0, "-", BS_CONTROLE[[#This Row],[SUB]]) -> 73 | AO13: =BS_CONTROLE[[#This Row],[KM - Inicio]] -> 379 | AP13: =BS_CONTROLE[[#This Row],[KM - Inicio]] -> 379 | AQ13: 0 | AR13: 0 | AS13: 0 | AX13: =IF(D13="","*",IFERROR(IF(ISODD(COUNT(AR13:AW13)),"ERRO",SUM((AS13-AR13),(AU13-AT13),(AW13-AV13))),"ERRO")) -> 0 | AZ13: 0 | BA13: =IFERROR(_xlfn.XLOOKUP(AH13, BS_ATIVIDADE[ATIVIDADE],BS_ATIVIDADE[UNIDADE] ), "*") -> Nº DE PEÇAS | BB13: {=_xlfn.XLOOKUP( 1, ( TabelaMap[SUB] = BS_CONTROLE[[#This Row],[SUB_5]]) * ( TabelaMap[KM Inicio] <= BS_CONTROLE[[#This Row],[KM - ínicio]]) * ( TabelaMap[KM Fim] >= BS_CONTROLE[[#This Row],[KM - ínicio]]), TabelaMap[Gerência], "-", 0 )} -> SP NORTE | BC13: {=_xlfn.XLOOKUP( 1, ( TabelaMap[SUB] = BS_CONTROLE[[#This Row],[SUB_5]]) * ( TabelaMap[KM Inicio] <= BS_CONTROLE[[#This Row],[KM - ínicio]]) * ( TabelaMap[KM Fim] >= BS_CONTROLE[[#This Row],[KM - ínicio]]), TabelaMap[Trecho Coordenação], "-", 0 )} -> TMI-ZEB | BD13: {=_xlfn.XLOOKUP( 1, ( TabelaMap[SUB] = BS_CONTROLE[[#This Row],[SUB_5]]) * ( TabelaMap[KM Inicio] <= BS_CONTROLE[[#This Row],[KM - Inicio]]) * ( TabelaMap[KM Fim] >= BS_CONTROLE[[#This Row],[KM - Inicio]]), TabelaMap[NOME SUB], "-", 0 )} -> ARARAQUARA - MARCO INICIAL | BG13: 0 | BI13: Sem oportunidade de faixa | BJ13: Sem oportunidade de faixa | BL13: CCO Circulação | BM13: Intervalo Oportunidade | BN13: Sem oportunidade | BO13: Sem oportunidade de faixa | BP13: =IF(AND(BQ13<1,BR13<1),"Produção e Intervalo",IF(BQ13<1,"Intervalo",IF(BR13<1,"Produção","Aderente"))) -> Produção e Intervalo | BQ13: =IF(OR(B13="",E13=""),"*",AX13/O13) -> 0 | BR13: =IF(OR(B13="",E13=""),"*",AZ13/P13) -> 0 | BS13: =IF(BM13="","",SUBSTITUTE(BL13," ","")&SUBSTITUTE(BM13," ","")) -> CCOCirculaçãoIntervaloOportunidade
A14: =D14&B14 -> JOSUÉ (TP-697)46055 | B14: 46055 | C14: =IF(BS_CONTROLE[[#This Row],[DATA]]="","",WEEKNUM(BS_CONTROLE[[#This Row],[DATA]])) -> 6 | D14: JOSUÉ (TP-697) | E14: PDM - SOLDA | F14: =IF(D14="","*",VLOOKUP(E14,BS_ATIVIDADE[],3,FALSE)) -> SOLDA | G14: - | H14: - | I14: 73 | J14: 336.5 | K14: - | L14: {=_xlfn.XLOOKUP( 1, ( TabelaMap[SUB] = BS_CONTROLE[[#This Row],[SUB]]) * ( TabelaMap[KM Inicio] <= BS_CONTROLE[[#This Row],[KM - Inicio]]) * ( TabelaMap[KM Fim] >= BS_CONTROLE[[#This Row],[KM - Inicio]]), TabelaMap[Trecho], "-", 0 )} -> ZGI-ZFN | M14: {=_xlfn.XLOOKUP( 1, ( TabelaMap[SUB] = BS_CONTROLE[[#This Row],[SUB]]) * ( TabelaMap[KM Inicio] <= BS_CONTROLE[[#This Row],[KM - Inicio]]) * ( TabelaMap[KM Fim] >= BS_CONTROLE[[#This Row],[KM - Inicio]]), TabelaMap[Trecho], "-", 0 )} -> ZGI-ZFN | N14: 0.375 | O14: 0.0625 | P14: 1 | Q14: =IF(E14=0, "*", IFERROR(_xlfn.XLOOKUP(E14, BS_ATIVIDADE[ATIVIDADE], BS_ATIVIDADE[UNIDADE]), "*")) -> Nº DE SOLDA | R14: {=_xlfn.XLOOKUP( 1, ( TabelaMap[SUB] = BS_CONTROLE[[#This Row],[SUB]]) * ( TabelaMap[KM Inicio] <= BS_CONTROLE[[#This Row],[KM - Inicio]]) * ( TabelaMap[KM Fim] >= BS_CONTROLE[[#This Row],[KM - Inicio]]), TabelaMap[Gerência], "-", 0 )} -> SP NORTE | S14: {=_xlfn.XLOOKUP( 1, ( TabelaMap[SUB] = BS_CONTROLE[[#This Row],[SUB]]) * ( TabelaMap[KM Inicio] <= BS_CONTROLE[[#This Row],[KM - Inicio]]) * ( TabelaMap[KM Fim] >= BS_CONTROLE[[#This Row],[KM - Inicio]]), TabelaMap[Trecho Coordenação], "-", 0 )} -> TMI-ZEB | T14: {=_xlfn.XLOOKUP( 1, ( TabelaMap[SUB] = BS_CONTROLE[[#This Row],[SUB]]) * ( TabelaMap[KM Inicio] <= BS_CONTROLE[[#This Row],[KM - Inicio]]) * ( TabelaMap[KM Fim] >= BS_CONTROLE[[#This Row],[KM - Inicio]]), TabelaMap[NOME SUB], "-", 0 )} -> ARARAQUARA - MARCO INICIAL | U14: ronaldo | V14: execução de solda - Condicionado à temperatura | W14: Oportunidade | AH14: =IF(BS_CONTROLE[[#This Row],[Atividade]]=0, "-", BS_CONTROLE[[#This Row],[Atividade]]) -> PDM - SOLDA | AI14: =IF(BS_CONTROLE[[#This Row],[Atividade]]=0, "-", BS_CONTROLE[[#This Row],[Atividade]]) -> PDM - SOLDA | AJ14: =BS_CONTROLE[[#This Row],[Local - Partida]] -> - | AK14: =BS_CONTROLE[[#This Row],[Local - Encerramento]] -> - | AL14: =IF(BS_CONTROLE[[#This Row],[Entre - Estações]]=0, "-", BS_CONTROLE[[#This Row],[Entre - Estações]]) -> ZGI-ZFN | AM14: =IF(BS_CONTROLE[[#This Row],[SB]]=0, "-", BS_CONTROLE[[#This Row],[SB]]) -> ZGI-ZFN | AN14: =IF(BS_CONTROLE[[#This Row],[SUB]]=0, "-", BS_CONTROLE[[#This Row],[SUB]]) -> 73 | AO14: =BS_CONTROLE[[#This Row],[KM - Inicio]] -> 336.5 | AP14: =BS_CONTROLE[[#This Row],[KM - Inicio]] -> 336.5 | AQ14: 0.41666667 | AR14: 0 | AS14: 0 | AX14: =IF(D14="","*",IFERROR(IF(ISODD(COUNT(AR14:AW14)),"ERRO",SUM((AS14-AR14),(AU14-AT14),(AW14-AV14))),"ERRO")) -> 0 | AZ14: 0 | BA14: =IFERROR(_xlfn.XLOOKUP(AH14, BS_ATIVIDADE[ATIVIDADE],BS_ATIVIDADE[UNIDADE] ), "*") -> Nº DE SOLDA | BB14: {=_xlfn.XLOOKUP( 1, ( TabelaMap[SUB] = BS_CONTROLE[[#This Row],[SUB_5]]) * ( TabelaMap[KM Inicio] <= BS_CONTROLE[[#This Row],[KM - ínicio]]) * ( TabelaMap[KM Fim] >= BS_CONTROLE[[#This Row],[KM - ínicio]]), TabelaMap[Gerência], "-", 0 )} -> SP NORTE | BC14: {=_xlfn.XLOOKUP( 1, ( TabelaMap[SUB] = BS_CONTROLE[[#This Row],[SUB_5]]) * ( TabelaMap[KM Inicio] <= BS_CONTROLE[[#This Row],[KM - ínicio]]) * ( TabelaMap[KM Fim] >= BS_CONTROLE[[#This Row],[KM - ínicio]]), TabelaMap[Trecho Coordenação], "-", 0 )} -> TMI-ZEB | BD14: {=_xlfn.XLOOKUP( 1, ( TabelaMap[SUB] = BS_CONTROLE[[#This Row],[SUB_5]]) * ( TabelaMap[KM Inicio] <= BS_CONTROLE[[#This Row],[KM - Inicio]]) * ( TabelaMap[KM Fim] >= BS_CONTROLE[[#This Row],[KM - Inicio]]), TabelaMap[NOME SUB], "-", 0 )} -> ARARAQUARA - MARCO INICIAL | BG14: 0 | BI14: TP pronta 07:30, não solicitou devido chuva no local | BJ14: TP pronta 07:30, não solicitou devido chuva no local | BL14: CCO Circulação | BM14: Intervalo Oportunidade | BN14: Sem oportunidade | BO14: TP pronta 07:30, não solicitou devido chuva no local | BP14: =IF(AND(BQ14<1,BR14<1),"Produção e Intervalo",IF(BQ14<1,"Intervalo",IF(BR14<1,"Produção","Aderente"))) -> Produção e Intervalo | BQ14: =IF(OR(B14="",E14=""),"*",AX14/O14) -> 0 | BR14: =IF(OR(B14="",E14=""),"*",AZ14/P14) -> 0 | BS14: =IF(BM14="","",SUBSTITUTE(BL14," ","")&SUBSTITUTE(BM14," ","")) -> CCOCirculaçãoIntervaloOportunidade
