Workbook
Name Anomalia: SELEÇÕES!$Q$14:$Q$15
Name AnomaliaMecânica: SELEÇÕES!$AD$29
Name AnomaliaVia: SELEÇÕES!$AC$29
Name ATIVOS: BS_ATIVO!$A$2:$A$253
Name CCOCirculação: SELEÇÕES!$K$14:$K$17
Name CCOCirculaçãoIntervaloContrato: SELEÇÕES!$Q$29:$Q$39
Name CCOCirculaçãoIntervaloExtra: SELEÇÕES!$AH$29
Name CCOCirculaçãoIntervaloOportunidade: SELEÇÕES!$S$29:$S$39
Name CCOCirculaçãoProgramação: SELEÇÕES!$R$29
Name CCOEscala: SELEÇÕES!$J$14
Name CCOEscalaEquipagem: SELEÇÕES!$P$29:$P$32
Name CondiçõesClimática: SELEÇÕES!$R$14:$R$16
Name CondiçõesClimáticaChuva: SELEÇÕES!$AF$29
Name CondiçõesClimáticaTemperatura: SELEÇÕES!$AE$29:$AE$31
Name CondiçõesClimáticaVentosFortes: SELEÇÕES!$AG$29:$AG$29
Name Confiabilidade: SELEÇÕES!$S$14:$S$15
Name ConfiabilidadeAtivo: SELEÇÕES!$AJ$29:$AJ$30
Name ConfiabilidadeOperação: SELEÇÕES!$AI$29:$AI$33
Name Expansão: SELEÇÕES!$M$14:$M$15
Name ExpansãoEquipamento: SELEÇÕES!$V$29:$V$30
Name ExpansãoExecução: SELEÇÕES!$W$29:$W$38
Name FaltadeContrato: SELEÇÕES!$U$14
Name FaltadeContratoFaltadeContrato: SELEÇÕES!$AM$29
Name IMPCAUSADOR: SELEÇÕES!$A$13:$V$13
Name Infraestrutura: SELEÇÕES!$O$14:$O$15
Name InfraestruturaEquipamento: SELEÇÕES!$Z$29:$Z$30
Name InfraestruturaExecução: SELEÇÕES!$AA$29:$AA$38
Name Mecânica: SELEÇÕES!$G$14:$G$15
Name MecânicaLocomotiva: SELEÇÕES!$J$29
Name MecânicaVagão: SELEÇÕES!$K$29
Name Mecanização: SELEÇÕES!$H$14:$H$15
Name MecanizaçãoAtivos: SELEÇÕES!$M$29:$M$31
Name MecanizaçãoOperação: SELEÇÕES!$L$29:$L$35
Name Modernização: SELEÇÕES!$N$14:$N$17
Name ModernizaçãoEquipamento: SELEÇÕES!$X$29:$X$30
Name ModernizaçãoExecução: SELEÇÕES!$Y$29:$Y$38
Name NãoControláveis: SELEÇÕES!$B$14:$B$15
Name NãoControláveisAcidente: SELEÇÕES!$E$29
Name NãoControláveisVandalismo: SELEÇÕES!$D$29:$D$33
Name OK: SELEÇÕES!$P$14
Name OKOK: SELEÇÕES!$AB$29
Name Pátio: SELEÇÕES!$D$14
Name PátioOperação: SELEÇÕES!$G$29:$G$30
Name PCMMecânica: SELEÇÕES!$F$14
Name PCMMecânicaLocomotiva: SELEÇÕES!$I$29:$I$30
Name PCMVIA: SELEÇÕES!$I$14:$I$15
Name PCMVIAProgramação: SELEÇÕES!$O$29:$O$31
Name PCMVIARecursosInternos: SELEÇÕES!$N$29:$N$31
Name Qualidade: SELEÇÕES!$T$14:$T$15
Name QualidadeAtivo: SELEÇÕES!$AL$29
Name QualidadeOperação: SELEÇÕES!$AK$29:$AK$30
Name SemOportunidade: SELEÇÕES!$V$14
Name SemOportunidadeSemOportunidade: SELEÇÕES!$AN$29
Name SUBs: SELEÇÕES!$A$44:$A$50
Name Super: SELEÇÕES!$L$14:$L$15
Name SuperEquipamento: SELEÇÕES!$T$29:$T$30
Name SuperExecução: SELEÇÕES!$U$29:$U$38
Name TI: SELEÇÕES!$C$14
Name TISistema: SELEÇÕES!$F$29:$F$30
Name TO: SELEÇÕES!$A$14:$A$16

Sheet BASE_MAPA
A1: Gerência | B1: SUB | C1: KM Inicio | D1: KM Fim | E1: Trecho | F1: SB | G1: NOME SUB | H1: Trecho Coordenação
A2: SP SUL | B2: 30 | C2: 108.728 | D2: 110.502 | E2: 109-ZGM | F2: 1101093 | G2: PARATINGA - PEREQUÊ (L1 PRINCIPAL) | H2: ZEV-ZPT
A3: SP SUL | B3: 30 | C3: 108.728 | D3: 110.502 | E3: 109-ZGM | F3: 1101091 | G3: PARATINGA - PEREQUÊ (L1 PRINCIPAL) | H3: ZEV-ZPT
A4: SP SUL | B4: 30 | C4: 110.502 | D4: 111.787 | E4: 109-ZGM | F4: 1121101 | G4: PARATINGA - PEREQUÊ (L1 PRINCIPAL) | H4: ZEV-ZPT
A5: SP SUL | B5: 30 | C5: 110.502 | D5: 111.787 | E5: 109-ZGM | F5: 1121103 | G5: PARATINGA - PEREQUÊ (L1 PRINCIPAL) | H5: ZEV-ZPT
A6: SP SUL | B6: 30 | C6: 111.787 | D6: 113 | E6: 109-ZGM | F6: 1131121 | G6: PARATINGA - PEREQUÊ (L1 PRINCIPAL) | H6: ZEV-ZPT
A7: SP SUL | B7: 30 | C7: 113 | D7: 114 | E7: 109-ZGM | F7: ZGM1131 | G7: PARATINGA - PEREQUÊ (L1 PRINCIPAL) | H7: ZEV-ZPT
A8: SP SUL | B8: 30 | C8: 114 | D8: 115 | E8: ZGM | F8: ZGM1 | G8: PARATINGA - PEREQUÊ (L1 PRINCIPAL) | H8: ZEV-ZPT
A9: SP SUL | B9: 30 | C9: 115 | D9: 116.725 | E9: ZGM-ZZV | F9: 117ZGM1 | G9: PARATINGA - PEREQUÊ (L1 PRINCIPAL) | H9: ZEV-ZPT
A10: SP SUL | B10: 30 | C10: 116.725 | D10: 118 | E10: ZGM-ZZV | F10: 1181171 | G10: PARATINGA - PEREQUÊ (L1 PRINCIPAL) | H10: ZEV-ZPT
A11: SP SUL | B11: 30 | C11: 118 | D11: 119 | E11: ZGM-ZZV | F11: 1191181 | G11: PARATINGA - PEREQUÊ (L1 PRINCIPAL) | H11: ZEV-ZPT
A12: SP SUL | B12: 30 | C12: 119 | D12: 120 | E12: ZGM-ZZV | F12: 1201191 | G12: PARATINGA - PEREQUÊ (L1 PRINCIPAL) | H12: ZEV-ZPT
A13: SP SUL | B13: 30 | C13: 120 | D13: 121 | E13: ZGM-ZZV | F13: ZZV1201 | G13: PARATINGA - PEREQUÊ (L1 PRINCIPAL) | H13: ZEV-ZPT
A14: SP SUL | B14: 30 | C14: 121 | D14: 122.66 | E14: ZZV | F14: ZZV1 | G14: PARATINGA - PEREQUÊ (L1 PRINCIPAL) | H14: ZEV-ZPT
A15: SP SUL | B15: 48 | C15: 76.258 | D15: 78 | E15: ZKE | F15: ZKE1 | G15: CANGUERA - EVANGELISTA DE SOUZA (L1 PRINCIPAL) | H15: ZKE-ZEV
A16: SP SUL | B16: 48 | C16: 78 | D16: 79.6 | E16: ZKE-ZWW | F16: K80ZKE1 | G16: CANGUERA - EVANGELISTA DE SOUZA (L1 PRINCIPAL) | H16: ZKE-ZEV
A17: SP SUL | B17: 48 | C17: 79.6 | D17: 83 | E17: ZKE-ZWW | F17: K83K801 | G17: CANGUERA - EVANGELISTA DE SOUZA (L1 PRINCIPAL) | H17: ZKE-ZEV
A18: SP SUL | B18: 48 | C18: 83 | D18: 85 | E18: ZKE-ZWW | F18: K85K831 | G18: CANGUERA - EVANGELISTA DE SOUZA (L1 PRINCIPAL) | H18: ZKE-ZEV
A19: SP SUL | B19: 48 | C19: 85 | D19: 86 | E19: ZKE-ZWW | F19: ZWWK851 | G19: CANGUERA - EVANGELISTA DE SOUZA (L1 PRINCIPAL) | H19: ZKE-ZEV
A20: SP SUL | B20: 48 | C20: 86 | D20: 87.425 | E20: ZWW | F20: ZWW1 | G20: CANGUERA - EVANGELISTA DE SOUZA (L1 PRINCIPAL) | H20: ZKE-ZEV
A21: SP SUL | B21: 48 | C21: 87.425 | D21: 91 | E21: ZWW-ZKW | F21: K91ZWW1 | G21: CANGUERA - EVANGELISTA DE SOUZA (L1 PRINCIPAL) | H21: ZKE-ZEV
A22: SP SUL | B22: 48 | C22: 91 | D22: 93 | E22: ZWW-ZKW | F22: K93K911 | G22: CANGUERA - EVANGELISTA DE SOUZA (L1 PRINCIPAL) | H22: ZKE-ZEV
A23: SP SUL | B23: 48 | C23: 93 | D23: 95 | E23: ZWW-ZKW | F23: ZKWK931 | G23: CANGUERA - EVANGELISTA DE SOUZA (L1 PRINCIPAL) | H23: ZKE-ZEV
A24: SP SUL | B24: 48 | C24: 95 | D24: 97.729 | E24: ZKW | F24: ZKW1 | G24: CANGUERA - EVANGELISTA DE SOUZA (L1 PRINCIPAL) | H24: ZKE-ZEV
A25: SP SUL | B25: 48 | C25: 97.729 | D25: 102 | E25: ZKW-ZLU | F25: 102ZKW1 | G25: CANGUERA - EVANGELISTA DE SOUZA (L1 PRINCIPAL) | H25: ZKE-ZEV
A26: SP SUL | B26: 48 | C26: 102 | D26: 103 | E26: ZKW-ZLU | F26: 1031021 | G26: CANGUERA - EVANGELISTA DE SOUZA (L1 PRINCIPAL) | H26: ZKE-ZEV
A27: SP SUL | B27: 48 | C27: 103 | D27: 105.501 | E27: ZKW-ZLU | F27: 1051031 | G27: CANGUERA - EVANGELISTA DE SOUZA (L1 PRINCIPAL) | H27: ZKE-ZEV
A28: SP SUL | B28: 48 | C28: 105.501 | D28: 108.349 | E28: ZKW-ZLU | F28: ZLU1051 | G28: CANGUERA - EVANGELISTA DE SOUZA (L1 PRINCIPAL) | H28: ZKE-ZEV
A29: SP SUL | B29: 48 | C29: 108.349 | D29: 110 | E29: ZLU | F29: ZLU1 | G29: CANGUERA - EVANGELISTA DE SOUZA (L1 PRINCIPAL) | H29: ZKE-ZEV
A30: SP SUL | B30: 48 | C30: 110 | D30: 111 | E30: ZLU-ZWI | F30: 111ZLU1 | G30: CANGUERA - EVANGELISTA DE SOUZA (L1 PRINCIPAL) | H30: ZKE-ZEV
A31: SP SUL | B31: 48 | C31: 111 | D31: 112 | E31: ZLU-ZWI | F31: 112K111 | G31: CANGUERA - EVANGELISTA DE SOUZA (L1 PRINCIPAL) | H31: ZKE-ZEV
A32: SP SUL | B32: 48 | C32: 112 | D32: 113.337 | E32: ZLU-ZWI | F32: 113K121 | G32: CANGUERA - EVANGELISTA DE SOUZA (L1 PRINCIPAL) | H32: ZKE-ZEV
A33: SP SUL | B33: 48 | C33: 113.337 | D33: 118.181 | E33: ZLU-ZWI | F33: ZWI1131 | G33: CANGUERA - EVANGELISTA DE SOUZA (L1 PRINCIPAL) | H33: ZKE-ZEV
A34: SP SUL | B34: 48 | C34: 118.181 | D34: 120 | E34: ZWI | F34: ZWI1 | G34: CANGUERA - EVANGELISTA DE SOUZA (L1 PRINCIPAL) | H34: ZKE-ZEV
A35: SP SUL | B35: 48 | C35: 120 | D35: 121 | E35: ZWI-ZEM | F35: 121ZWI1 | G35: CANGUERA - EVANGELISTA DE SOUZA (L1 PRINCIPAL) | H35: ZKE-ZEV
A36: SP SUL | B36: 48 | C36: 121 | D36: 123 | E36: ZWI-ZEM | F36: 1231211 | G36: CANGUERA - EVANGELISTA DE SOUZA (L1 PRINCIPAL) | H36: ZKE-ZEV
A37: SP SUL | B37: 48 | C37: 123 | D37: 124 | E37: ZWI-ZEM | F37: 1241231 | G37: CANGUERA - EVANGELISTA DE SOUZA (L1 PRINCIPAL) | H37: ZKE-ZEV
A38: SP SUL | B38: 48 | C38: 124 | D38: 125 | E38: ZWI-ZEM | F38: 1251241 | G38: CANGUERA - EVANGELISTA DE SOUZA (L1 PRINCIPAL) | H38: ZKE-ZEV
A39: SP SUL | B39: 48 | C39: 125 | D39: 126 | E39: ZWI-ZEM | F39: 1261251 | G39: CANGUERA - EVANGELISTA DE SOUZA (L1 PRINCIPAL) | H39: ZKE-ZEV
A40: SP SUL | B40: 48 | C40: 126 | D40: 127.201 | E40: ZWI-ZEM | F40: ZYQ1261 | G40: CANGUERA - EVANGELISTA DE SOUZA (L1 PRINCIPAL) | H40: ZKE-ZEV
...

Sheet SELEÇÕES
A1: MAQUINISTAS | C1: ACIONAMENTO | E1: PRÉVIA | G1: DESVIO | I1: PROGRAMADO? | K1: ProgramaPCM | M1: Prioridade
A2: FIXO | C2: SBR | E2: 1 | G2: VIA | I2: SIM | K2: Contrato | M2: P0
A3: ESCALA | C3: AGD ACIONAMENTO PCM | E3: 2 | I3: NÃO | K3: Oportunidade | M3: P1
A4: FIXO + ESCALA | C4: ACIONAMENTO | I4: OPORTUNIDADE | K4: Extra | M4: P2
M5: P3
M6: P4
M7: P5
A13: TO | B13: Não Controláveis | C13: TI | D13: Pátio | E13: Tração | F13: PCM Mecânica | G13: Mecânica | H13: Mecanização | I13: PCM VIA | J13: CCO Escala | K13: CCO Circulação | L13: Super | M13: Expansão | N13: Modernização | O13: Infraestrutura | P13: OK | Q13: Anomalia | R13: Condições Climática | S13: Confiabilidade | T13: Engenharia | U13: Falta de Contrato | V13: Sem Oportunidade
A14: Embarcado | B14: Vandalismo | C14: Sistema | D14: Operação | E14: Operação | F14: Locomotiva | G14: Locomotiva | H14: Operação | I14: Recursos Internos | J14: Equipagem | K14: Intervalo Contrato | L14: Equipamento | M14: Equipamento | N14: Equipamento | O14: Equipamento | P14: OK | Q14: Via | R14: Temperatura | S14: Operação | T14: Operação | U14: Falta de Contrato | V14: Sem Oportunidade
A15: Não Embarcado | B15: Acidente | C15: ="" | G15: Vagão | H15: Ativos | I15: Programação | K15: Intervalo Oportunidade | L15: Execução | M15: Execução | N15: Execução | O15: Execução | Q15: Mecânica | R15: Chuva | S15: Ativo | T15: Ativo
A16: Operação | C16: ="" | K16: Intervalo Extra | R16: Ventos Fortes
K17: Programação
A28: TOEmbarcado | B28: TONãoEmbarcado | C28: TOOperação | D28: NãoControláveisVandalismo | E28: NãoControláveisAcidente | F28: TISistema | G28: PátioOperação | H28: TraçãoOperação | I28: PCMMecânicaLocomotiva | J28: MecânicaLocomotiva | K28: MecânicaVagão | L28: MecanizaçãoOperação | M28: MecanizaçãoAtivos | N28: PCMVIARecursosInternos | O28: PCMVIAProgramação | P28: CCOEscalaEquipagem | Q28: CCOCirculaçãoIntervaloContrato | R28: CCOCirculaçãoProgramação | S28: CCOCirculaçãoIntervaloOportunidade | T28: SuperEquipamento | U28: SuperExecução | V28: ExpansãoEquipamento | W28: ExpansãoExecução | X28: ModernizaçãoEquipamento | Y28: ModernizaçãoExecução | Z28: InfraestruturaEquipamento | AA28: InfraestruturaExecução | AB28: OKOK | AC28: AnomaliaVia | AD28: AnomaliaMecânica | AE28: CondiçõesClimáticaTemperatura | AF28: CondiçõesClimáticaChuva | AG28: CondiçõesClimáticaVentos Fortes | AH28: CCOCirculaçãoIntervaloExtra | AI28: ConfiabilidadeOperação | AJ28: ConfiabilidadeAtivo | AK28: EngenhariaOperação | AL28: EngenhariaAtivo | AM28: Falta de ContratoFalta de Contrato | AN28: SemOportunidadeSemOportunidade
A29: Avaria de CBL | B29: AMV sem indicação | C29: Alteração de programação da turma | D29: Locomotiva | E29: Acidente | F29: Sistema licenciamento indisponível | G29: Manobra indisponível | H29: Maquinista indisponível | I29: Alteração de programação | J29: Avaria | K29: Avaria | L29: Operador indisponível | M29: Avaria em veículo (Mecanização) | N29: Cancelado devido priorização | O29: Falta de OS | P29: Atraso chegada maquinista | Q29: Realizado entre trens | R29: Desvio alocação de locomotiva | S29: Sem oportunidade | T29: Avaria (Escavadeira / caminhão / munck) | U29: Erro de programação | V29: Avaria (Escavadeira / caminhão / munck) | W29: Erro de programação | X29: Avaria (Escavadeira / caminhão / munck / Socadora) | Y29: Erro de programação | Z29: Avaria (Escavadeira / caminhão / munck) | AA29: Erro de programação | AB29: OK | AC29: Defeito na via | AD29: Avaria em trem | AE29: Temperatura Alta | AF29: Chuva | AG29: Ventos Fortes | AH29: Serviço extra contrato | AI29: Falta de Equipe | AJ29: Avaria | AK29: Falta de Equipe | AL29: Avaria | AM29: Falta de Contrato | AN29: Sem Oportunidade
A30: Avaria de CBL | D30: Vagão | F30: Queda / Instabilidade de sistema | G30: Linha ocupada | H30: Atualização malha | I30: Locomotiva indisponível | L30: Operador não habilitado | M30: Avaria em veículo (Detecção) | N30: Alteração de programação | O30: Alteração de programação (Equipamento) | P30: Jornada maquinista excedida | Q30: Concedido intervalo parcial | S30: Realizado entre trens | T30: Avaria (Ferramental) | U30: Alteração de programação | V30: Avaria (Ferramental) | W30: Alteração de programação | X30: Avaria (Ferramental) | Y30: Alteração de programação | Z30: Avaria (Ferramental) | AA30: Alteração de programação | AE30: Temperatura Baixa | AI30: Alteração de Programação | AJ30: Manutenção | AK30: Alteração de Programação
D31: Via de circulação | L31: Desvio de escala | M31: Desvio programação (Manutenção) | N31: Erro de programação | O31: Falta de equipamento / material | P31: Falta Maquinista (Contrato) | Q31: Intervalo negado em D-1 | S31: Concedido intervalo parcial | U31: Quando reduzido da turma | W31: Quando reduzido da turma | Y31: Quando reduzido da turma | AA31: Quando reduzido da turma | AE31: Oscilação de Temperatura | AI31: Falha de programação
D32: Equipamento via | L32: Baixa produtividade | P32: Falta Maquinista (Extra) | Q32: Intervalo Concedido fora do horário programado | S32: Intervalo negado em D-1 | U32: Falta de turma (Não Justificado) | W32: Falta de turma (Não Justificado) | Y32: Falta de turma (Não Justificado) | AA32: Falta de turma (Não Justificado) | AI32: Desvio de escala
D33: Ativo mecanização | L33: Risco de exceder a jornada | Q33: Fluxo intenso de trens | S33: Intervalo Concedido fora do horário programado | U33: Equipe interditada | W33: Equipe interditada | Y33: Equipe interditada | AA33: Equipe interditada | AI33: Risco de exceder a jornada
L34: Abastecimento | Q34: Propagação de TI | S34: Fluxo intenso de trens | U34: Falta de insumo / material | W34: Falta de insumo / material | Y34: Falta de insumo / material | AA34: Falta de insumo / material
L35: Desvio de programação | Q35: Propagação de avaria de trens | S35: Propagação de TI | U35: Desvio escala da turma | W35: Desvio escala da turma | Y35: Desvio escala da turma | AA35: Desvio escala da turma
Q36: Propagação de vandalismo | S36: Propagação de avaria de trens | U36: Intervalo utilizado parcialmente | W36: Intervalo utilizado parcialmente | Y36: Intervalo utilizado parcialmente | AA36: Intervalo utilizado parcialmente
Q37: Propagação por motivo via | S37: Propagação de vandalismo | U37: Baixa produtividade | W37: Baixa produtividade | Y37: Baixa produtividade | AA37: Baixa produtividade
Q38: Erro CCO | S38: Propagação por motivo via | U38: Falha de execução | W38: Falha de execução | Y38: Falha de execução | AA38: Falha de execução
Q39: Intervalo Fracionado | S39: Erro CCO
A44: 42
A45: 43
A46: 70
A47: 71
A48: 73 | C48: /
A49: 170

Sheet SP_SUL
B1: INICIO | F1: PROGRAMA | AI1: ] | BH1: GESTÃO DE ACOMPANHAMENTO | BM1: FECHAMENTO
F2: ITENS GUIA | S2: RESPONSABILIDADE | AA2: RECURSO | AI2: ITENS GUIA | AS2: INTERVALO | BA2: PRODUÇÃO | BC2: RESPONSABILIDADE
F3: O QUE? | H3: ONDE? | O3: INTERVALO | Q3: PODUÇÃO | S3: QUEM VAI RESPONDER PELA EXECUÇÃO? | W3: GESTÃO | AA3: EQUIPAGEM | AE3: ATIVOS | AI3: O QUE? | AK3: ONDE? | AS3: PARCIAL 1 | AU3: PARCIAL 2 | AW3: PARCIAL 3 | AY3: TOTAL | BC3: QUEM VAI RESPONDER PELA EXECUÇÃO? | BM3: ANALISE | BQ3: %
A4: FORMULA | B4: ESCREVE | C4: FORMULA | D4: SELECIONAR | F4: SELECIONAR | G4: FORMULA | H4: ESCREVE | I4: ESCREVE | J4: ESCREVE | K4: ESCREVE | L4: ESCREVE | M4: ESCREVE | N4: ESCREVE | O4: ESCREVE | P4: ESCREVE | Q4: ESCREVE | R4: FORMULA | S4: SELECIONAR | T4: SELECIONAR | U4: FORMULA | V4: ESCREVE | W4: ESCREVE | X4: SELECIONAR | Y4: SELECIONAR | Z4: SELECIONAR | AA4: ESCREVE | AB4: SELECIONAR | AC4: SELECIONAR | AD4: ESCREVE | AE4: ESCREVE | AF4: ESCREVE | AG4: ESCREVE | AI4: SELECIONAR | AJ4: FORMULA | AK4: ESCREVE | AL4: ESCREVE | AM4: ESCREVE | AN4: ESCREVE | AO4: ESCREVE | AP4: ESCREVE | AQ4: ESCREVE | AR4: ESCREVE | AS4: ESCREVE | AT4: ESCREVE | AU4: ESCREVE | AV4: ESCREVE | AW4: ESCREVE | AX4: ESCREVE | AY4: FORMULA | AZ4: SELECIONAR | BA4: ESCREVE | BB4: FORMULA | BC4: SELECIONAR | BD4: SELECIONAR | BE4: FORMULA | BF4: ESCREVE | BG4: * | BH4: ESCREVE | BI4: ESCREVE | BJ4: ESCREVE | BK4: ESCREVE | BL4: * | BM4: SELECIONAR | BN4: SELECIONAR | BO4: SELECIONAR | BP4: ESCREVE | BQ4: FORMULA | BR4: FORMULA | BS4: FORMULA
A5: CHAVE | B5: DATA | C5: Semana | D5: ATIVO | E5: *1 | F5: Atividade | G5: Atividade - Inidicador | H5: Local - Partida | I5: Local - Encerramento | J5: SUB | K5: KM - Inicio | L5: KM - Fim | M5: Entre - Estações | N5: SB | O5: Inicia | P5: Duração | Q5: Quantidade | R5: Unidade | S5: Gerência da Via | T5: Coordenação da Via | U5: Trecho | V5: Responsavel pelo boletim | W5: Detalhe Programação | X5: Programar para D+1 | Y5: Confirmação programação | Z5: Prioridade | AA5: Qtd. Maquinista | AB5: Tipo de Maquinista (Fixo / Escala) | AC5: Tipo de Acionamento | AD5: Apresentação no lastro | AE5: Ativo - 1 | AF5: Ativo - 2 | AG5: Vagões - Qtd. | AH5: *2 | AI5: Atividade_1 | AJ5: Atividade - PDM | AK5: Local - Partida_2 | AL5: Local - Encerramento_3 | AM5: Entre-Locais | AN5: SB_4 | AO5: SUB_5 | AP5: KM - ínicio | AQ5: KM - Fim_6 | AR5: HR Turma Pronta | AS5: Inicio | AT5: Fim | AU5: Inicio_7 | AV5: Fim_8 | AW5: Inicio_9 | AX5: Fim_10 | AY5: TOTAL | AZ5: LIBERADO PELO CCO | BA5: Quantidade_11 | BB5: Unidade_12 | BC5: Gerência da Via_13 | BD5: Coordenação da Via_14 | BE5: Trecho_15 | BF5: Responsavel pelo boletim_16 | BG5: *3 | BH5: Status | BI5: Prévia CCO 22h | BJ5: Prévia - 1 | BK5: Prévia - 2 | BL5: *4 | BM5: Responsabilidade | BN5: Fechamento - Impacto | BO5: Detalhe - Fechamento | BP5: Justificativa | BQ5: Analise Prévia | BR5: Intervalo | BS5: QTD | BT5: Concat
A6: =D6&B6 -> V4846054 | B6: 46054 | C6: =IF(BS_CONTROLE[[#This Row],[DATA]]="","",WEEKNUM(BS_CONTROLE[[#This Row],[DATA]])) -> 6 | D6: V48 | F6: DESLOCAMENTO | G6: =IF(D6="","*",VLOOKUP(F6,BS_ATIVIDADE[],3,FALSE)) -> OUTROS | H6: ZRX | I6: ZAC | J6: 70 | K6: 82.4 | L6: - | M6: ZRX-ZAC | N6: ZRXZAC | O6: 0.35416667 | P6: 0.041666667 | Q6: 1 | R6: =IFERROR(_xlfn.XLOOKUP(F6, BS_ATIVIDADE[ATIVIDADE],BS_ATIVIDADE[UNIDADE] ), "*") -> BINÁRIO | S6: {=_xlfn.XLOOKUP( 1, ( TabelaMap[SUB] = BS_CONTROLE[[#This Row],[SUB]]) * ( TabelaMap[KM Inicio] <= BS_CONTROLE[[#This Row],[KM - Inicio]]) * ( TabelaMap[KM Fim] >= BS_CONTROLE[[#This Row],[KM - Inicio]]), TabelaMap[Gerência], "-", 0 )} -> SP SUL | T6: {=_xlfn.XLOOKUP( 1, ( TabelaMap[SUB] = BS_CONTROLE[[#This Row],[SUB]]) * ( TabelaMap[KM Inicio] <= BS_CONTROLE[[#This Row],[KM - Inicio]]) * ( TabelaMap[KM Fim] >= BS_CONTROLE[[#This Row],[KM - Inicio]]), TabelaMap[Trecho Coordenação], "-", 0 )} -> ZBV-ZRX | U6: {=_xlfn.XLOOKUP( 1, ( TabelaMap[SUB] = BS_CONTROLE[[#This Row],[SUB]]) * ( TabelaMap[KM Inicio] <= BS_CONTROLE[[#This Row],[KM - Inicio]]) * ( TabelaMap[KM Fim] >= BS_CONTROLE[[#This Row],[KM - Inicio]]), TabelaMap[NOME SUB], "-", 0 )} -> RECANTO - ITIRAPINA (L1 PRINCIPAL) | V6: Ezequiel | W6: Deslocamento | X6: Oportunidade | AA6: 1 | AB6: FIXO | AC6: - | AD6: 0.29166667 | AE6: 6249 | AF6: - | AG6: - | AI6: =IF(BS_CONTROLE[[#This Row],[Atividade]]=0, "-", BS_CONTROLE[[#This Row],[Atividade]]) -> DESLOCAMENTO | AJ6: =IF(BS_CONTROLE[[#This Row],[Atividade]]=0, "-", BS_CONTROLE[[#This Row],[Atividade]]) -> DESLOCAMENTO | AK6: =BS_CONTROLE[[#This Row],[Local - Partida]] -> ZRX | AL6: =BS_CONTROLE[[#This Row],[Local - Encerramento]] -> ZAC | AM6: =IF(BS_CONTROLE[[#This Row],[Entre - Estações]]=0, "-", BS_CONTROLE[[#This Row],[Entre - Estações]]) -> ZRX-ZAC | AN6: =IF(BS_CONTROLE[[#This Row],[SB]]=0, "-", BS_CONTROLE[[#This Row],[SB]]) -> ZRXZAC | AO6: =IF(BS_CONTROLE[[#This Row],[SUB]]=0, "-", BS_CONTROLE[[#This Row],[SUB]]) -> 70 | AP6: =BS_CONTROLE[[#This Row],[KM - Inicio]] -> 82.4 | AQ6: =BS_CONTROLE[[#This Row],[KM - Inicio]] -> 82.4 | AR6: 0.39791667 | AS6: 0 | AT6: 0.041666667 | AY6: =IF(D6="","*",IFERROR(IF(ISODD(COUNT(AS6:AX6)),"ERRO",SUM((AT6-AS6),(AV6-AU6),(AX6-AW6))),"ERRO")) -> 0.041666667 | BA6: 1 | BB6: =IFERROR(_xlfn.XLOOKUP(AI6, BS_ATIVIDADE[ATIVIDADE],BS_ATIVIDADE[UNIDADE] ), "*") -> BINÁRIO | BC6: {=_xlfn.XLOOKUP( 1, ( TabelaMap[SUB] = BS_CONTROLE[[#This Row],[SUB_5]]) * ( TabelaMap[KM Inicio] <= BS_CONTROLE[[#This Row],[KM - ínicio]]) * ( TabelaMap[KM Fim] >= BS_CONTROLE[[#This Row],[KM - ínicio]]), TabelaMap[Gerência], "-", 0 )} -> SP SUL | BD6: {=_xlfn.XLOOKUP( 1, ( TabelaMap[SUB] = BS_CONTROLE[[#This Row],[SUB_5]]) * ( TabelaMap[KM Inicio] <= BS_CONTROLE[[#This Row],[KM - ínicio]]) * ( TabelaMap[KM Fim] >= BS_CONTROLE[[#This Row],[KM - ínicio]]), TabelaMap[Trecho Coordenação], "-", 0 )} -> ZBV-ZRX | BE6: {=_xlfn.XLOOKUP( 1, ( TabelaMap[SUB] = BS_CONTROLE[[#This Row],[SUB_5]]) * ( TabelaMap[KM Inicio] <= BS_CONTROLE[[#This Row],[KM - Inicio]]) * ( TabelaMap[KM Fim] >= BS_CONTROLE[[#This Row],[KM - Inicio]]), TabelaMap[NOME SUB], "-", 0 )} -> RECANTO - ITIRAPINA (L1 PRINCIPAL) | BH6: 2 | BJ6: MC1 09:33, licenciado 10:41, segue para o local de trabalho | BK6: Realozado deslocamento de ZRX para ZAC. | BM6: OK | BN6: OK | BO6: OK | BP6: - | BQ6: =IF(AND(BR6<1,BS6<1),"Produção e Intervalo",IF(BR6<1,"Intervalo",IF(BS6<1,"Produção","Aderente"))) -> Aderente | BR6: =IF(OR(B6="",F6=""),"*",AY6/P6) -> 1 | BS6: =IF(OR(B6="",F6=""),"*",BA6/Q6) -> 1 | BT6: =IF(BN6="","",SUBSTITUTE(BM6," ","")&SUBSTITUTE(BN6," ","")) -> OKOK
A7: =D7&B7 -> V4246054 | B7: 46054 | C7: =IF(BS_CONTROLE[[#This Row],[DATA]]="","",WEEKNUM(BS_CONTROLE[[#This Row],[DATA]])) -> 6 | D7: V42 | F7: MECANIZAÇÃO - SOCADORA | G7: =IF(D7="","*",VLOOKUP(F7,BS_ATIVIDADE[],3,FALSE)) -> MECANIZAÇÃO - SOCADORA | H7: ZYU1 | I7: ZYU1 | J7: 56 | K7: 206.78 | L7: 208.6 | M7: {=_xlfn.XLOOKUP( 1, ( TabelaMap[SUB] = BS_CONTROLE[[#This Row],[SUB]]) * ( TabelaMap[KM Inicio] <= BS_CONTROLE[[#This Row],[KM - Inicio]]) * ( TabelaMap[KM Fim] >= BS_CONTROLE[[#This Row],[KM - Inicio]]), TabelaMap[Trecho], "-", 0 )} -> ZYU-ZST | N7: {=_xlfn.XLOOKUP( 1, ( TabelaMap[SUB] = BS_CONTROLE[[#This Row],[SUB]]) * ( TabelaMap[KM Inicio] <= BS_CONTROLE[[#This Row],[KM - Inicio]]) * ( TabelaMap[KM Fim] >= BS_CONTROLE[[#This Row],[KM - Inicio]]), TabelaMap[SB], "-", 0 )} -> 206ZST | O7: 0.35416667 | P7: 0.083333333 | Q7: 500 | R7: =IFERROR(_xlfn.XLOOKUP(F7, BS_ATIVIDADE[ATIVIDADE],BS_ATIVIDADE[UNIDADE] ), "*") -> M | S7: {=_xlfn.XLOOKUP( 1, ( TabelaMap[SUB] = BS_CONTROLE[[#This Row],[SUB]]) * ( TabelaMap[KM Inicio] <= BS_CONTROLE[[#This Row],[KM - Inicio]]) * ( TabelaMap[KM Fim] >= BS_CONTROLE[[#This Row],[KM - Inicio]]), TabelaMap[Gerência], "-", 0 )} -> SP SUL | T7: {=_xlfn.XLOOKUP( 1, ( TabelaMap[SUB] = BS_CONTROLE[[#This Row],[SUB]]) * ( TabelaMap[KM Inicio] <= BS_CONTROLE[[#This Row],[KM - Inicio]]) * ( TabelaMap[KM Fim] >= BS_CONTROLE[[#This Row],[KM - Inicio]]), TabelaMap[Trecho Coordenação], "-", 0 )} -> ZBV-ZKE | U7: {=_xlfn.XLOOKUP( 1, ( TabelaMap[SUB] = BS_CONTROLE[[#This Row],[SUB]]) * ( TabelaMap[KM Inicio] <= BS_CONTROLE[[#This Row],[KM - Inicio]]) * ( TabelaMap[KM Fim] >= BS_CONTROLE[[#This Row],[KM - Inicio]]), TabelaMap[NOME SUB], "-", 0 )} -> CANGUERA - BOA VISTA NOVA (L2 PRINCIPAL) | V7: Ezequiel | W7: Socaria mecanizada | X7: Oportunidade | AA7: 1 | AB7: FIXO | AC7: - | AD7: 0.29166667 | AE7: 6242 | AF7: - | AG7: - | AI7: =IF(BS_CONTROLE[[#This Row],[Atividade]]=0, "-", BS_CONTROLE[[#This Row],[Atividade]]) -> MECANIZAÇÃO - SOCADORA | AJ7: =IF(BS_CONTROLE[[#This Row],[Atividade]]=0, "-", BS_CONTROLE[[#This Row],[Atividade]]) -> MECANIZAÇÃO - SOCADORA | AK7: =BS_CONTROLE[[#This Row],[Local - Partida]] -> ZYU1 | AL7: =BS_CONTROLE[[#This Row],[Local - Encerramento]] -> ZYU1 | AM7: =IF(BS_CONTROLE[[#This Row],[Entre - Estações]]=0, "-", BS_CONTROLE[[#This Row],[Entre - Estações]]) -> ZYU-ZST | AN7: =IF(BS_CONTROLE[[#This Row],[SB]]=0, "-", BS_CONTROLE[[#This Row],[SB]]) -> 206ZST | AO7: =IF(BS_CONTROLE[[#This Row],[SUB]]=0, "-", BS_CONTROLE[[#This Row],[SUB]]) -> 56 | AP7: =BS_CONTROLE[[#This Row],[KM - Inicio]] -> 206.78 | AQ7: =BS_CONTROLE[[#This Row],[KM - Inicio]] -> 206.78 | AR7: 0.32916667 | AS7: 0.42638889 | AT7: 0.525 | AY7: =IF(D7="","*",IFERROR(IF(ISODD(COUNT(AS7:AX7)),"ERRO",SUM((AT7-AS7),(AV7-AU7),(AX7-AW7))),"ERRO")) -> 0.098611111 | BA7: 500 | BB7: =IFERROR(_xlfn.XLOOKUP(AI7, BS_ATIVIDADE[ATIVIDADE],BS_ATIVIDADE[UNIDADE] ), "*") -> M | BC7: {=_xlfn.XLOOKUP( 1, ( TabelaMap[SUB] = BS_CONTROLE[[#This Row],[SUB_5]]) * ( TabelaMap[KM Inicio] <= BS_CONTROLE[[#This Row],[KM - ínicio]]) * ( TabelaMap[KM Fim] >= BS_CONTROLE[[#This Row],[KM - ínicio]]), TabelaMap[Gerência], "-", 0 )} -> SP SUL | BD7: {=_xlfn.XLOOKUP( 1, ( TabelaMap[SUB] = BS_CONTROLE[[#This Row],[SUB_5]]) * ( TabelaMap[KM Inicio] <= BS_CONTROLE[[#This Row],[KM - ínicio]]) * ( TabelaMap[KM Fim] >= BS_CONTROLE[[#This Row],[KM - ínicio]]), TabelaMap[Trecho Coordenação], "-", 0 )} -> ZBV-ZKE | BE7: {=_xlfn.XLOOKUP( 1, ( TabelaMap[SUB] = BS_CONTROLE[[#This Row],[SUB_5]]) * ( TabelaMap[KM Inicio] <= BS_CONTROLE[[#This Row],[KM - Inicio]]) * ( TabelaMap[KM Fim] >= BS_CONTROLE[[#This Row],[KM - Inicio]]), TabelaMap[NOME SUB], "-", 0 )} -> CANGUERA - BOA VISTA NOVA (L2 PRINCIPAL) | BH7: 2 | BJ7: MC1 07:54, intervalo 10:14 até 12:36 | BK7: MC1 07:54, intervalo 10:14 até 12:36 | BM7: OK | BN7: OK | BO7: OK | BQ7: =IF(AND(BR7<1,BS7<1),"Produção e Intervalo",IF(BR7<1,"Intervalo",IF(BS7<1,"Produção","Aderente"))) -> Aderente | BR7: =IF(OR(B7="",F7=""),"*",AY7/P7) -> 1.1833333 | BS7: =IF(OR(B7="",F7=""),"*",BA7/Q7) -> 1 | BT7: =IF(BN7="","",SUBSTITUTE(BM7," ","")&SUBSTITUTE(BN7," ","")) -> OKOK
A8: =D8&B8 -> V85 | C8: =IF(BS_CONTROLE[[#This Row],[DATA]]="","",WEEKNUM(BS_CONTROLE[[#This Row],[DATA]])) | D8: V85 | F8: MECANIZAÇÃO - SOCADORA | G8: =IF(D8="","*",VLOOKUP(F8,BS_ATIVIDADE[],3,FALSE)) -> MECANIZAÇÃO - SOCADORA | M8: {=_xlfn.XLOOKUP( 1, ( TabelaMap[SUB] = BS_CONTROLE[[#This Row],[SUB]]) * ( TabelaMap[KM Inicio] <= BS_CONTROLE[[#This Row],[KM - Inicio]]) * ( TabelaMap[KM Fim] >= BS_CONTROLE[[#This Row],[KM - Inicio]]), TabelaMap[Trecho], "-", 0 )} -> - | N8: {=_xlfn.XLOOKUP( 1, ( TabelaMap[SUB] = BS_CONTROLE[[#This Row],[SUB]]) * ( TabelaMap[KM Inicio] <= BS_CONTROLE[[#This Row],[KM - Inicio]]) * ( TabelaMap[KM Fim] >= BS_CONTROLE[[#This Row],[KM - Inicio]]), TabelaMap[SB], "-", 0 )} -> - | R8: =IFERROR(_xlfn.XLOOKUP(F8, BS_ATIVIDADE[ATIVIDADE],BS_ATIVIDADE[UNIDADE] ), "*") -> M | S8: {=_xlfn.XLOOKUP( 1, ( TabelaMap[SUB] = BS_CONTROLE[[#This Row],[SUB]]) * ( TabelaMap[KM Inicio] <= BS_CONTROLE[[#This Row],[KM - Inicio]]) * ( TabelaMap[KM Fim] >= BS_CONTROLE[[#This Row],[KM - Inicio]]), TabelaMap[Gerência], "-", 0 )} -> - | T8: {=_xlfn.XLOOKUP( 1, ( TabelaMap[SUB] = BS_CONTROLE[[#This Row],[SUB]]) * ( TabelaMap[KM Inicio] <= BS_CONTROLE[[#This Row],[KM - Inicio]]) * ( TabelaMap[KM Fim] >= BS_CONTROLE[[#This Row],[KM - Inicio]]), TabelaMap[Trecho Coordenação], "-", 0 )} -> - | U8: {=_xlfn.XLOOKUP( 1, ( TabelaMap[SUB] = BS_CONTROLE[[#This Row],[SUB]]) * ( TabelaMap[KM Inicio] <= BS_CONTROLE[[#This Row],[KM - Inicio]]) * ( TabelaMap[KM Fim] >= BS_CONTROLE[[#This Row],[KM - Inicio]]), TabelaMap[NOME SUB], "-", 0 )} -> - | AI8: =IF(BS_CONTROLE[[#This Row],[Atividade]]=0, "-", BS_CONTROLE[[#This Row],[Atividade]]) -> MECANIZAÇÃO - SOCADORA | AJ8: =IF(BS_CONTROLE[[#This Row],[Atividade]]=0, "-", BS_CONTROLE[[#This Row],[Atividade]]) -> MECANIZAÇÃO - SOCADORA | AK8: =BS_CONTROLE[[#This Row],[Local - Partida]] -> 0 | AL8: =BS_CONTROLE[[#This Row],[Local - Encerramento]] -> 0 | AM8: =IF(BS_CONTROLE[[#This Row],[Entre - Estações]]=0, "-", BS_CONTROLE[[#This Row],[Entre - Estações]]) -> - | AN8: =IF(BS_CONTROLE[[#This Row],[SB]]=0, "-", BS_CONTROLE[[#This Row],[SB]]) -> - | AO8: =IF(BS_CONTROLE[[#This Row],[SUB]]=0, "-", BS_CONTROLE[[#This Row],[SUB]]) -> - | AP8: =BS_CONTROLE[[#This Row],[KM - Inicio]] -> 0 | AQ8: =BS_CONTROLE[[#This Row],[KM - Inicio]] -> 0 | AY8: =IF(D8="","*",IFERROR(IF(ISODD(COUNT(AS8:AX8)),"ERRO",SUM((AT8-AS8),(AV8-AU8),(AX8-AW8))),"ERRO")) -> 0 | BB8: =IFERROR(_xlfn.XLOOKUP(AI8, BS_ATIVIDADE[ATIVIDADE],BS_ATIVIDADE[UNIDADE] ), "*") -> M | BC8: {=_xlfn.XLOOKUP( 1, ( TabelaMap[SUB] = BS_CONTROLE[[#This Row],[SUB_5]]) * ( TabelaMap[KM Inicio] <= BS_CONTROLE[[#This Row],[KM - ínicio]]) * ( TabelaMap[KM Fim] >= BS_CONTROLE[[#This Row],[KM - ínicio]]), TabelaMap[Gerência], "-", 0 )} -> - | BD8: {=_xlfn.XLOOKUP( 1, ( TabelaMap[SUB] = BS_CONTROLE[[#This Row],[SUB_5]]) * ( TabelaMap[KM Inicio] <= BS_CONTROLE[[#This Row],[KM - ínicio]]) * ( TabelaMap[KM Fim] >= BS_CONTROLE[[#This Row],[KM - ínicio]]), TabelaMap[Trecho Coordenação], "-", 0 )} -> - | BE8: {=_xlfn.XLOOKUP( 1, ( TabelaMap[SUB] = BS_CONTROLE[[#This Row],[SUB_5]]) * ( TabelaMap[KM Inicio] <= BS_CONTROLE[[#This Row],[KM - Inicio]]) * ( TabelaMap[KM Fim] >= BS_CONTROLE[[#This Row],[KM - Inicio]]), TabelaMap[NOME SUB], "-", 0 )} -> - | BQ8: =IF(AND(BR8<1,BS8<1),"Produção e Intervalo",IF(BR8<1,"Intervalo",IF(BS8<1,"Produção","Aderente"))) -> Aderente | BR8: =IF(OR(B8="",F8=""),"*",AY8/P8) -> * | BS8: =IF(OR(B8="",F8=""),"*",BA8/Q8) -> * | BT8: =IF(BN8="","",SUBSTITUTE(BM8," ","")&SUBSTITUTE(BN8," ","")) | BU8: TEXTO ABAIXO
A9: =D9&B9 -> E17 | C9: =IF(BS_CONTROLE[[#This Row],[DATA]]="","",WEEKNUM(BS_CONTROLE[[#This Row],[DATA]])) | D9: E17 | E9: 4 | F9: CAMINHÃO DE SOLDA | G9: =IF(D9="","*",VLOOKUP(F9,BS_ATIVIDADE[],3,FALSE)) -> CAMINHÂO - SOLDA | M9: {=_xlfn.XLOOKUP( 1, ( TabelaMap[SUB] = BS_CONTROLE[[#This Row],[SUB]]) * ( TabelaMap[KM Inicio] <= BS_CONTROLE[[#This Row],[KM - Inicio]]) * ( TabelaMap[KM Fim] >= BS_CONTROLE[[#This Row],[KM - Inicio]]), TabelaMap[Trecho], "-", 0 )} -> - | N9: {=_xlfn.XLOOKUP( 1, ( TabelaMap[SUB] = BS_CONTROLE[[#This Row],[SUB]]) * ( TabelaMap[KM Inicio] <= BS_CONTROLE[[#This Row],[KM - Inicio]]) * ( TabelaMap[KM Fim] >= BS_CONTROLE[[#This Row],[KM - Inicio]]), TabelaMap[SB], "-", 0 )} -> - | R9: =IFERROR(_xlfn.XLOOKUP(F9, BS_ATIVIDADE[ATIVIDADE],BS_ATIVIDADE[UNIDADE] ), "*") -> Nº DE SOLDA | S9: {=_xlfn.XLOOKUP( 1, ( TabelaMap[SUB] = BS_CONTROLE[[#This Row],[SUB]]) * ( TabelaMap[KM Inicio] <= BS_CONTROLE[[#This Row],[KM - Inicio]]) * ( TabelaMap[KM Fim] >= BS_CONTROLE[[#This Row],[KM - Inicio]]), TabelaMap[Gerência], "-", 0 )} -> - | T9: {=_xlfn.XLOOKUP( 1, ( TabelaMap[SUB] = BS_CONTROLE[[#This Row],[SUB]]) * ( TabelaMap[KM Inicio] <= BS_CONTROLE[[#This Row],[KM - Inicio]]) * ( TabelaMap[KM Fim] >= BS_CONTROLE[[#This Row],[KM - Inicio]]), TabelaMap[Trecho Coordenação], "-", 0 )} -> - | U9: {=_xlfn.XLOOKUP( 1, ( TabelaMap[SUB] = BS_CONTROLE[[#This Row],[SUB]]) * ( TabelaMap[KM Inicio] <= BS_CONTROLE[[#This Row],[KM - Inicio]]) * ( TabelaMap[KM Fim] >= BS_CONTROLE[[#This Row],[KM - Inicio]]), TabelaMap[NOME SUB], "-", 0 )} -> - | AI9: =IF(BS_CONTROLE[[#This Row],[Atividade]]=0, "-", BS_CONTROLE[[#This Row],[Atividade]]) -> CAMINHÃO DE SOLDA | AJ9: =IF(BS_CONTROLE[[#This Row],[Atividade]]=0, "-", BS_CONTROLE[[#This Row],[Atividade]]) -> CAMINHÃO DE SOLDA | AK9: =BS_CONTROLE[[#This Row],[Local - Partida]] -> 0 | AL9: =BS_CONTROLE[[#This Row],[Local - Encerramento]] -> 0 | AM9: =IF(BS_CONTROLE[[#This Row],[Entre - Estações]]=0, "-", BS_CONTROLE[[#This Row],[Entre - Estações]]) -> - | AN9: =IF(BS_CONTROLE[[#This Row],[SB]]=0, "-", BS_CONTROLE[[#This Row],[SB]]) -> - | AO9: =IF(BS_CONTROLE[[#This Row],[SUB]]=0, "-", BS_CONTROLE[[#This Row],[SUB]]) -> - | AP9: =BS_CONTROLE[[#This Row],[KM - Inicio]] -> 0 | AQ9: =BS_CONTROLE[[#This Row],[KM - Inicio]] -> 0 | AY9: =IF(D9="","*",IFERROR(IF(ISODD(COUNT(AS9:AX9)),"ERRO",SUM((AT9-AS9),(AV9-AU9),(AX9-AW9))),"ERRO")) -> 0 | BB9: =IFERROR(_xlfn.XLOOKUP(AI9, BS_ATIVIDADE[ATIVIDADE],BS_ATIVIDADE[UNIDADE] ), "*") -> Nº DE SOLDA | BC9: {=_xlfn.XLOOKUP( 1, ( TabelaMap[SUB] = BS_CONTROLE[[#This Row],[SUB_5]]) * ( TabelaMap[KM Inicio] <= BS_CONTROLE[[#This Row],[KM - ínicio]]) * ( TabelaMap[KM Fim] >= BS_CONTROLE[[#This Row],[KM - ínicio]]), TabelaMap[Gerência], "-", 0 )} -> - | BD9: {=_xlfn.XLOOKUP( 1, ( TabelaMap[SUB] = BS_CONTROLE[[#This Row],[SUB_5]]) * ( TabelaMap[KM Inicio] <= BS_CONTROLE[[#This Row],[KM - ínicio]]) * ( TabelaMap[KM Fim] >= BS_CONTROLE[[#This Row],[KM - ínicio]]), TabelaMap[Trecho Coordenação], "-", 0 )} -> - | BE9: {=_xlfn.XLOOKUP( 1, ( TabelaMap[SUB] = BS_CONTROLE[[#This Row],[SUB_5]]) * ( TabelaMap[KM Inicio] <= BS_CONTROLE[[#This Row],[KM - Inicio]]) * ( TabelaMap[KM Fim] >= BS_CONTROLE[[#This Row],[KM - Inicio]]), TabelaMap[NOME SUB], "-", 0 )} -> - | BQ9: =IF(AND(BR9<1,BS9<1),"Produção e Intervalo",IF(BR9<1,"Intervalo",IF(BS9<1,"Produção","Aderente"))) -> Aderente | BR9: =IF(OR(B9="",F9=""),"*",AY9/P9) -> * | BS9: =IF(OR(B9="",F9=""),"*",BA9/Q9) -> * | BT9: =IF(BN9="","",SUBSTITUTE(BM9," ","")&SUBSTITUTE(BN9," ","")) | BU9: *RELATÓRIO DIÁRIO - SP_SUL - 16/2/2026* ---------------------------- ⚪ *Ativo:* EXPANSÃO TURMA 1 ├ KM: 170 └ Status: TP pronto 08h42 / Concedidointervalo das 09h42 até 11h00. Realizado alívio de tensão ⚪ *Ativo:* KLECIO (TP-699) ├ KM: 68 └ Status: TP em preparação, pronta 08:52 / Previsão de faixa após L90 as 14h00 ⚪ *Ativo:* E42 ├ KM: 68 └ Status: Previsão de solicitar MC1 13h30 / ⚪ *Ativo:* ROGÉRIO (TP-730) ├ KM: 56 └ Status: TP não solicita intervalo/ realizado acabamento. ⚪ *Ativo:* V93 ├ KM: 56 └ Status: Acionado maquinista / MC1 10h31 /autorizado entrada na via 11h52 / aguardando passagem do M80 para deslocar para km de trabalho. ⚪ *Ativo:* W59 ├ KM: 49 └ Status: Alterado progrmação / recolher dormentes do km200 e descarregar no km190+000 / MC1 08h48 /Autorizado entrada na via 10h47 / Em deslocamento ⚪ *Ativo:* ROBSON (TF-701) ├ KM: 56 └ Status: TP em preparação ⚪ *Ativo:* JACIANO (TF-674) ├ KM: 56 └ Status: TP em preparação ⚪ *Ativo:* V95 ├ KM: 49 └ Status: Alterado programação, solicita MC1 em ZMA. ⚪ *Ativo:* W60 ├ KM: 55 └ Status: MC1 10h06 / Cancelado a faixa, devido priorização do E17 + TP's solda e troca de trilho. ⚪ *Ativo:* E17 ├ KM: 55 └ Status: MC1 08h06 / PRevisão de faixa após L40, em intervalo 09:12 ⚪ *Ativo:* V89 ├ KM: 55 └ Status: Alterado programação para deslocamento de ZEM para ZKW / MC1 09h49 / previsão de faixa após i13 / ⚪ *Ativo:* CLEBISON (TP-728) ├ KM: 55 └ Status: Alterado programação para km 102+500 via 2 / Em interevalo das 09h32 até 12h00 ⚪ *Ativo:* ISMAEL(TP-726) ├ KM: 55 └ Status: Alterado programação para km 102+500 via 2 / Em interevalo das 09h32 até 12h00 ⚪ *Ativo:* DIEGO (TP-681) ├ KM: 55 └ Status: TP pronto 09h32 / Em intrervalo das 09h32 até 12h00 ⚪ *Ativo:* MATEUS (TP-809) ├ KM: 48 └ Status: TP pronto 08h50 / Realizado intervalo 09:12 até 11:12 ⚪ *Ativo:* ADENISON (TP-810) ├ KM: 48 └ Status: TP pronto 08h50 / Realizado intervalo 09:12 até 11:12 ⚪ *Ativo:* JACIANO (TF-674) ├ KM: 92 └ Status: TP pronto 09h51 / Previsão de faixa após L40 / ⚪ *Ativo:* A84 ├ KM: 92 └ Status: MC1 07h55 / Previsão de faixa após i22, autorizado 08:59, em inspeção a ZPT ⚪ *Ativo:* W61 ├ KM: 92 └ Status: MC1 08h25 / Em deslocamento da turmas ⚪ *Ativo:* W62 ├ KM: 92 └ Status: MC1 07h13 / autorizado entrada na via 08h03 / Em deslocamento das turmas ⚪ *Ativo:* EXPANSÃO TURMA 1 ├ KM: 53 └ Status: Equipe pronta 09:05, sem oportunidade ⚪ *Ativo:* RAFAEL (TP-695) ├ KM: 53 └ Status: TP pronto 10h47 / Previsão de faixa após i22 (A confirmar) / ✅ *Total de itens encontrados:* 23
A10: =D10&B10 | C10: =IF(BS_CONTROLE[[#This Row],[DATA]]="","",WEEKNUM(BS_CONTROLE[[#This Row],[DATA]])) | E10: 5 | G10: =IF(D10="","*",VLOOKUP(F10,BS_ATIVIDADE[],3,FALSE)) -> * | M10: {=_xlfn.XLOOKUP( 1, ( TabelaMap[SUB] = BS_CONTROLE[[#This Row],[SUB]]) * ( TabelaMap[KM Inicio] <= BS_CONTROLE[[#This Row],[KM - Inicio]]) * ( TabelaMap[KM Fim] >= BS_CONTROLE[[#This Row],[KM - Inicio]]), TabelaMap[Trecho], "-", 0 )} -> - | N10: {=_xlfn.XLOOKUP( 1, ( TabelaMap[SUB] = BS_CONTROLE[[#This Row],[SUB]]) * ( TabelaMap[KM Inicio] <= BS_CONTROLE[[#This Row],[KM - Inicio]]) * ( TabelaMap[KM Fim] >= BS_CONTROLE[[#This Row],[KM - Inicio]]), TabelaMap[SB], "-", 0 )} -> - | R10: =IFERROR(_xlfn.XLOOKUP(F10, BS_ATIVIDADE[ATIVIDADE],BS_ATIVIDADE[UNIDADE] ), "*") -> * | S10: {=_xlfn.XLOOKUP( 1, ( TabelaMap[SUB] = BS_CONTROLE[[#This Row],[SUB]]) * ( TabelaMap[KM Inicio] <= BS_CONTROLE[[#This Row],[KM - Inicio]]) * ( TabelaMap[KM Fim] >= BS_CONTROLE[[#This Row],[KM - Inicio]]), TabelaMap[Gerência], "-", 0 )} -> - | T10: {=_xlfn.XLOOKUP( 1, ( TabelaMap[SUB] = BS_CONTROLE[[#This Row],[SUB]]) * ( TabelaMap[KM Inicio] <= BS_CONTROLE[[#This Row],[KM - Inicio]]) * ( TabelaMap[KM Fim] >= BS_CONTROLE[[#This Row],[KM - Inicio]]), TabelaMap[Trecho Coordenação], "-", 0 )} -> - | U10: {=_xlfn.XLOOKUP( 1, ( TabelaMap[SUB] = BS_CONTROLE[[#This Row],[SUB]]) * ( TabelaMap[KM Inicio] <= BS_CONTROLE[[#This Row],[KM - Inicio]]) * ( TabelaMap[KM Fim] >= BS_CONTROLE[[#This Row],[KM - Inicio]]), TabelaMap[NOME SUB], "-", 0 )} -> - | AI10: =IF(BS_CONTROLE[[#This Row],[Atividade]]=0, "-", BS_CONTROLE[[#This Row],[Atividade]]) -> - | AJ10: =IF(BS_CONTROLE[[#This Row],[Atividade]]=0, "-", BS_CONTROLE[[#This Row],[Atividade]]) -> - | AK10: =BS_CONTROLE[[#This Row],[Local - Partida]] -> 0 | AL10: =BS_CONTROLE[[#This Row],[Local - Encerramento]] -> 0 | AM10: =IF(BS_CONTROLE[[#This Row],[Entre - Estações]]=0, "-", BS_CONTROLE[[#This Row],[Entre - Estações]]) -> - | AN10: =IF(BS_CONTROLE[[#This Row],[SB]]=0, "-", BS_CONTROLE[[#This Row],[SB]]) -> - | AO10: =IF(BS_CONTROLE[[#This Row],[SUB]]=0, "-", BS_CONTROLE[[#This Row],[SUB]]) -> - | AP10: =BS_CONTROLE[[#This Row],[KM - Inicio]] -> 0 | AQ10: =BS_CONTROLE[[#This Row],[KM - Inicio]] -> 0 | AY10: =IF(D10="","*",IFERROR(IF(ISODD(COUNT(AS10:AX10)),"ERRO",SUM((AT10-AS10),(AV10-AU10),(AX10-AW10))),"ERRO")) -> * | BB10: =IFERROR(_xlfn.XLOOKUP(AI10, BS_ATIVIDADE[ATIVIDADE],BS_ATIVIDADE[UNIDADE] ), "*") -> * | BC10: {=_xlfn.XLOOKUP( 1, ( TabelaMap[SUB] = BS_CONTROLE[[#This Row],[SUB_5]]) * ( TabelaMap[KM Inicio] <= BS_CONTROLE[[#This Row],[KM - ínicio]]) * ( TabelaMap[KM Fim] >= BS_CONTROLE[[#This Row],[KM - ínicio]]), TabelaMap[Gerência], "-", 0 )} -> - | BD10: {=_xlfn.XLOOKUP( 1, ( TabelaMap[SUB] = BS_CONTROLE[[#This Row],[SUB_5]]) * ( TabelaMap[KM Inicio] <= BS_CONTROLE[[#This Row],[KM - ínicio]]) * ( TabelaMap[KM Fim] >= BS_CONTROLE[[#This Row],[KM - ínicio]]), TabelaMap[Trecho Coordenação], "-", 0 )} -> - | BE10: {=_xlfn.XLOOKUP( 1, ( TabelaMap[SUB] = BS_CONTROLE[[#This Row],[SUB_5]]) * ( TabelaMap[KM Inicio] <= BS_CONTROLE[[#This Row],[KM - Inicio]]) * ( TabelaMap[KM Fim] >= BS_CONTROLE[[#This Row],[KM - Inicio]]), TabelaMap[NOME SUB], "-", 0 )} -> - | BQ10: =IF(AND(BR10<1,BS10<1),"Produção e Intervalo",IF(BR10<1,"Intervalo",IF(BS10<1,"Produção","Aderente"))) -> Aderente | BR10: =IF(OR(B10="",F10=""),"*",AY10/P10) -> * | BS10: =IF(OR(B10="",F10=""),"*",BA10/Q10) -> * | BT10: =IF(BN10="","",SUBSTITUTE(BM10," ","")&SUBSTITUTE(BN10," ",""))
A11: =D11&B11 | C11: =IF(BS_CONTROLE[[#This Row],[DATA]]="","",WEEKNUM(BS_CONTROLE[[#This Row],[DATA]])) | E11: 6 | G11: =IF(D11="","*",VLOOKUP(F11,BS_ATIVIDADE[],3,FALSE)) -> * | M11: {=_xlfn.XLOOKUP( 1, ( TabelaMap[SUB] = BS_CONTROLE[[#This Row],[SUB]]) * ( TabelaMap[KM Inicio] <= BS_CONTROLE[[#This Row],[KM - Inicio]]) * ( TabelaMap[KM Fim] >= BS_CONTROLE[[#This Row],[KM - Inicio]]), TabelaMap[Trecho], "-", 0 )} -> - | N11: {=_xlfn.XLOOKUP( 1, ( TabelaMap[SUB] = BS_CONTROLE[[#This Row],[SUB]]) * ( TabelaMap[KM Inicio] <= BS_CONTROLE[[#This Row],[KM - Inicio]]) * ( TabelaMap[KM Fim] >= BS_CONTROLE[[#This Row],[KM - Inicio]]), TabelaMap[SB], "-", 0 )} -> - | R11: =IFERROR(_xlfn.XLOOKUP(F11, BS_ATIVIDADE[ATIVIDADE],BS_ATIVIDADE[UNIDADE] ), "*") -> * | S11: {=_xlfn.XLOOKUP( 1, ( TabelaMap[SUB] = BS_CONTROLE[[#This Row],[SUB]]) * ( TabelaMap[KM Inicio] <= BS_CONTROLE[[#This Row],[KM - Inicio]]) * ( TabelaMap[KM Fim] >= BS_CONTROLE[[#This Row],[KM - Inicio]]), TabelaMap[Gerência], "-", 0 )} -> - | T11: {=_xlfn.XLOOKUP( 1, ( TabelaMap[SUB] = BS_CONTROLE[[#This Row],[SUB]]) * ( TabelaMap[KM Inicio] <= BS_CONTROLE[[#This Row],[KM - Inicio]]) * ( TabelaMap[KM Fim] >= BS_CONTROLE[[#This Row],[KM - Inicio]]), TabelaMap[Trecho Coordenação], "-", 0 )} -> - | U11: {=_xlfn.XLOOKUP( 1, ( TabelaMap[SUB] = BS_CONTROLE[[#This Row],[SUB]]) * ( TabelaMap[KM Inicio] <= BS_CONTROLE[[#This Row],[KM - Inicio]]) * ( TabelaMap[KM Fim] >= BS_CONTROLE[[#This Row],[KM - Inicio]]), TabelaMap[NOME SUB], "-", 0 )} -> - | AI11: =IF(BS_CONTROLE[[#This Row],[Atividade]]=0, "-", BS_CONTROLE[[#This Row],[Atividade]]) -> - | AJ11: =IF(BS_CONTROLE[[#This Row],[Atividade]]=0, "-", BS_CONTROLE[[#This Row],[Atividade]]) -> - | AK11: =BS_CONTROLE[[#This Row],[Local - Partida]] -> 0 | AL11: =BS_CONTROLE[[#This Row],[Local - Encerramento]] -> 0 | AM11: =IF(BS_CONTROLE[[#This Row],[Entre - Estações]]=0, "-", BS_CONTROLE[[#This Row],[Entre - Estações]]) -> - | AN11: =IF(BS_CONTROLE[[#This Row],[SB]]=0, "-", BS_CONTROLE[[#This Row],[SB]]) -> - | AO11: =IF(BS_CONTROLE[[#This Row],[SUB]]=0, "-", BS_CONTROLE[[#This Row],[SUB]]) -> - | AP11: =BS_CONTROLE[[#This Row],[KM - Inicio]] -> 0 | AQ11: =BS_CONTROLE[[#This Row],[KM - Inicio]] -> 0 | AY11: =IF(D11="","*",IFERROR(IF(ISODD(COUNT(AS11:AX11)),"ERRO",SUM((AT11-AS11),(AV11-AU11),(AX11-AW11))),"ERRO")) -> * | BB11: =IFERROR(_xlfn.XLOOKUP(AI11, BS_ATIVIDADE[ATIVIDADE],BS_ATIVIDADE[UNIDADE] ), "*") -> * | BC11: {=_xlfn.XLOOKUP( 1, ( TabelaMap[SUB] = BS_CONTROLE[[#This Row],[SUB_5]]) * ( TabelaMap[KM Inicio] <= BS_CONTROLE[[#This Row],[KM - ínicio]]) * ( TabelaMap[KM Fim] >= BS_CONTROLE[[#This Row],[KM - ínicio]]), TabelaMap[Gerência], "-", 0 )} -> - | BD11: {=_xlfn.XLOOKUP( 1, ( TabelaMap[SUB] = BS_CONTROLE[[#This Row],[SUB_5]]) * ( TabelaMap[KM Inicio] <= BS_CONTROLE[[#This Row],[KM - ínicio]]) * ( TabelaMap[KM Fim] >= BS_CONTROLE[[#This Row],[KM - ínicio]]), TabelaMap[Trecho Coordenação], "-", 0 )} -> - | BE11: {=_xlfn.XLOOKUP( 1, ( TabelaMap[SUB] = BS_CONTROLE[[#This Row],[SUB_5]]) * ( TabelaMap[KM Inicio] <= BS_CONTROLE[[#This Row],[KM - Inicio]]) * ( TabelaMap[KM Fim] >= BS_CONTROLE[[#This Row],[KM - Inicio]]), TabelaMap[NOME SUB], "-", 0 )} -> - | BQ11: =IF(AND(BR11<1,BS11<1),"Produção e Intervalo",IF(BR11<1,"Intervalo",IF(BS11<1,"Produção","Aderente"))) -> Aderente | BR11: =IF(OR(B11="",F11=""),"*",AY11/P11) -> * | BS11: =IF(OR(B11="",F11=""),"*",BA11/Q11) -> * | BT11: =IF(BN11="","",SUBSTITUTE(BM11," ","")&SUBSTITUTE(BN11," ",""))
A12: =D12&B12 -> KLECIO (TP-699)46055 | B12: 46055 | C12: =IF(BS_CONTROLE[[#This Row],[DATA]]="","",WEEKNUM(BS_CONTROLE[[#This Row],[DATA]])) -> 6 | D12: KLECIO (TP-699) | F12: PDM - SOLDA | G12: =IF(D12="","*",VLOOKUP(F12,BS_ATIVIDADE[],3,FALSE)) -> SOLDA | H12: - | I12: - | J12: 70 | K12: 134.9 | L12: - | M12: ZRX-ZWX | N12: ZRQ1/133ZRQ1 | O12: 0.33333333 | P12: 0.083333333 | Q12: 1 | R12: =IFERROR(_xlfn.XLOOKUP(F12, BS_ATIVIDADE[ATIVIDADE],BS_ATIVIDADE[UNIDADE] ), "*") -> Nº DE SOLDA | S12: SP SUL | T12: ZBV-ZRX | U12: {=_xlfn.XLOOKUP( 1, ( TabelaMap[SUB] = BS_CONTROLE[[#This Row],[SUB]]) * ( TabelaMap[KM Inicio] <= BS_CONTROLE[[#This Row],[KM - Inicio]]) * ( TabelaMap[KM Fim] >= BS_CONTROLE[[#This Row],[KM - Inicio]]), TabelaMap[NOME SUB], "-", 0 )} -> RECANTO - ITIRAPINA (L1 PRINCIPAL) | V12: Klecio | W12: Execução de solda - Condicionado a temperatura | X12: Oportunidade | Y12: OPORTUNIDADE | AA12: - | AD12: - | AI12: =IF(BS_CONTROLE[[#This Row],[Atividade]]=0, "-", BS_CONTROLE[[#This Row],[Atividade]]) -> PDM - SOLDA | AJ12: =IF(BS_CONTROLE[[#This Row],[Atividade]]=0, "-", BS_CONTROLE[[#This Row],[Atividade]]) -> PDM - SOLDA | AK12: =BS_CONTROLE[[#This Row],[Local - Partida]] -> - | AL12: =BS_CONTROLE[[#This Row],[Local - Encerramento]] -> - | AM12: =IF(BS_CONTROLE[[#This Row],[Entre - Estações]]=0, "-", BS_CONTROLE[[#This Row],[Entre - Estações]]) -> ZRX-ZWX | AN12: =IF(BS_CONTROLE[[#This Row],[SB]]=0, "-", BS_CONTROLE[[#This Row],[SB]]) -> ZRQ1/133ZRQ1 | AO12: =IF(BS_CONTROLE[[#This Row],[SUB]]=0, "-", BS_CONTROLE[[#This Row],[SUB]]) -> 70 | AP12: =BS_CONTROLE[[#This Row],[KM - Inicio]] -> 134.9 | AQ12: =BS_CONTROLE[[#This Row],[KM - Inicio]] -> 134.9 | AR12: 0.40625 | AS12: 0 | AT12: 0 | AY12: =IF(D12="","*",IFERROR(IF(ISODD(COUNT(AS12:AX12)),"ERRO",SUM((AT12-AS12),(AV12-AU12),(AX12-AW12))),"ERRO")) -> 0 | BA12: 0 | BB12: =IFERROR(_xlfn.XLOOKUP(AI12, BS_ATIVIDADE[ATIVIDADE],BS_ATIVIDADE[UNIDADE] ), "*") -> Nº DE SOLDA | BC12: SP SUL | BD12: ZBV-ZRX | BF12: Klecio | BH12: 0 | BJ12: Devido condições climáticas / TP pronto 09h45 / Sem oportunidade de faixa | BK12: Devido condições climáticas / TP pronto 09h45 / Sem oportunidade de faixa | BM12: Sem Oportunidade | BN12: Sem Oportunidade | BO12: Sem Oportunidade | BP12: Devido condições climáticas / TP pronto 09h45 / Sem oportunidade de faixa | BQ12: =IF(AND(BR12<1,BS12<1),"Produção e Intervalo",IF(BR12<1,"Intervalo",IF(BS12<1,"Produção","Aderente"))) -> Produção e Intervalo | BR12: =IF(OR(B12="",F12=""),"*",AY12/P12) -> 0 | BS12: =IF(OR(B12="",F12=""),"*",BA12/Q12) -> 0 | BT12: =IF(BN12="","",SUBSTITUTE(BM12," ","")&SUBSTITUTE(BN12," ","")) -> SemOportunidadeSemOportunidade
A13: =D13&B13 -> EXPANSÃO TURMA 146055 | B13: 46055 | C13: =IF(BS_CONTROLE[[#This Row],[DATA]]="","",WEEKNUM(BS_CONTROLE[[#This Row],[DATA]])) -> 6 | D13: EXPANSÃO TURMA 1 | F13: EXPANSÃO - SOLDA | G13: =IF(D13="","*",VLOOKUP(F13,BS_ATIVIDADE[],3,FALSE)) -> EXPANSÃO | H13: - | I13: - | J13: 170 | K13: 114.045 | L13: - | M13: {=_xlfn.XLOOKUP( 1, ( TabelaMap[SUB] = BS_CONTROLE[[#This Row],[SUB]]) * ( TabelaMap[KM Inicio] <= BS_CONTROLE[[#This Row],[KM - Inicio]]) * ( TabelaMap[KM Fim] >= BS_CONTROLE[[#This Row],[KM - Inicio]]), TabelaMap[Trecho], "-", 0 )} -> ZCD-ZSQ | N13: ZCD1172 | O13: 0.33333333 | P13: 0.083333333 | Q13: 1 | R13: =IFERROR(_xlfn.XLOOKUP(F13, BS_ATIVIDADE[ATIVIDADE],BS_ATIVIDADE[UNIDADE] ), "*") -> Nº DE SOLDA | S13: {=_xlfn.XLOOKUP( 1, ( TabelaMap[SUB] = BS_CONTROLE[[#This Row],[SUB]]) * ( TabelaMap[KM Inicio] <= BS_CONTROLE[[#This Row],[KM - Inicio]]) * ( TabelaMap[KM Fim] >= BS_CONTROLE[[#This Row],[KM - Inicio]]), TabelaMap[Gerência], "-", 0 )} -> SP SUL | T13: {=_xlfn.XLOOKUP( 1, ( TabelaMap[SUB] = BS_CONTROLE[[#This Row],[SUB]]) * ( TabelaMap[KM Inicio] <= BS_CONTROLE[[#This Row],[KM - Inicio]]) * ( TabelaMap[KM Fim] >= BS_CONTROLE[[#This Row],[KM - Inicio]]), TabelaMap[Trecho Coordenação], "-", 0 )} -> ZBV-ZRX | U13: {=_xlfn.XLOOKUP( 1, ( TabelaMap[SUB] = BS_CONTROLE[[#This Row],[SUB]]) * ( TabelaMap[KM Inicio] <= BS_CONTROLE[[#This Row],[KM - Inicio]]) * ( TabelaMap[KM Fim] >= BS_CONTROLE[[#This Row],[KM - Inicio]]), TabelaMap[NOME SUB], "-", 0 )} -> RECANTO - ITIRAPINA (L2 PRINCIPAL) | V13: Elder | W13: Execução de solda - Condicionado a temperatura | X13: Oportunidade | Y13: OPORTUNIDADE | AA13: 1 | AB13: FIXO | AC13: - | AD13: 0.29166667 | AE13: 6249 | AF13: - | AG13: - | AI13: =IF(BS_CONTROLE[[#This Row],[Atividade]]=0, "-", BS_CONTROLE[[#This Row],[Atividade]]) -> EXPANSÃO - SOLDA | AJ13: =IF(BS_CONTROLE[[#This Row],[Atividade]]=0, "-", BS_CONTROLE[[#This Row],[Atividade]]) -> EXPANSÃO - SOLDA | AK13: =BS_CONTROLE[[#This Row],[Local - Partida]] -> - | AL13: =BS_CONTROLE[[#This Row],[Local - Encerramento]] -> - | AM13: =IF(BS_CONTROLE[[#This Row],[Entre - Estações]]=0, "-", BS_CONTROLE[[#This Row],[Entre - Estações]]) -> ZCD-ZSQ | AN13: =IF(BS_CONTROLE[[#This Row],[SB]]=0, "-", BS_CONTROLE[[#This Row],[SB]]) -> ZCD1172 | AO13: =IF(BS_CONTROLE[[#This Row],[SUB]]=0, "-", BS_CONTROLE[[#This Row],[SUB]]) -> 170 | AP13: =BS_CONTROLE[[#This Row],[KM - Inicio]] -> 114.045 | AQ13: =BS_CONTROLE[[#This Row],[KM - Inicio]] -> 114.045 | AR13: 0 | AS13: 0 | AT13: 0 | AY13: =IF(D13="","*",IFERROR(IF(ISODD(COUNT(AS13:AX13)),"ERRO",SUM((AT13-AS13),(AV13-AU13),(AX13-AW13))),"ERRO")) -> 0 | BA13: 0 | BB13: =IFERROR(_xlfn.XLOOKUP(AI13, BS_ATIVIDADE[ATIVIDADE],BS_ATIVIDADE[UNIDADE] ), "*") -> Nº DE SOLDA | BC13: {=_xlfn.XLOOKUP( 1, ( TabelaMap[SUB] = BS_CONTROLE[[#This Row],[SUB_5]]) * ( TabelaMap[KM Inicio] <= BS_CONTROLE[[#This Row],[KM - ínicio]]) * ( TabelaMap[KM Fim] >= BS_CONTROLE[[#This Row],[KM - ínicio]]), TabelaMap[Gerência], "-", 0 )} -> SP SUL | BD13: {=_xlfn.XLOOKUP( 1, ( TabelaMap[SUB] = BS_CONTROLE[[#This Row],[SUB_5]]) * ( TabelaMap[KM Inicio] <= BS_CONTROLE[[#This Row],[KM - ínicio]]) * ( TabelaMap[KM Fim] >= BS_CONTROLE[[#This Row],[KM - ínicio]]), TabelaMap[Trecho Coordenação], "-", 0 )} -> ZBV-ZRX | BE13: {=_xlfn.XLOOKUP( 1, ( TabelaMap[SUB] = BS_CONTROLE[[#This Row],[SUB_5]]) * ( TabelaMap[KM Inicio] <= BS_CONTROLE[[#This Row],[KM - Inicio]]) * ( TabelaMap[KM Fim] >= BS_CONTROLE[[#This Row],[KM - Inicio]]), TabelaMap[NOME SUB], "-", 0 )} -> RECANTO - ITIRAPINA (L2 PRINCIPAL) | BF13: Elder | BH13: 0 | BJ13: TP não solicita intervalo / condições climáticas (chuva) | BK13: TP não solicita intervalo / condições climáticas (chuva) | BM13: Condições Climática | BN13: Chuva | BO13: Chuva | BP13: TP não solicita intervalo / condições climáticas (chuva) | BQ13: =IF(AND(BR13<1,BS13<1),"Produção e Intervalo",IF(BR13<1,"Intervalo",IF(BS13<1,"Produção","Aderente"))) -> Produção e Intervalo | BR13: =IF(OR(B13="",F13=""),"*",AY13/P13) -> 0 | BS13: =IF(OR(B13="",F13=""),"*",BA13/Q13) -> 0 | BT13: =IF(BN13="","",SUBSTITUTE(BM13," ","")&SUBSTITUTE(BN13," ","")) -> CondiçõesClimáticaChuva
A14: =D14&B14 -> V8346055 | B14: 46055 | C14: =IF(BS_CONTROLE[[#This Row],[DATA]]="","",WEEKNUM(BS_CONTROLE[[#This Row],[DATA]])) -> 6 | D14: V83 | F14: MECANIZAÇÃO - SOCADORA | G14: =IF(D14="","*",VLOOKUP(F14,BS_ATIVIDADE[],3,FALSE)) -> MECANIZAÇÃO - SOCADORA | H14: ZAC2 | I14: ZAC2 | J14: 70 | K14: 87 | L14: - | M14: {=_xlfn.XLOOKUP( 1, ( TabelaMap[SUB] = BS_CONTROLE[[#This Row],[SUB]]) * ( TabelaMap[KM Inicio] <= BS_CONTROLE[[#This Row],[KM - Inicio]]) * ( TabelaMap[KM Fim] >= BS_CONTROLE[[#This Row],[KM - Inicio]]), TabelaMap[Trecho], "-", 0 )} -> ZAC-ZSW | N14: {=_xlfn.XLOOKUP( 1, ( TabelaMap[SUB] = BS_CONTROLE[[#This Row],[SUB]]) * ( TabelaMap[KM Inicio] <= BS_CONTROLE[[#This Row],[KM - Inicio]]) * ( TabelaMap[KM Fim] >= BS_CONTROLE[[#This Row],[KM - Inicio]]), TabelaMap[SB], "-", 0 )} -> ZACZSW | O14: 0.41666667 | P14: 0.083333333 | Q14: 360 | R14: =IFERROR(_xlfn.XLOOKUP(F14, BS_ATIVIDADE[ATIVIDADE],BS_ATIVIDADE[UNIDADE] ), "*") -> M | S14: {=_xlfn.XLOOKUP( 1, ( TabelaMap[SUB] = BS_CONTROLE[[#This Row],[SUB]]) * ( TabelaMap[KM Inicio] <= BS_CONTROLE[[#This Row],[KM - Inicio]]) * ( TabelaMap[KM Fim] >= BS_CONTROLE[[#This Row],[KM - Inicio]]), TabelaMap[Gerência], "-", 0 )} -> SP SUL | T14: {=_xlfn.XLOOKUP( 1, ( TabelaMap[SUB] = BS_CONTROLE[[#This Row],[SUB]]) * ( TabelaMap[KM Inicio] <= BS_CONTROLE[[#This Row],[KM - Inicio]]) * ( TabelaMap[KM Fim] >= BS_CONTROLE[[#This Row],[KM - Inicio]]), TabelaMap[Trecho Coordenação], "-", 0 )} -> ZBV-ZRX | U14: {=_xlfn.XLOOKUP( 1, ( TabelaMap[SUB] = BS_CONTROLE[[#This Row],[SUB]]) * ( TabelaMap[KM Inicio] <= BS_CONTROLE[[#This Row],[KM - Inicio]]) * ( TabelaMap[KM Fim] >= BS_CONTROLE[[#This Row],[KM - Inicio]]), TabelaMap[NOME SUB], "-", 0 )} -> RECANTO - ITIRAPINA (L1 PRINCIPAL) | V14: Antonioni | W14: Socaria mecanizada | X14: Oportunidade | Y14: OPORTUNIDADE | AA14: 1 | AB14: FIXO | AC14: - | AD14: - | AE14: - | AF14: - | AI14: =IF(BS_CONTROLE[[#This Row],[Atividade]]=0, "-", BS_CONTROLE[[#This Row],[Atividade]]) -> MECANIZAÇÃO - SOCADORA | AJ14: =IF(BS_CONTROLE[[#This Row],[Atividade]]=0, "-", BS_CONTROLE[[#This Row],[Atividade]]) -> MECANIZAÇÃO - SOCADORA | AK14: ZIQ-2 | AL14: ZIQ-2 | AM14: ZRX | AN14: ZRX1 | AO14: =IF(BS_CONTROLE[[#This Row],[SUB]]=0, "-", BS_CONTROLE[[#This Row],[SUB]]) -> 70 | AP14: 131.99 | AQ14: 131.2 | AR14: 0.33402778 | AS14: 0 | AT14: 0 | AY14: =IF(D14="","*",IFERROR(IF(ISODD(COUNT(AS14:AX14)),"ERRO",SUM((AT14-AS14),(AV14-AU14),(AX14-AW14))),"ERRO")) -> 0 | BA14: 0 | BB14: =IFERROR(_xlfn.XLOOKUP(AI14, BS_ATIVIDADE[ATIVIDADE],BS_ATIVIDADE[UNIDADE] ), "*") -> M | BC14: {=_xlfn.XLOOKUP( 1, ( TabelaMap[SUB] = BS_CONTROLE[[#This Row],[SUB_5]]) * ( TabelaMap[KM Inicio] <= BS_CONTROLE[[#This Row],[KM - ínicio]]) * ( TabelaMap[KM Fim] >= BS_CONTROLE[[#This Row],[KM - ínicio]]), TabelaMap[Gerência], "-", 0 )} -> SP SUL | BD14: {=_xlfn.XLOOKUP( 1, ( TabelaMap[SUB] = BS_CONTROLE[[#This Row],[SUB_5]]) * ( TabelaMap[KM Inicio] <= BS_CONTROLE[[#This Row],[KM - ínicio]]) * ( TabelaMap[KM Fim] >= BS_CONTROLE[[#This Row],[KM - ínicio]]), TabelaMap[Trecho Coordenação], "-", 0 )} -> ZBV-ZRX | BE14: {=_xlfn.XLOOKUP( 1, ( TabelaMap[SUB] = BS_CONTROLE[[#This Row],[SUB_5]]) * ( TabelaMap[KM Inicio] <= BS_CONTROLE[[#This Row],[KM - Inicio]]) * ( TabelaMap[KM Fim] >= BS_CONTROLE[[#This Row],[KM - Inicio]]), TabelaMap[NOME SUB], "-", 0 )} -> RECANTO - ITIRAPINA (L1 PRINCIPAL) | BF14: Antonioni | BH14: 0 | BJ14: MC1 08h01 / Sem oportunidade de faixa | BK14: MC1 08h01 / Sem oportunidade de faixa | BM14: Sem Oportunidade | BN14: Sem Oportunidade | BO14: Sem Oportunidade | BP14: MC1 08h01 / Sem oportunidade de faixa | BQ14: =IF(AND(BR14<1,BS14<1),"Produção e Intervalo",IF(BR14<1,"Intervalo",IF(BS14<1,"Produção","Aderente"))) -> Produção e Intervalo | BR14: =IF(OR(B14="",F14=""),"*",AY14/P14) -> 0 | BS14: =IF(OR(B14="",F14=""),"*",BA14/Q14) -> 0 | BT14: =IF(BN14="","",SUBSTITUTE(BM14," ","")&SUBSTITUTE(BN14," ","")) -> SemOportunidadeSemOportunidade
A15: =D15&B15 -> V4846055 | B15: 46055 | C15: =IF(BS_CONTROLE[[#This Row],[DATA]]="","",WEEKNUM(BS_CONTROLE[[#This Row],[DATA]])) -> 6 | D15: V48 | F15: MECANIZAÇÃO - SOCADORA | G15: =IF(D15="","*",VLOOKUP(F15,BS_ATIVIDADE[],3,FALSE)) -> MECANIZAÇÃO - SOCADORA | H15: ZAC2 | I15: ZAC2 | J15: 70 | K15: 85.4 | L15: 86.4 | M15: {=_xlfn.XLOOKUP( 1, ( TabelaMap[SUB] = BS_CONTROLE[[#This Row],[SUB]]) * ( TabelaMap[KM Inicio] <= BS_CONTROLE[[#This Row],[KM - Inicio]]) * ( TabelaMap[KM Fim] >= BS_CONTROLE[[#This Row],[KM - Inicio]]), TabelaMap[Trecho], "-", 0 )} -> ZAC-ZSW | N15: {=_xlfn.XLOOKUP( 1, ( TabelaMap[SUB] = BS_CONTROLE[[#This Row],[SUB]]) * ( TabelaMap[KM Inicio] <= BS_CONTROLE[[#This Row],[KM - Inicio]]) * ( TabelaMap[KM Fim] >= BS_CONTROLE[[#This Row],[KM - Inicio]]), TabelaMap[SB], "-", 0 )} -> ZACZSW | O15: 0.35416667 | P15: 0.083333333 | Q15: 510 | R15: =IFERROR(_xlfn.XLOOKUP(F15, BS_ATIVIDADE[ATIVIDADE],BS_ATIVIDADE[UNIDADE] ), "*") -> M | S15: {=_xlfn.XLOOKUP( 1, ( TabelaMap[SUB] = BS_CONTROLE[[#This Row],[SUB]]) * ( TabelaMap[KM Inicio] <= BS_CONTROLE[[#This Row],[KM - Inicio]]) * ( TabelaMap[KM Fim] >= BS_CONTROLE[[#This Row],[KM - Inicio]]), TabelaMap[Gerência], "-", 0 )} -> SP SUL | T15: {=_xlfn.XLOOKUP( 1, ( TabelaMap[SUB] = BS_CONTROLE[[#This Row],[SUB]]) * ( TabelaMap[KM Inicio] <= BS_CONTROLE[[#This Row],[KM - Inicio]]) * ( TabelaMap[KM Fim] >= BS_CONTROLE[[#This Row],[KM - Inicio]]), TabelaMap[Trecho Coordenação], "-", 0 )} -> ZBV-ZRX | U15: {=_xlfn.XLOOKUP( 1, ( TabelaMap[SUB] = BS_CONTROLE[[#This Row],[SUB]]) * ( TabelaMap[KM Inicio] <= BS_CONTROLE[[#This Row],[KM - Inicio]]) * ( TabelaMap[KM Fim] >= BS_CONTROLE[[#This Row],[KM - Inicio]]), TabelaMap[NOME SUB], "-", 0 )} -> RECANTO - ITIRAPINA (L1 PRINCIPAL) | V15: Ezequiel | W15: Socaria mecanizada | X15: Oportunidade | Y15: OPORTUNIDADE | AA15: 1 | AB15: FIXO | AC15: - | AD15: 0.29166667 | AE15: 6249 | AF15: - | AG15: - | AI15: =IF(BS_CONTROLE[[#This Row],[Atividade]]=0, "-", BS_CONTROLE[[#This Row],[Atividade]]) -> MECANIZAÇÃO - SOCADORA | AJ15: =IF(BS_CONTROLE[[#This Row],[Atividade]]=0, "-", BS_CONTROLE[[#This Row],[Atividade]]) -> MECANIZAÇÃO - SOCADORA | AK15: =BS_CONTROLE[[#This Row],[Local - Partida]] -> ZAC2 | AL15: =BS_CONTROLE[[#This Row],[Local - Encerramento]] -> ZAC2 | AM15: =IF(BS_CONTROLE[[#This Row],[Entre - Estações]]=0, "-", BS_CONTROLE[[#This Row],[Entre - Estações]]) -> ZAC-ZSW | AN15: =IF(BS_CONTROLE[[#This Row],[SB]]=0, "-", BS_CONTROLE[[#This Row],[SB]]) -> ZACZSW | AO15: =IF(BS_CONTROLE[[#This Row],[SUB]]=0, "-", BS_CONTROLE[[#This Row],[SUB]]) -> 70 | AP15: =BS_CONTROLE[[#This Row],[KM - Inicio]] -> 85.4 | AQ15: =BS_CONTROLE[[#This Row],[KM - Inicio]] -> 85.4 | AR15: 0.33402778 | AS15: 0 | AT15: 0 | AY15: =IF(D15="","*",IFERROR(IF(ISODD(COUNT(AS15:AX15)),"ERRO",SUM((AT15-AS15),(AV15-AU15),(AX15-AW15))),"ERRO")) -> 0 | BA15: 0 | BB15: =IFERROR(_xlfn.XLOOKUP(AI15, BS_ATIVIDADE[ATIVIDADE],BS_ATIVIDADE[UNIDADE] ), "*") -> M | BC15: {=_xlfn.XLOOKUP( 1, ( TabelaMap[SUB] = BS_CONTROLE[[#This Row],[SUB_5]]) * ( TabelaMap[KM Inicio] <= BS_CONTROLE[[#This Row],[KM - ínicio]]) * ( TabelaMap[KM Fim] >= BS_CONTROLE[[#This Row],[KM - ínicio]]), TabelaMap[Gerência], "-", 0 )} -> SP SUL | BD15: {=_xlfn.XLOOKUP( 1, ( TabelaMap[SUB] = BS_CONTROLE[[#This Row],[SUB_5]]) * ( TabelaMap[KM Inicio] <= BS_CONTROLE[[#This Row],[KM - ínicio]]) * ( TabelaMap[KM Fim] >= BS_CONTROLE[[#This Row],[KM - ínicio]]), TabelaMap[Trecho Coordenação], "-", 0 )} -> ZBV-ZRX | BE15: {=_xlfn.XLOOKUP( 1, ( TabelaMap[SUB] = BS_CONTROLE[[#This Row],[SUB_5]]) * ( TabelaMap[KM Inicio] <= BS_CONTROLE[[#This Row],[KM - Inicio]]) * ( TabelaMap[KM Fim] >= BS_CONTROLE[[#This Row],[KM - Inicio]]), TabelaMap[NOME SUB], "-", 0 )} -> RECANTO - ITIRAPINA (L1 PRINCIPAL) | BF15: Ezequiel | BH15: 0 | BJ15: MC1 08h01 / Sem oportunidade de faixa | BK15: MC1 08h01 / Sem oportunidade de faixa | BM15: Sem Oportunidade | BN15: Sem Oportunidade | BO15: Sem Oportunidade | BP15: MC1 08h01 / Sem oportunidade de faixa | BQ15: =IF(AND(BR15<1,BS15<1),"Produção e Intervalo",IF(BR15<1,"Intervalo",IF(BS15<1,"Produção","Aderente"))) -> Produção e Intervalo | BR15: =IF(OR(B15="",F15=""),"*",AY15/P15) -> 0 | BS15: =IF(OR(B15="",F15=""),"*",BA15/Q15) -> 0 | BT15: =IF(BN15="","",SUBSTITUTE(BM15," ","")&SUBSTITUTE(BN15," ","")) -> SemOportunidadeSemOportunidade
